[2025-01-14T17:23:05.686+0000] {processor.py:186} INFO - Started process (PID=79) to work on /opt/airflow/dags/tes_dag.py
[2025-01-14T17:23:05.688+0000] {processor.py:914} INFO - Processing file /opt/airflow/dags/tes_dag.py for tasks to queue
[2025-01-14T17:23:05.694+0000] {logging_mixin.py:190} INFO - [2025-01-14T17:23:05.693+0000] {dagbag.py:588} INFO - Filling up the DagBag from /opt/airflow/dags/tes_dag.py
[2025-01-14T17:23:05.997+0000] {logging_mixin.py:190} INFO - [2025-01-14T17:23:05.984+0000] {dagbag.py:387} ERROR - Failed to import: /opt/airflow/dags/tes_dag.py
Traceback (most recent call last):
  File "/home/airflow/.local/lib/python3.12/site-packages/airflow/models/dagbag.py", line 383, in parse
    loader.exec_module(new_module)
  File "<frozen importlib._bootstrap_external>", line 999, in exec_module
  File "<frozen importlib._bootstrap>", line 488, in _call_with_frames_removed
  File "/opt/airflow/dags/tes_dag.py", line 5, in <module>
    from test import test2
  File "/opt/airflow/dags/test.py", line 2, in <module>
    from kaggle.api.kaggle_api_extended import KaggleApi
  File "/home/airflow/.local/lib/python3.12/site-packages/kaggle/__init__.py", line 7, in <module>
    api.authenticate()
  File "/home/airflow/.local/lib/python3.12/site-packages/kaggle/api/kaggle_api_extended.py", line 407, in authenticate
    raise IOError('Could not find {}. Make sure it\'s located in'
OSError: Could not find kaggle.json. Make sure it's located in /home/airflow/.config/kaggle. Or use the environment method. See setup instructions at https://github.com/Kaggle/kaggle-api/
[2025-01-14T17:23:05.999+0000] {processor.py:927} WARNING - No viable dags retrieved from /opt/airflow/dags/tes_dag.py
[2025-01-14T17:23:06.033+0000] {processor.py:208} INFO - Processing /opt/airflow/dags/tes_dag.py took 0.357 seconds
[2025-01-14T17:23:37.568+0000] {processor.py:186} INFO - Started process (PID=101) to work on /opt/airflow/dags/tes_dag.py
[2025-01-14T17:23:37.570+0000] {processor.py:914} INFO - Processing file /opt/airflow/dags/tes_dag.py for tasks to queue
[2025-01-14T17:23:37.573+0000] {logging_mixin.py:190} INFO - [2025-01-14T17:23:37.573+0000] {dagbag.py:588} INFO - Filling up the DagBag from /opt/airflow/dags/tes_dag.py
[2025-01-14T17:23:37.836+0000] {logging_mixin.py:190} INFO - [2025-01-14T17:23:37.825+0000] {dagbag.py:387} ERROR - Failed to import: /opt/airflow/dags/tes_dag.py
Traceback (most recent call last):
  File "/home/airflow/.local/lib/python3.12/site-packages/airflow/models/dagbag.py", line 383, in parse
    loader.exec_module(new_module)
  File "<frozen importlib._bootstrap_external>", line 999, in exec_module
  File "<frozen importlib._bootstrap>", line 488, in _call_with_frames_removed
  File "/opt/airflow/dags/tes_dag.py", line 5, in <module>
    from test import test2
  File "/opt/airflow/dags/test.py", line 2, in <module>
    from kaggle.api.kaggle_api_extended import KaggleApi
  File "/home/airflow/.local/lib/python3.12/site-packages/kaggle/__init__.py", line 7, in <module>
    api.authenticate()
  File "/home/airflow/.local/lib/python3.12/site-packages/kaggle/api/kaggle_api_extended.py", line 407, in authenticate
    raise IOError('Could not find {}. Make sure it\'s located in'
OSError: Could not find kaggle.json. Make sure it's located in /home/airflow/.config/kaggle. Or use the environment method. See setup instructions at https://github.com/Kaggle/kaggle-api/
[2025-01-14T17:23:37.837+0000] {processor.py:927} WARNING - No viable dags retrieved from /opt/airflow/dags/tes_dag.py
[2025-01-14T17:23:37.862+0000] {processor.py:208} INFO - Processing /opt/airflow/dags/tes_dag.py took 0.305 seconds
[2025-01-14T17:24:09.104+0000] {processor.py:186} INFO - Started process (PID=123) to work on /opt/airflow/dags/tes_dag.py
[2025-01-14T17:24:09.105+0000] {processor.py:914} INFO - Processing file /opt/airflow/dags/tes_dag.py for tasks to queue
[2025-01-14T17:24:09.107+0000] {logging_mixin.py:190} INFO - [2025-01-14T17:24:09.106+0000] {dagbag.py:588} INFO - Filling up the DagBag from /opt/airflow/dags/tes_dag.py
[2025-01-14T17:24:09.248+0000] {logging_mixin.py:190} INFO - [2025-01-14T17:24:09.236+0000] {dagbag.py:387} ERROR - Failed to import: /opt/airflow/dags/tes_dag.py
Traceback (most recent call last):
  File "/home/airflow/.local/lib/python3.12/site-packages/airflow/models/dagbag.py", line 383, in parse
    loader.exec_module(new_module)
  File "<frozen importlib._bootstrap_external>", line 999, in exec_module
  File "<frozen importlib._bootstrap>", line 488, in _call_with_frames_removed
  File "/opt/airflow/dags/tes_dag.py", line 5, in <module>
    from test import test2
  File "/opt/airflow/dags/test.py", line 2, in <module>
    from kaggle.api.kaggle_api_extended import KaggleApi
  File "/home/airflow/.local/lib/python3.12/site-packages/kaggle/__init__.py", line 7, in <module>
    api.authenticate()
  File "/home/airflow/.local/lib/python3.12/site-packages/kaggle/api/kaggle_api_extended.py", line 407, in authenticate
    raise IOError('Could not find {}. Make sure it\'s located in'
OSError: Could not find kaggle.json. Make sure it's located in /home/airflow/.config/kaggle. Or use the environment method. See setup instructions at https://github.com/Kaggle/kaggle-api/
[2025-01-14T17:24:09.249+0000] {processor.py:927} WARNING - No viable dags retrieved from /opt/airflow/dags/tes_dag.py
[2025-01-14T17:24:09.271+0000] {processor.py:208} INFO - Processing /opt/airflow/dags/tes_dag.py took 0.175 seconds
[2025-01-14T17:24:39.533+0000] {processor.py:186} INFO - Started process (PID=144) to work on /opt/airflow/dags/tes_dag.py
[2025-01-14T17:24:39.535+0000] {processor.py:914} INFO - Processing file /opt/airflow/dags/tes_dag.py for tasks to queue
[2025-01-14T17:24:39.538+0000] {logging_mixin.py:190} INFO - [2025-01-14T17:24:39.537+0000] {dagbag.py:588} INFO - Filling up the DagBag from /opt/airflow/dags/tes_dag.py
[2025-01-14T17:24:39.684+0000] {logging_mixin.py:190} INFO - [2025-01-14T17:24:39.672+0000] {dagbag.py:387} ERROR - Failed to import: /opt/airflow/dags/tes_dag.py
Traceback (most recent call last):
  File "/home/airflow/.local/lib/python3.12/site-packages/airflow/models/dagbag.py", line 383, in parse
    loader.exec_module(new_module)
  File "<frozen importlib._bootstrap_external>", line 999, in exec_module
  File "<frozen importlib._bootstrap>", line 488, in _call_with_frames_removed
  File "/opt/airflow/dags/tes_dag.py", line 5, in <module>
    from test import test2
  File "/opt/airflow/dags/test.py", line 2, in <module>
    from kaggle.api.kaggle_api_extended import KaggleApi
  File "/home/airflow/.local/lib/python3.12/site-packages/kaggle/__init__.py", line 7, in <module>
    api.authenticate()
  File "/home/airflow/.local/lib/python3.12/site-packages/kaggle/api/kaggle_api_extended.py", line 407, in authenticate
    raise IOError('Could not find {}. Make sure it\'s located in'
OSError: Could not find kaggle.json. Make sure it's located in /home/airflow/.config/kaggle. Or use the environment method. See setup instructions at https://github.com/Kaggle/kaggle-api/
[2025-01-14T17:24:39.685+0000] {processor.py:927} WARNING - No viable dags retrieved from /opt/airflow/dags/tes_dag.py
[2025-01-14T17:24:39.717+0000] {processor.py:208} INFO - Processing /opt/airflow/dags/tes_dag.py took 0.193 seconds
[2025-01-14T17:25:10.130+0000] {processor.py:186} INFO - Started process (PID=165) to work on /opt/airflow/dags/tes_dag.py
[2025-01-14T17:25:10.132+0000] {processor.py:914} INFO - Processing file /opt/airflow/dags/tes_dag.py for tasks to queue
[2025-01-14T17:25:10.134+0000] {logging_mixin.py:190} INFO - [2025-01-14T17:25:10.133+0000] {dagbag.py:588} INFO - Filling up the DagBag from /opt/airflow/dags/tes_dag.py
[2025-01-14T17:25:10.297+0000] {logging_mixin.py:190} INFO - [2025-01-14T17:25:10.283+0000] {dagbag.py:387} ERROR - Failed to import: /opt/airflow/dags/tes_dag.py
Traceback (most recent call last):
  File "/home/airflow/.local/lib/python3.12/site-packages/airflow/models/dagbag.py", line 383, in parse
    loader.exec_module(new_module)
  File "<frozen importlib._bootstrap_external>", line 999, in exec_module
  File "<frozen importlib._bootstrap>", line 488, in _call_with_frames_removed
  File "/opt/airflow/dags/tes_dag.py", line 5, in <module>
    from test import test2
  File "/opt/airflow/dags/test.py", line 2, in <module>
    from kaggle.api.kaggle_api_extended import KaggleApi
  File "/home/airflow/.local/lib/python3.12/site-packages/kaggle/__init__.py", line 7, in <module>
    api.authenticate()
  File "/home/airflow/.local/lib/python3.12/site-packages/kaggle/api/kaggle_api_extended.py", line 407, in authenticate
    raise IOError('Could not find {}. Make sure it\'s located in'
OSError: Could not find kaggle.json. Make sure it's located in /home/airflow/.config/kaggle. Or use the environment method. See setup instructions at https://github.com/Kaggle/kaggle-api/
[2025-01-14T17:25:10.299+0000] {processor.py:927} WARNING - No viable dags retrieved from /opt/airflow/dags/tes_dag.py
[2025-01-14T17:25:10.336+0000] {processor.py:208} INFO - Processing /opt/airflow/dags/tes_dag.py took 0.215 seconds
[2025-01-14T17:25:40.614+0000] {processor.py:186} INFO - Started process (PID=187) to work on /opt/airflow/dags/tes_dag.py
[2025-01-14T17:25:40.615+0000] {processor.py:914} INFO - Processing file /opt/airflow/dags/tes_dag.py for tasks to queue
[2025-01-14T17:25:40.618+0000] {logging_mixin.py:190} INFO - [2025-01-14T17:25:40.617+0000] {dagbag.py:588} INFO - Filling up the DagBag from /opt/airflow/dags/tes_dag.py
[2025-01-14T17:25:40.775+0000] {logging_mixin.py:190} INFO - [2025-01-14T17:25:40.761+0000] {dagbag.py:387} ERROR - Failed to import: /opt/airflow/dags/tes_dag.py
Traceback (most recent call last):
  File "/home/airflow/.local/lib/python3.12/site-packages/airflow/models/dagbag.py", line 383, in parse
    loader.exec_module(new_module)
  File "<frozen importlib._bootstrap_external>", line 999, in exec_module
  File "<frozen importlib._bootstrap>", line 488, in _call_with_frames_removed
  File "/opt/airflow/dags/tes_dag.py", line 5, in <module>
    from test import test2
  File "/opt/airflow/dags/test.py", line 2, in <module>
    from kaggle.api.kaggle_api_extended import KaggleApi
  File "/home/airflow/.local/lib/python3.12/site-packages/kaggle/__init__.py", line 7, in <module>
    api.authenticate()
  File "/home/airflow/.local/lib/python3.12/site-packages/kaggle/api/kaggle_api_extended.py", line 407, in authenticate
    raise IOError('Could not find {}. Make sure it\'s located in'
OSError: Could not find kaggle.json. Make sure it's located in /home/airflow/.config/kaggle. Or use the environment method. See setup instructions at https://github.com/Kaggle/kaggle-api/
[2025-01-14T17:25:40.776+0000] {processor.py:927} WARNING - No viable dags retrieved from /opt/airflow/dags/tes_dag.py
[2025-01-14T17:25:40.807+0000] {processor.py:208} INFO - Processing /opt/airflow/dags/tes_dag.py took 0.201 seconds
[2025-01-14T17:26:11.169+0000] {processor.py:186} INFO - Started process (PID=209) to work on /opt/airflow/dags/tes_dag.py
[2025-01-14T17:26:11.170+0000] {processor.py:914} INFO - Processing file /opt/airflow/dags/tes_dag.py for tasks to queue
[2025-01-14T17:26:11.172+0000] {logging_mixin.py:190} INFO - [2025-01-14T17:26:11.172+0000] {dagbag.py:588} INFO - Filling up the DagBag from /opt/airflow/dags/tes_dag.py
[2025-01-14T17:26:11.351+0000] {logging_mixin.py:190} INFO - [2025-01-14T17:26:11.343+0000] {dagbag.py:387} ERROR - Failed to import: /opt/airflow/dags/tes_dag.py
Traceback (most recent call last):
  File "/home/airflow/.local/lib/python3.12/site-packages/airflow/models/dagbag.py", line 383, in parse
    loader.exec_module(new_module)
  File "<frozen importlib._bootstrap_external>", line 999, in exec_module
  File "<frozen importlib._bootstrap>", line 488, in _call_with_frames_removed
  File "/opt/airflow/dags/tes_dag.py", line 5, in <module>
    from test import test2
  File "/opt/airflow/dags/test.py", line 2, in <module>
    from kaggle.api.kaggle_api_extended import KaggleApi
  File "/home/airflow/.local/lib/python3.12/site-packages/kaggle/__init__.py", line 7, in <module>
    api.authenticate()
  File "/home/airflow/.local/lib/python3.12/site-packages/kaggle/api/kaggle_api_extended.py", line 407, in authenticate
    raise IOError('Could not find {}. Make sure it\'s located in'
OSError: Could not find kaggle.json. Make sure it's located in /home/airflow/.config/kaggle. Or use the environment method. See setup instructions at https://github.com/Kaggle/kaggle-api/
[2025-01-14T17:26:11.352+0000] {processor.py:927} WARNING - No viable dags retrieved from /opt/airflow/dags/tes_dag.py
[2025-01-14T17:26:11.382+0000] {processor.py:208} INFO - Processing /opt/airflow/dags/tes_dag.py took 0.222 seconds
[2025-01-14T17:26:41.452+0000] {processor.py:186} INFO - Started process (PID=231) to work on /opt/airflow/dags/tes_dag.py
[2025-01-14T17:26:41.454+0000] {processor.py:914} INFO - Processing file /opt/airflow/dags/tes_dag.py for tasks to queue
[2025-01-14T17:26:41.456+0000] {logging_mixin.py:190} INFO - [2025-01-14T17:26:41.456+0000] {dagbag.py:588} INFO - Filling up the DagBag from /opt/airflow/dags/tes_dag.py
[2025-01-14T17:26:41.622+0000] {logging_mixin.py:190} INFO - [2025-01-14T17:26:41.605+0000] {dagbag.py:387} ERROR - Failed to import: /opt/airflow/dags/tes_dag.py
Traceback (most recent call last):
  File "/home/airflow/.local/lib/python3.12/site-packages/airflow/models/dagbag.py", line 383, in parse
    loader.exec_module(new_module)
  File "<frozen importlib._bootstrap_external>", line 999, in exec_module
  File "<frozen importlib._bootstrap>", line 488, in _call_with_frames_removed
  File "/opt/airflow/dags/tes_dag.py", line 5, in <module>
    from test import test2
  File "/opt/airflow/dags/test.py", line 2, in <module>
    from kaggle.api.kaggle_api_extended import KaggleApi
  File "/home/airflow/.local/lib/python3.12/site-packages/kaggle/__init__.py", line 7, in <module>
    api.authenticate()
  File "/home/airflow/.local/lib/python3.12/site-packages/kaggle/api/kaggle_api_extended.py", line 407, in authenticate
    raise IOError('Could not find {}. Make sure it\'s located in'
OSError: Could not find kaggle.json. Make sure it's located in /home/airflow/.config/kaggle. Or use the environment method. See setup instructions at https://github.com/Kaggle/kaggle-api/
[2025-01-14T17:26:41.623+0000] {processor.py:927} WARNING - No viable dags retrieved from /opt/airflow/dags/tes_dag.py
[2025-01-14T17:26:41.656+0000] {processor.py:208} INFO - Processing /opt/airflow/dags/tes_dag.py took 0.213 seconds
[2025-01-14T17:27:11.882+0000] {processor.py:186} INFO - Started process (PID=253) to work on /opt/airflow/dags/tes_dag.py
[2025-01-14T17:27:11.883+0000] {processor.py:914} INFO - Processing file /opt/airflow/dags/tes_dag.py for tasks to queue
[2025-01-14T17:27:11.886+0000] {logging_mixin.py:190} INFO - [2025-01-14T17:27:11.885+0000] {dagbag.py:588} INFO - Filling up the DagBag from /opt/airflow/dags/tes_dag.py
[2025-01-14T17:27:12.042+0000] {logging_mixin.py:190} INFO - [2025-01-14T17:27:12.027+0000] {dagbag.py:387} ERROR - Failed to import: /opt/airflow/dags/tes_dag.py
Traceback (most recent call last):
  File "/home/airflow/.local/lib/python3.12/site-packages/airflow/models/dagbag.py", line 383, in parse
    loader.exec_module(new_module)
  File "<frozen importlib._bootstrap_external>", line 999, in exec_module
  File "<frozen importlib._bootstrap>", line 488, in _call_with_frames_removed
  File "/opt/airflow/dags/tes_dag.py", line 5, in <module>
    from test import test2
  File "/opt/airflow/dags/test.py", line 2, in <module>
    from kaggle.api.kaggle_api_extended import KaggleApi
  File "/home/airflow/.local/lib/python3.12/site-packages/kaggle/__init__.py", line 7, in <module>
    api.authenticate()
  File "/home/airflow/.local/lib/python3.12/site-packages/kaggle/api/kaggle_api_extended.py", line 407, in authenticate
    raise IOError('Could not find {}. Make sure it\'s located in'
OSError: Could not find kaggle.json. Make sure it's located in /home/airflow/.config/kaggle. Or use the environment method. See setup instructions at https://github.com/Kaggle/kaggle-api/
[2025-01-14T17:27:12.043+0000] {processor.py:927} WARNING - No viable dags retrieved from /opt/airflow/dags/tes_dag.py
[2025-01-14T17:27:12.068+0000] {processor.py:208} INFO - Processing /opt/airflow/dags/tes_dag.py took 0.195 seconds
[2025-01-14T17:27:42.478+0000] {processor.py:186} INFO - Started process (PID=276) to work on /opt/airflow/dags/tes_dag.py
[2025-01-14T17:27:42.479+0000] {processor.py:914} INFO - Processing file /opt/airflow/dags/tes_dag.py for tasks to queue
[2025-01-14T17:27:42.480+0000] {logging_mixin.py:190} INFO - [2025-01-14T17:27:42.480+0000] {dagbag.py:588} INFO - Filling up the DagBag from /opt/airflow/dags/tes_dag.py
[2025-01-14T17:27:42.795+0000] {logging_mixin.py:190} INFO - [2025-01-14T17:27:42.785+0000] {dagbag.py:387} ERROR - Failed to import: /opt/airflow/dags/tes_dag.py
Traceback (most recent call last):
  File "/home/airflow/.local/lib/python3.12/site-packages/airflow/models/dagbag.py", line 383, in parse
    loader.exec_module(new_module)
  File "<frozen importlib._bootstrap_external>", line 999, in exec_module
  File "<frozen importlib._bootstrap>", line 488, in _call_with_frames_removed
  File "/opt/airflow/dags/tes_dag.py", line 5, in <module>
    from test import test2
  File "/opt/airflow/dags/test.py", line 2, in <module>
    from kaggle.api.kaggle_api_extended import KaggleApi
  File "/home/airflow/.local/lib/python3.12/site-packages/kaggle/__init__.py", line 7, in <module>
    api.authenticate()
  File "/home/airflow/.local/lib/python3.12/site-packages/kaggle/api/kaggle_api_extended.py", line 407, in authenticate
    raise IOError('Could not find {}. Make sure it\'s located in'
OSError: Could not find kaggle.json. Make sure it's located in /home/airflow/.config/kaggle. Or use the environment method. See setup instructions at https://github.com/Kaggle/kaggle-api/
[2025-01-14T17:27:42.796+0000] {processor.py:927} WARNING - No viable dags retrieved from /opt/airflow/dags/tes_dag.py
[2025-01-14T17:27:42.818+0000] {processor.py:208} INFO - Processing /opt/airflow/dags/tes_dag.py took 0.350 seconds
[2025-01-14T17:28:13.262+0000] {processor.py:186} INFO - Started process (PID=300) to work on /opt/airflow/dags/tes_dag.py
[2025-01-14T17:28:13.265+0000] {processor.py:914} INFO - Processing file /opt/airflow/dags/tes_dag.py for tasks to queue
[2025-01-14T17:28:13.273+0000] {logging_mixin.py:190} INFO - [2025-01-14T17:28:13.270+0000] {dagbag.py:588} INFO - Filling up the DagBag from /opt/airflow/dags/tes_dag.py
[2025-01-14T17:28:13.655+0000] {logging_mixin.py:190} INFO - [2025-01-14T17:28:13.645+0000] {dagbag.py:387} ERROR - Failed to import: /opt/airflow/dags/tes_dag.py
Traceback (most recent call last):
  File "/home/airflow/.local/lib/python3.12/site-packages/airflow/models/dagbag.py", line 383, in parse
    loader.exec_module(new_module)
  File "<frozen importlib._bootstrap_external>", line 999, in exec_module
  File "<frozen importlib._bootstrap>", line 488, in _call_with_frames_removed
  File "/opt/airflow/dags/tes_dag.py", line 5, in <module>
    from test import test2
  File "/opt/airflow/dags/test.py", line 2, in <module>
    from kaggle.api.kaggle_api_extended import KaggleApi
  File "/home/airflow/.local/lib/python3.12/site-packages/kaggle/__init__.py", line 7, in <module>
    api.authenticate()
  File "/home/airflow/.local/lib/python3.12/site-packages/kaggle/api/kaggle_api_extended.py", line 407, in authenticate
    raise IOError('Could not find {}. Make sure it\'s located in'
OSError: Could not find kaggle.json. Make sure it's located in /home/airflow/.config/kaggle. Or use the environment method. See setup instructions at https://github.com/Kaggle/kaggle-api/
[2025-01-14T17:28:13.656+0000] {processor.py:927} WARNING - No viable dags retrieved from /opt/airflow/dags/tes_dag.py
[2025-01-14T17:28:13.679+0000] {processor.py:208} INFO - Processing /opt/airflow/dags/tes_dag.py took 0.432 seconds
[2025-01-14T17:28:43.929+0000] {processor.py:186} INFO - Started process (PID=324) to work on /opt/airflow/dags/tes_dag.py
[2025-01-14T17:28:43.930+0000] {processor.py:914} INFO - Processing file /opt/airflow/dags/tes_dag.py for tasks to queue
[2025-01-14T17:28:43.932+0000] {logging_mixin.py:190} INFO - [2025-01-14T17:28:43.932+0000] {dagbag.py:588} INFO - Filling up the DagBag from /opt/airflow/dags/tes_dag.py
[2025-01-14T17:28:44.253+0000] {logging_mixin.py:190} INFO - [2025-01-14T17:28:44.242+0000] {dagbag.py:387} ERROR - Failed to import: /opt/airflow/dags/tes_dag.py
Traceback (most recent call last):
  File "/home/airflow/.local/lib/python3.12/site-packages/airflow/models/dagbag.py", line 383, in parse
    loader.exec_module(new_module)
  File "<frozen importlib._bootstrap_external>", line 999, in exec_module
  File "<frozen importlib._bootstrap>", line 488, in _call_with_frames_removed
  File "/opt/airflow/dags/tes_dag.py", line 5, in <module>
    from test import test2
  File "/opt/airflow/dags/test.py", line 2, in <module>
    from kaggle.api.kaggle_api_extended import KaggleApi
  File "/home/airflow/.local/lib/python3.12/site-packages/kaggle/__init__.py", line 7, in <module>
    api.authenticate()
  File "/home/airflow/.local/lib/python3.12/site-packages/kaggle/api/kaggle_api_extended.py", line 407, in authenticate
    raise IOError('Could not find {}. Make sure it\'s located in'
OSError: Could not find kaggle.json. Make sure it's located in /home/airflow/.config/kaggle. Or use the environment method. See setup instructions at https://github.com/Kaggle/kaggle-api/
[2025-01-14T17:28:44.254+0000] {processor.py:927} WARNING - No viable dags retrieved from /opt/airflow/dags/tes_dag.py
[2025-01-14T17:28:44.274+0000] {processor.py:208} INFO - Processing /opt/airflow/dags/tes_dag.py took 0.354 seconds
[2025-01-14T17:29:14.559+0000] {processor.py:186} INFO - Started process (PID=346) to work on /opt/airflow/dags/tes_dag.py
[2025-01-14T17:29:14.560+0000] {processor.py:914} INFO - Processing file /opt/airflow/dags/tes_dag.py for tasks to queue
[2025-01-14T17:29:14.562+0000] {logging_mixin.py:190} INFO - [2025-01-14T17:29:14.561+0000] {dagbag.py:588} INFO - Filling up the DagBag from /opt/airflow/dags/tes_dag.py
[2025-01-14T17:29:14.958+0000] {logging_mixin.py:190} INFO - [2025-01-14T17:29:14.948+0000] {dagbag.py:387} ERROR - Failed to import: /opt/airflow/dags/tes_dag.py
Traceback (most recent call last):
  File "/home/airflow/.local/lib/python3.12/site-packages/airflow/models/dagbag.py", line 383, in parse
    loader.exec_module(new_module)
  File "<frozen importlib._bootstrap_external>", line 999, in exec_module
  File "<frozen importlib._bootstrap>", line 488, in _call_with_frames_removed
  File "/opt/airflow/dags/tes_dag.py", line 5, in <module>
    from test import test2
  File "/opt/airflow/dags/test.py", line 2, in <module>
    from kaggle.api.kaggle_api_extended import KaggleApi
  File "/home/airflow/.local/lib/python3.12/site-packages/kaggle/__init__.py", line 7, in <module>
    api.authenticate()
  File "/home/airflow/.local/lib/python3.12/site-packages/kaggle/api/kaggle_api_extended.py", line 407, in authenticate
    raise IOError('Could not find {}. Make sure it\'s located in'
OSError: Could not find kaggle.json. Make sure it's located in /home/airflow/.config/kaggle. Or use the environment method. See setup instructions at https://github.com/Kaggle/kaggle-api/
[2025-01-14T17:29:14.959+0000] {processor.py:927} WARNING - No viable dags retrieved from /opt/airflow/dags/tes_dag.py
[2025-01-14T17:29:14.985+0000] {processor.py:208} INFO - Processing /opt/airflow/dags/tes_dag.py took 0.436 seconds
[2025-01-14T17:29:45.055+0000] {processor.py:186} INFO - Started process (PID=368) to work on /opt/airflow/dags/tes_dag.py
[2025-01-14T17:29:45.056+0000] {processor.py:914} INFO - Processing file /opt/airflow/dags/tes_dag.py for tasks to queue
[2025-01-14T17:29:45.058+0000] {logging_mixin.py:190} INFO - [2025-01-14T17:29:45.057+0000] {dagbag.py:588} INFO - Filling up the DagBag from /opt/airflow/dags/tes_dag.py
[2025-01-14T17:29:45.211+0000] {logging_mixin.py:190} INFO - [2025-01-14T17:29:45.201+0000] {dagbag.py:387} ERROR - Failed to import: /opt/airflow/dags/tes_dag.py
Traceback (most recent call last):
  File "/home/airflow/.local/lib/python3.12/site-packages/airflow/models/dagbag.py", line 383, in parse
    loader.exec_module(new_module)
  File "<frozen importlib._bootstrap_external>", line 999, in exec_module
  File "<frozen importlib._bootstrap>", line 488, in _call_with_frames_removed
  File "/opt/airflow/dags/tes_dag.py", line 5, in <module>
    from test import test2
  File "/opt/airflow/dags/test.py", line 2, in <module>
    from kaggle.api.kaggle_api_extended import KaggleApi
  File "/home/airflow/.local/lib/python3.12/site-packages/kaggle/__init__.py", line 7, in <module>
    api.authenticate()
  File "/home/airflow/.local/lib/python3.12/site-packages/kaggle/api/kaggle_api_extended.py", line 407, in authenticate
    raise IOError('Could not find {}. Make sure it\'s located in'
OSError: Could not find kaggle.json. Make sure it's located in /home/airflow/.config/kaggle. Or use the environment method. See setup instructions at https://github.com/Kaggle/kaggle-api/
[2025-01-14T17:29:45.213+0000] {processor.py:927} WARNING - No viable dags retrieved from /opt/airflow/dags/tes_dag.py
[2025-01-14T17:29:45.244+0000] {processor.py:208} INFO - Processing /opt/airflow/dags/tes_dag.py took 0.197 seconds
[2025-01-14T17:30:15.447+0000] {processor.py:186} INFO - Started process (PID=389) to work on /opt/airflow/dags/tes_dag.py
[2025-01-14T17:30:15.448+0000] {processor.py:914} INFO - Processing file /opt/airflow/dags/tes_dag.py for tasks to queue
[2025-01-14T17:30:15.450+0000] {logging_mixin.py:190} INFO - [2025-01-14T17:30:15.450+0000] {dagbag.py:588} INFO - Filling up the DagBag from /opt/airflow/dags/tes_dag.py
[2025-01-14T17:30:15.677+0000] {logging_mixin.py:190} INFO - [2025-01-14T17:30:15.659+0000] {dagbag.py:387} ERROR - Failed to import: /opt/airflow/dags/tes_dag.py
Traceback (most recent call last):
  File "/home/airflow/.local/lib/python3.12/site-packages/airflow/models/dagbag.py", line 383, in parse
    loader.exec_module(new_module)
  File "<frozen importlib._bootstrap_external>", line 999, in exec_module
  File "<frozen importlib._bootstrap>", line 488, in _call_with_frames_removed
  File "/opt/airflow/dags/tes_dag.py", line 5, in <module>
    from test import test2
  File "/opt/airflow/dags/test.py", line 2, in <module>
    from kaggle.api.kaggle_api_extended import KaggleApi
  File "/home/airflow/.local/lib/python3.12/site-packages/kaggle/__init__.py", line 7, in <module>
    api.authenticate()
  File "/home/airflow/.local/lib/python3.12/site-packages/kaggle/api/kaggle_api_extended.py", line 407, in authenticate
    raise IOError('Could not find {}. Make sure it\'s located in'
OSError: Could not find kaggle.json. Make sure it's located in /home/airflow/.config/kaggle. Or use the environment method. See setup instructions at https://github.com/Kaggle/kaggle-api/
[2025-01-14T17:30:15.680+0000] {processor.py:927} WARNING - No viable dags retrieved from /opt/airflow/dags/tes_dag.py
[2025-01-14T17:30:16.106+0000] {processor.py:208} INFO - Processing /opt/airflow/dags/tes_dag.py took 0.672 seconds
[2025-01-14T17:30:46.466+0000] {processor.py:186} INFO - Started process (PID=410) to work on /opt/airflow/dags/tes_dag.py
[2025-01-14T17:30:46.467+0000] {processor.py:914} INFO - Processing file /opt/airflow/dags/tes_dag.py for tasks to queue
[2025-01-14T17:30:46.469+0000] {logging_mixin.py:190} INFO - [2025-01-14T17:30:46.469+0000] {dagbag.py:588} INFO - Filling up the DagBag from /opt/airflow/dags/tes_dag.py
[2025-01-14T17:30:46.844+0000] {logging_mixin.py:190} INFO - [2025-01-14T17:30:46.835+0000] {dagbag.py:387} ERROR - Failed to import: /opt/airflow/dags/tes_dag.py
Traceback (most recent call last):
  File "/home/airflow/.local/lib/python3.12/site-packages/airflow/models/dagbag.py", line 383, in parse
    loader.exec_module(new_module)
  File "<frozen importlib._bootstrap_external>", line 999, in exec_module
  File "<frozen importlib._bootstrap>", line 488, in _call_with_frames_removed
  File "/opt/airflow/dags/tes_dag.py", line 5, in <module>
    from test import test2
  File "/opt/airflow/dags/test.py", line 2, in <module>
    from kaggle.api.kaggle_api_extended import KaggleApi
  File "/home/airflow/.local/lib/python3.12/site-packages/kaggle/__init__.py", line 7, in <module>
    api.authenticate()
  File "/home/airflow/.local/lib/python3.12/site-packages/kaggle/api/kaggle_api_extended.py", line 407, in authenticate
    raise IOError('Could not find {}. Make sure it\'s located in'
OSError: Could not find kaggle.json. Make sure it's located in /home/airflow/.config/kaggle. Or use the environment method. See setup instructions at https://github.com/Kaggle/kaggle-api/
[2025-01-14T17:30:46.846+0000] {processor.py:927} WARNING - No viable dags retrieved from /opt/airflow/dags/tes_dag.py
[2025-01-14T17:30:46.885+0000] {processor.py:208} INFO - Processing /opt/airflow/dags/tes_dag.py took 0.428 seconds
[2025-01-14T17:31:17.410+0000] {processor.py:186} INFO - Started process (PID=432) to work on /opt/airflow/dags/tes_dag.py
[2025-01-14T17:31:17.412+0000] {processor.py:914} INFO - Processing file /opt/airflow/dags/tes_dag.py for tasks to queue
[2025-01-14T17:31:17.415+0000] {logging_mixin.py:190} INFO - [2025-01-14T17:31:17.415+0000] {dagbag.py:588} INFO - Filling up the DagBag from /opt/airflow/dags/tes_dag.py
[2025-01-14T17:31:17.824+0000] {logging_mixin.py:190} INFO - [2025-01-14T17:31:17.815+0000] {dagbag.py:387} ERROR - Failed to import: /opt/airflow/dags/tes_dag.py
Traceback (most recent call last):
  File "/home/airflow/.local/lib/python3.12/site-packages/airflow/models/dagbag.py", line 383, in parse
    loader.exec_module(new_module)
  File "<frozen importlib._bootstrap_external>", line 999, in exec_module
  File "<frozen importlib._bootstrap>", line 488, in _call_with_frames_removed
  File "/opt/airflow/dags/tes_dag.py", line 5, in <module>
    from test import test2
  File "/opt/airflow/dags/test.py", line 2, in <module>
    from kaggle.api.kaggle_api_extended import KaggleApi
  File "/home/airflow/.local/lib/python3.12/site-packages/kaggle/__init__.py", line 7, in <module>
    api.authenticate()
  File "/home/airflow/.local/lib/python3.12/site-packages/kaggle/api/kaggle_api_extended.py", line 407, in authenticate
    raise IOError('Could not find {}. Make sure it\'s located in'
OSError: Could not find kaggle.json. Make sure it's located in /home/airflow/.config/kaggle. Or use the environment method. See setup instructions at https://github.com/Kaggle/kaggle-api/
[2025-01-14T17:31:17.825+0000] {processor.py:927} WARNING - No viable dags retrieved from /opt/airflow/dags/tes_dag.py
[2025-01-14T17:31:17.849+0000] {processor.py:208} INFO - Processing /opt/airflow/dags/tes_dag.py took 0.457 seconds
[2025-01-14T17:31:48.667+0000] {processor.py:186} INFO - Started process (PID=454) to work on /opt/airflow/dags/tes_dag.py
[2025-01-14T17:31:48.668+0000] {processor.py:914} INFO - Processing file /opt/airflow/dags/tes_dag.py for tasks to queue
[2025-01-14T17:31:48.670+0000] {logging_mixin.py:190} INFO - [2025-01-14T17:31:48.670+0000] {dagbag.py:588} INFO - Filling up the DagBag from /opt/airflow/dags/tes_dag.py
[2025-01-14T17:31:49.004+0000] {logging_mixin.py:190} INFO - [2025-01-14T17:31:48.989+0000] {dagbag.py:387} ERROR - Failed to import: /opt/airflow/dags/tes_dag.py
Traceback (most recent call last):
  File "/home/airflow/.local/lib/python3.12/site-packages/airflow/models/dagbag.py", line 383, in parse
    loader.exec_module(new_module)
  File "<frozen importlib._bootstrap_external>", line 999, in exec_module
  File "<frozen importlib._bootstrap>", line 488, in _call_with_frames_removed
  File "/opt/airflow/dags/tes_dag.py", line 5, in <module>
    from test import test2
  File "/opt/airflow/dags/test.py", line 2, in <module>
    from kaggle.api.kaggle_api_extended import KaggleApi
  File "/home/airflow/.local/lib/python3.12/site-packages/kaggle/__init__.py", line 7, in <module>
    api.authenticate()
  File "/home/airflow/.local/lib/python3.12/site-packages/kaggle/api/kaggle_api_extended.py", line 407, in authenticate
    raise IOError('Could not find {}. Make sure it\'s located in'
OSError: Could not find kaggle.json. Make sure it's located in /home/airflow/.config/kaggle. Or use the environment method. See setup instructions at https://github.com/Kaggle/kaggle-api/
[2025-01-14T17:31:49.005+0000] {processor.py:927} WARNING - No viable dags retrieved from /opt/airflow/dags/tes_dag.py
[2025-01-14T17:31:49.028+0000] {processor.py:208} INFO - Processing /opt/airflow/dags/tes_dag.py took 0.372 seconds
[2025-01-14T17:32:19.124+0000] {processor.py:186} INFO - Started process (PID=475) to work on /opt/airflow/dags/tes_dag.py
[2025-01-14T17:32:19.126+0000] {processor.py:914} INFO - Processing file /opt/airflow/dags/tes_dag.py for tasks to queue
[2025-01-14T17:32:19.129+0000] {logging_mixin.py:190} INFO - [2025-01-14T17:32:19.128+0000] {dagbag.py:588} INFO - Filling up the DagBag from /opt/airflow/dags/tes_dag.py
[2025-01-14T17:32:19.354+0000] {logging_mixin.py:190} INFO - [2025-01-14T17:32:19.341+0000] {dagbag.py:387} ERROR - Failed to import: /opt/airflow/dags/tes_dag.py
Traceback (most recent call last):
  File "/home/airflow/.local/lib/python3.12/site-packages/airflow/models/dagbag.py", line 383, in parse
    loader.exec_module(new_module)
  File "<frozen importlib._bootstrap_external>", line 999, in exec_module
  File "<frozen importlib._bootstrap>", line 488, in _call_with_frames_removed
  File "/opt/airflow/dags/tes_dag.py", line 5, in <module>
    from test import test2
  File "/opt/airflow/dags/test.py", line 2, in <module>
    from kaggle.api.kaggle_api_extended import KaggleApi
  File "/home/airflow/.local/lib/python3.12/site-packages/kaggle/__init__.py", line 7, in <module>
    api.authenticate()
  File "/home/airflow/.local/lib/python3.12/site-packages/kaggle/api/kaggle_api_extended.py", line 407, in authenticate
    raise IOError('Could not find {}. Make sure it\'s located in'
OSError: Could not find kaggle.json. Make sure it's located in /home/airflow/.config/kaggle. Or use the environment method. See setup instructions at https://github.com/Kaggle/kaggle-api/
[2025-01-14T17:32:19.356+0000] {processor.py:927} WARNING - No viable dags retrieved from /opt/airflow/dags/tes_dag.py
[2025-01-14T17:32:19.393+0000] {processor.py:208} INFO - Processing /opt/airflow/dags/tes_dag.py took 0.281 seconds
[2025-01-14T17:32:49.830+0000] {processor.py:186} INFO - Started process (PID=502) to work on /opt/airflow/dags/tes_dag.py
[2025-01-14T17:32:49.831+0000] {processor.py:914} INFO - Processing file /opt/airflow/dags/tes_dag.py for tasks to queue
[2025-01-14T17:32:49.833+0000] {logging_mixin.py:190} INFO - [2025-01-14T17:32:49.833+0000] {dagbag.py:588} INFO - Filling up the DagBag from /opt/airflow/dags/tes_dag.py
[2025-01-14T17:32:50.041+0000] {logging_mixin.py:190} INFO - [2025-01-14T17:32:50.030+0000] {dagbag.py:387} ERROR - Failed to import: /opt/airflow/dags/tes_dag.py
Traceback (most recent call last):
  File "/home/airflow/.local/lib/python3.12/site-packages/airflow/models/dagbag.py", line 383, in parse
    loader.exec_module(new_module)
  File "<frozen importlib._bootstrap_external>", line 999, in exec_module
  File "<frozen importlib._bootstrap>", line 488, in _call_with_frames_removed
  File "/opt/airflow/dags/tes_dag.py", line 5, in <module>
    from test import test2
  File "/opt/airflow/dags/test.py", line 2, in <module>
    from kaggle.api.kaggle_api_extended import KaggleApi
  File "/home/airflow/.local/lib/python3.12/site-packages/kaggle/__init__.py", line 7, in <module>
    api.authenticate()
  File "/home/airflow/.local/lib/python3.12/site-packages/kaggle/api/kaggle_api_extended.py", line 407, in authenticate
    raise IOError('Could not find {}. Make sure it\'s located in'
OSError: Could not find kaggle.json. Make sure it's located in /home/airflow/.config/kaggle. Or use the environment method. See setup instructions at https://github.com/Kaggle/kaggle-api/
[2025-01-14T17:32:50.043+0000] {processor.py:927} WARNING - No viable dags retrieved from /opt/airflow/dags/tes_dag.py
[2025-01-14T17:32:50.069+0000] {processor.py:208} INFO - Processing /opt/airflow/dags/tes_dag.py took 0.250 seconds
[2025-01-14T17:33:20.256+0000] {processor.py:186} INFO - Started process (PID=524) to work on /opt/airflow/dags/tes_dag.py
[2025-01-14T17:33:20.257+0000] {processor.py:914} INFO - Processing file /opt/airflow/dags/tes_dag.py for tasks to queue
[2025-01-14T17:33:20.259+0000] {logging_mixin.py:190} INFO - [2025-01-14T17:33:20.259+0000] {dagbag.py:588} INFO - Filling up the DagBag from /opt/airflow/dags/tes_dag.py
[2025-01-14T17:33:20.611+0000] {logging_mixin.py:190} INFO - [2025-01-14T17:33:20.597+0000] {dagbag.py:387} ERROR - Failed to import: /opt/airflow/dags/tes_dag.py
Traceback (most recent call last):
  File "/home/airflow/.local/lib/python3.12/site-packages/airflow/models/dagbag.py", line 383, in parse
    loader.exec_module(new_module)
  File "<frozen importlib._bootstrap_external>", line 999, in exec_module
  File "<frozen importlib._bootstrap>", line 488, in _call_with_frames_removed
  File "/opt/airflow/dags/tes_dag.py", line 5, in <module>
    from test import test2
  File "/opt/airflow/dags/test.py", line 2, in <module>
    from kaggle.api.kaggle_api_extended import KaggleApi
  File "/home/airflow/.local/lib/python3.12/site-packages/kaggle/__init__.py", line 7, in <module>
    api.authenticate()
  File "/home/airflow/.local/lib/python3.12/site-packages/kaggle/api/kaggle_api_extended.py", line 407, in authenticate
    raise IOError('Could not find {}. Make sure it\'s located in'
OSError: Could not find kaggle.json. Make sure it's located in /home/airflow/.config/kaggle. Or use the environment method. See setup instructions at https://github.com/Kaggle/kaggle-api/
[2025-01-14T17:33:20.612+0000] {processor.py:927} WARNING - No viable dags retrieved from /opt/airflow/dags/tes_dag.py
[2025-01-14T17:33:20.636+0000] {processor.py:208} INFO - Processing /opt/airflow/dags/tes_dag.py took 0.389 seconds
[2025-01-14T17:33:51.022+0000] {processor.py:186} INFO - Started process (PID=546) to work on /opt/airflow/dags/tes_dag.py
[2025-01-14T17:33:51.024+0000] {processor.py:914} INFO - Processing file /opt/airflow/dags/tes_dag.py for tasks to queue
[2025-01-14T17:33:51.026+0000] {logging_mixin.py:190} INFO - [2025-01-14T17:33:51.026+0000] {dagbag.py:588} INFO - Filling up the DagBag from /opt/airflow/dags/tes_dag.py
[2025-01-14T17:33:51.374+0000] {logging_mixin.py:190} INFO - [2025-01-14T17:33:51.359+0000] {dagbag.py:387} ERROR - Failed to import: /opt/airflow/dags/tes_dag.py
Traceback (most recent call last):
  File "/home/airflow/.local/lib/python3.12/site-packages/airflow/models/dagbag.py", line 383, in parse
    loader.exec_module(new_module)
  File "<frozen importlib._bootstrap_external>", line 999, in exec_module
  File "<frozen importlib._bootstrap>", line 488, in _call_with_frames_removed
  File "/opt/airflow/dags/tes_dag.py", line 5, in <module>
    from test import test2
  File "/opt/airflow/dags/test.py", line 2, in <module>
    from kaggle.api.kaggle_api_extended import KaggleApi
  File "/home/airflow/.local/lib/python3.12/site-packages/kaggle/__init__.py", line 7, in <module>
    api.authenticate()
  File "/home/airflow/.local/lib/python3.12/site-packages/kaggle/api/kaggle_api_extended.py", line 407, in authenticate
    raise IOError('Could not find {}. Make sure it\'s located in'
OSError: Could not find kaggle.json. Make sure it's located in /home/airflow/.config/kaggle. Or use the environment method. See setup instructions at https://github.com/Kaggle/kaggle-api/
[2025-01-14T17:33:51.376+0000] {processor.py:927} WARNING - No viable dags retrieved from /opt/airflow/dags/tes_dag.py
[2025-01-14T17:33:51.408+0000] {processor.py:208} INFO - Processing /opt/airflow/dags/tes_dag.py took 0.397 seconds
[2025-01-14T17:34:21.649+0000] {processor.py:186} INFO - Started process (PID=568) to work on /opt/airflow/dags/tes_dag.py
[2025-01-14T17:34:21.652+0000] {processor.py:914} INFO - Processing file /opt/airflow/dags/tes_dag.py for tasks to queue
[2025-01-14T17:34:21.654+0000] {logging_mixin.py:190} INFO - [2025-01-14T17:34:21.654+0000] {dagbag.py:588} INFO - Filling up the DagBag from /opt/airflow/dags/tes_dag.py
[2025-01-14T17:34:21.997+0000] {logging_mixin.py:190} INFO - [2025-01-14T17:34:21.985+0000] {dagbag.py:387} ERROR - Failed to import: /opt/airflow/dags/tes_dag.py
Traceback (most recent call last):
  File "/home/airflow/.local/lib/python3.12/site-packages/airflow/models/dagbag.py", line 383, in parse
    loader.exec_module(new_module)
  File "<frozen importlib._bootstrap_external>", line 999, in exec_module
  File "<frozen importlib._bootstrap>", line 488, in _call_with_frames_removed
  File "/opt/airflow/dags/tes_dag.py", line 5, in <module>
    from test import test2
  File "/opt/airflow/dags/test.py", line 2, in <module>
    from kaggle.api.kaggle_api_extended import KaggleApi
  File "/home/airflow/.local/lib/python3.12/site-packages/kaggle/__init__.py", line 7, in <module>
    api.authenticate()
  File "/home/airflow/.local/lib/python3.12/site-packages/kaggle/api/kaggle_api_extended.py", line 407, in authenticate
    raise IOError('Could not find {}. Make sure it\'s located in'
OSError: Could not find kaggle.json. Make sure it's located in /home/airflow/.config/kaggle. Or use the environment method. See setup instructions at https://github.com/Kaggle/kaggle-api/
[2025-01-14T17:34:21.998+0000] {processor.py:927} WARNING - No viable dags retrieved from /opt/airflow/dags/tes_dag.py
[2025-01-14T17:34:22.019+0000] {processor.py:208} INFO - Processing /opt/airflow/dags/tes_dag.py took 0.380 seconds
[2025-01-14T17:34:52.433+0000] {processor.py:186} INFO - Started process (PID=590) to work on /opt/airflow/dags/tes_dag.py
[2025-01-14T17:34:52.435+0000] {processor.py:914} INFO - Processing file /opt/airflow/dags/tes_dag.py for tasks to queue
[2025-01-14T17:34:52.438+0000] {logging_mixin.py:190} INFO - [2025-01-14T17:34:52.437+0000] {dagbag.py:588} INFO - Filling up the DagBag from /opt/airflow/dags/tes_dag.py
[2025-01-14T17:34:52.994+0000] {logging_mixin.py:190} INFO - [2025-01-14T17:34:52.981+0000] {dagbag.py:387} ERROR - Failed to import: /opt/airflow/dags/tes_dag.py
Traceback (most recent call last):
  File "/home/airflow/.local/lib/python3.12/site-packages/airflow/models/dagbag.py", line 383, in parse
    loader.exec_module(new_module)
  File "<frozen importlib._bootstrap_external>", line 999, in exec_module
  File "<frozen importlib._bootstrap>", line 488, in _call_with_frames_removed
  File "/opt/airflow/dags/tes_dag.py", line 5, in <module>
    from test import test2
  File "/opt/airflow/dags/test.py", line 2, in <module>
    from kaggle.api.kaggle_api_extended import KaggleApi
  File "/home/airflow/.local/lib/python3.12/site-packages/kaggle/__init__.py", line 7, in <module>
    api.authenticate()
  File "/home/airflow/.local/lib/python3.12/site-packages/kaggle/api/kaggle_api_extended.py", line 407, in authenticate
    raise IOError('Could not find {}. Make sure it\'s located in'
OSError: Could not find kaggle.json. Make sure it's located in /home/airflow/.config/kaggle. Or use the environment method. See setup instructions at https://github.com/Kaggle/kaggle-api/
[2025-01-14T17:34:52.996+0000] {processor.py:927} WARNING - No viable dags retrieved from /opt/airflow/dags/tes_dag.py
[2025-01-14T17:34:53.028+0000] {processor.py:208} INFO - Processing /opt/airflow/dags/tes_dag.py took 0.604 seconds
[2025-01-14T17:35:23.448+0000] {processor.py:186} INFO - Started process (PID=612) to work on /opt/airflow/dags/tes_dag.py
[2025-01-14T17:35:23.450+0000] {processor.py:914} INFO - Processing file /opt/airflow/dags/tes_dag.py for tasks to queue
[2025-01-14T17:35:23.453+0000] {logging_mixin.py:190} INFO - [2025-01-14T17:35:23.452+0000] {dagbag.py:588} INFO - Filling up the DagBag from /opt/airflow/dags/tes_dag.py
[2025-01-14T17:35:23.629+0000] {logging_mixin.py:190} INFO - [2025-01-14T17:35:23.619+0000] {dagbag.py:387} ERROR - Failed to import: /opt/airflow/dags/tes_dag.py
Traceback (most recent call last):
  File "/home/airflow/.local/lib/python3.12/site-packages/airflow/models/dagbag.py", line 383, in parse
    loader.exec_module(new_module)
  File "<frozen importlib._bootstrap_external>", line 999, in exec_module
  File "<frozen importlib._bootstrap>", line 488, in _call_with_frames_removed
  File "/opt/airflow/dags/tes_dag.py", line 5, in <module>
    from test import test2
  File "/opt/airflow/dags/test.py", line 2, in <module>
    from kaggle.api.kaggle_api_extended import KaggleApi
  File "/home/airflow/.local/lib/python3.12/site-packages/kaggle/__init__.py", line 7, in <module>
    api.authenticate()
  File "/home/airflow/.local/lib/python3.12/site-packages/kaggle/api/kaggle_api_extended.py", line 407, in authenticate
    raise IOError('Could not find {}. Make sure it\'s located in'
OSError: Could not find kaggle.json. Make sure it's located in /home/airflow/.config/kaggle. Or use the environment method. See setup instructions at https://github.com/Kaggle/kaggle-api/
[2025-01-14T17:35:23.630+0000] {processor.py:927} WARNING - No viable dags retrieved from /opt/airflow/dags/tes_dag.py
[2025-01-14T17:35:23.662+0000] {processor.py:208} INFO - Processing /opt/airflow/dags/tes_dag.py took 0.224 seconds
[2025-01-14T17:35:54.022+0000] {processor.py:186} INFO - Started process (PID=634) to work on /opt/airflow/dags/tes_dag.py
[2025-01-14T17:35:54.024+0000] {processor.py:914} INFO - Processing file /opt/airflow/dags/tes_dag.py for tasks to queue
[2025-01-14T17:35:54.028+0000] {logging_mixin.py:190} INFO - [2025-01-14T17:35:54.027+0000] {dagbag.py:588} INFO - Filling up the DagBag from /opt/airflow/dags/tes_dag.py
[2025-01-14T17:35:54.205+0000] {logging_mixin.py:190} INFO - [2025-01-14T17:35:54.194+0000] {dagbag.py:387} ERROR - Failed to import: /opt/airflow/dags/tes_dag.py
Traceback (most recent call last):
  File "/home/airflow/.local/lib/python3.12/site-packages/airflow/models/dagbag.py", line 383, in parse
    loader.exec_module(new_module)
  File "<frozen importlib._bootstrap_external>", line 999, in exec_module
  File "<frozen importlib._bootstrap>", line 488, in _call_with_frames_removed
  File "/opt/airflow/dags/tes_dag.py", line 5, in <module>
    from test import test2
  File "/opt/airflow/dags/test.py", line 2, in <module>
    from kaggle.api.kaggle_api_extended import KaggleApi
  File "/home/airflow/.local/lib/python3.12/site-packages/kaggle/__init__.py", line 7, in <module>
    api.authenticate()
  File "/home/airflow/.local/lib/python3.12/site-packages/kaggle/api/kaggle_api_extended.py", line 407, in authenticate
    raise IOError('Could not find {}. Make sure it\'s located in'
OSError: Could not find kaggle.json. Make sure it's located in /home/airflow/.config/kaggle. Or use the environment method. See setup instructions at https://github.com/Kaggle/kaggle-api/
[2025-01-14T17:35:54.206+0000] {processor.py:927} WARNING - No viable dags retrieved from /opt/airflow/dags/tes_dag.py
[2025-01-14T17:35:54.230+0000] {processor.py:208} INFO - Processing /opt/airflow/dags/tes_dag.py took 0.225 seconds
[2025-01-14T17:36:24.416+0000] {processor.py:186} INFO - Started process (PID=656) to work on /opt/airflow/dags/tes_dag.py
[2025-01-14T17:36:24.418+0000] {processor.py:914} INFO - Processing file /opt/airflow/dags/tes_dag.py for tasks to queue
[2025-01-14T17:36:24.421+0000] {logging_mixin.py:190} INFO - [2025-01-14T17:36:24.420+0000] {dagbag.py:588} INFO - Filling up the DagBag from /opt/airflow/dags/tes_dag.py
[2025-01-14T17:36:24.814+0000] {logging_mixin.py:190} INFO - [2025-01-14T17:36:24.803+0000] {dagbag.py:387} ERROR - Failed to import: /opt/airflow/dags/tes_dag.py
Traceback (most recent call last):
  File "/home/airflow/.local/lib/python3.12/site-packages/airflow/models/dagbag.py", line 383, in parse
    loader.exec_module(new_module)
  File "<frozen importlib._bootstrap_external>", line 999, in exec_module
  File "<frozen importlib._bootstrap>", line 488, in _call_with_frames_removed
  File "/opt/airflow/dags/tes_dag.py", line 5, in <module>
    from test import test2
  File "/opt/airflow/dags/test.py", line 2, in <module>
    from kaggle.api.kaggle_api_extended import KaggleApi
  File "/home/airflow/.local/lib/python3.12/site-packages/kaggle/__init__.py", line 7, in <module>
    api.authenticate()
  File "/home/airflow/.local/lib/python3.12/site-packages/kaggle/api/kaggle_api_extended.py", line 407, in authenticate
    raise IOError('Could not find {}. Make sure it\'s located in'
OSError: Could not find kaggle.json. Make sure it's located in /home/airflow/.config/kaggle. Or use the environment method. See setup instructions at https://github.com/Kaggle/kaggle-api/
[2025-01-14T17:36:24.816+0000] {processor.py:927} WARNING - No viable dags retrieved from /opt/airflow/dags/tes_dag.py
[2025-01-14T17:36:24.836+0000] {processor.py:208} INFO - Processing /opt/airflow/dags/tes_dag.py took 0.430 seconds
[2025-01-14T17:36:55.116+0000] {processor.py:186} INFO - Started process (PID=678) to work on /opt/airflow/dags/tes_dag.py
[2025-01-14T17:36:55.117+0000] {processor.py:914} INFO - Processing file /opt/airflow/dags/tes_dag.py for tasks to queue
[2025-01-14T17:36:55.119+0000] {logging_mixin.py:190} INFO - [2025-01-14T17:36:55.118+0000] {dagbag.py:588} INFO - Filling up the DagBag from /opt/airflow/dags/tes_dag.py
[2025-01-14T17:36:55.509+0000] {logging_mixin.py:190} INFO - [2025-01-14T17:36:55.497+0000] {dagbag.py:387} ERROR - Failed to import: /opt/airflow/dags/tes_dag.py
Traceback (most recent call last):
  File "/home/airflow/.local/lib/python3.12/site-packages/airflow/models/dagbag.py", line 383, in parse
    loader.exec_module(new_module)
  File "<frozen importlib._bootstrap_external>", line 999, in exec_module
  File "<frozen importlib._bootstrap>", line 488, in _call_with_frames_removed
  File "/opt/airflow/dags/tes_dag.py", line 5, in <module>
    from test import test2
  File "/opt/airflow/dags/test.py", line 2, in <module>
    from kaggle.api.kaggle_api_extended import KaggleApi
  File "/home/airflow/.local/lib/python3.12/site-packages/kaggle/__init__.py", line 7, in <module>
    api.authenticate()
  File "/home/airflow/.local/lib/python3.12/site-packages/kaggle/api/kaggle_api_extended.py", line 407, in authenticate
    raise IOError('Could not find {}. Make sure it\'s located in'
OSError: Could not find kaggle.json. Make sure it's located in /home/airflow/.config/kaggle. Or use the environment method. See setup instructions at https://github.com/Kaggle/kaggle-api/
[2025-01-14T17:36:55.510+0000] {processor.py:927} WARNING - No viable dags retrieved from /opt/airflow/dags/tes_dag.py
[2025-01-14T17:36:55.540+0000] {processor.py:208} INFO - Processing /opt/airflow/dags/tes_dag.py took 0.435 seconds
[2025-01-14T17:37:25.985+0000] {processor.py:186} INFO - Started process (PID=700) to work on /opt/airflow/dags/tes_dag.py
[2025-01-14T17:37:25.986+0000] {processor.py:914} INFO - Processing file /opt/airflow/dags/tes_dag.py for tasks to queue
[2025-01-14T17:37:25.988+0000] {logging_mixin.py:190} INFO - [2025-01-14T17:37:25.987+0000] {dagbag.py:588} INFO - Filling up the DagBag from /opt/airflow/dags/tes_dag.py
[2025-01-14T17:37:26.347+0000] {logging_mixin.py:190} INFO - [2025-01-14T17:37:26.332+0000] {dagbag.py:387} ERROR - Failed to import: /opt/airflow/dags/tes_dag.py
Traceback (most recent call last):
  File "/home/airflow/.local/lib/python3.12/site-packages/airflow/models/dagbag.py", line 383, in parse
    loader.exec_module(new_module)
  File "<frozen importlib._bootstrap_external>", line 999, in exec_module
  File "<frozen importlib._bootstrap>", line 488, in _call_with_frames_removed
  File "/opt/airflow/dags/tes_dag.py", line 5, in <module>
    from test import test2
  File "/opt/airflow/dags/test.py", line 2, in <module>
    from kaggle.api.kaggle_api_extended import KaggleApi
  File "/home/airflow/.local/lib/python3.12/site-packages/kaggle/__init__.py", line 7, in <module>
    api.authenticate()
  File "/home/airflow/.local/lib/python3.12/site-packages/kaggle/api/kaggle_api_extended.py", line 407, in authenticate
    raise IOError('Could not find {}. Make sure it\'s located in'
OSError: Could not find kaggle.json. Make sure it's located in /home/airflow/.config/kaggle. Or use the environment method. See setup instructions at https://github.com/Kaggle/kaggle-api/
[2025-01-14T17:37:26.348+0000] {processor.py:927} WARNING - No viable dags retrieved from /opt/airflow/dags/tes_dag.py
[2025-01-14T17:37:26.371+0000] {processor.py:208} INFO - Processing /opt/airflow/dags/tes_dag.py took 0.395 seconds
[2025-01-14T17:37:56.489+0000] {processor.py:186} INFO - Started process (PID=722) to work on /opt/airflow/dags/tes_dag.py
[2025-01-14T17:37:56.490+0000] {processor.py:914} INFO - Processing file /opt/airflow/dags/tes_dag.py for tasks to queue
[2025-01-14T17:37:56.492+0000] {logging_mixin.py:190} INFO - [2025-01-14T17:37:56.492+0000] {dagbag.py:588} INFO - Filling up the DagBag from /opt/airflow/dags/tes_dag.py
[2025-01-14T17:37:56.681+0000] {logging_mixin.py:190} INFO - [2025-01-14T17:37:56.669+0000] {dagbag.py:387} ERROR - Failed to import: /opt/airflow/dags/tes_dag.py
Traceback (most recent call last):
  File "/home/airflow/.local/lib/python3.12/site-packages/airflow/models/dagbag.py", line 383, in parse
    loader.exec_module(new_module)
  File "<frozen importlib._bootstrap_external>", line 999, in exec_module
  File "<frozen importlib._bootstrap>", line 488, in _call_with_frames_removed
  File "/opt/airflow/dags/tes_dag.py", line 5, in <module>
    from test import test2
  File "/opt/airflow/dags/test.py", line 2, in <module>
    from kaggle.api.kaggle_api_extended import KaggleApi
  File "/home/airflow/.local/lib/python3.12/site-packages/kaggle/__init__.py", line 7, in <module>
    api.authenticate()
  File "/home/airflow/.local/lib/python3.12/site-packages/kaggle/api/kaggle_api_extended.py", line 407, in authenticate
    raise IOError('Could not find {}. Make sure it\'s located in'
OSError: Could not find kaggle.json. Make sure it's located in /home/airflow/.config/kaggle. Or use the environment method. See setup instructions at https://github.com/Kaggle/kaggle-api/
[2025-01-14T17:37:56.683+0000] {processor.py:927} WARNING - No viable dags retrieved from /opt/airflow/dags/tes_dag.py
[2025-01-14T17:37:56.707+0000] {processor.py:208} INFO - Processing /opt/airflow/dags/tes_dag.py took 0.230 seconds
[2025-01-14T17:38:27.246+0000] {processor.py:186} INFO - Started process (PID=743) to work on /opt/airflow/dags/tes_dag.py
[2025-01-14T17:38:27.248+0000] {processor.py:914} INFO - Processing file /opt/airflow/dags/tes_dag.py for tasks to queue
[2025-01-14T17:38:27.250+0000] {logging_mixin.py:190} INFO - [2025-01-14T17:38:27.249+0000] {dagbag.py:588} INFO - Filling up the DagBag from /opt/airflow/dags/tes_dag.py
[2025-01-14T17:38:27.411+0000] {logging_mixin.py:190} INFO - [2025-01-14T17:38:27.400+0000] {dagbag.py:387} ERROR - Failed to import: /opt/airflow/dags/tes_dag.py
Traceback (most recent call last):
  File "/home/airflow/.local/lib/python3.12/site-packages/airflow/models/dagbag.py", line 383, in parse
    loader.exec_module(new_module)
  File "<frozen importlib._bootstrap_external>", line 999, in exec_module
  File "<frozen importlib._bootstrap>", line 488, in _call_with_frames_removed
  File "/opt/airflow/dags/tes_dag.py", line 5, in <module>
    from test import test2
  File "/opt/airflow/dags/test.py", line 2, in <module>
    from kaggle.api.kaggle_api_extended import KaggleApi
  File "/home/airflow/.local/lib/python3.12/site-packages/kaggle/__init__.py", line 7, in <module>
    api.authenticate()
  File "/home/airflow/.local/lib/python3.12/site-packages/kaggle/api/kaggle_api_extended.py", line 407, in authenticate
    raise IOError('Could not find {}. Make sure it\'s located in'
OSError: Could not find kaggle.json. Make sure it's located in /home/airflow/.config/kaggle. Or use the environment method. See setup instructions at https://github.com/Kaggle/kaggle-api/
[2025-01-14T17:38:27.412+0000] {processor.py:927} WARNING - No viable dags retrieved from /opt/airflow/dags/tes_dag.py
[2025-01-14T17:38:27.444+0000] {processor.py:208} INFO - Processing /opt/airflow/dags/tes_dag.py took 0.206 seconds
[2025-01-14T17:38:57.806+0000] {processor.py:186} INFO - Started process (PID=765) to work on /opt/airflow/dags/tes_dag.py
[2025-01-14T17:38:57.808+0000] {processor.py:914} INFO - Processing file /opt/airflow/dags/tes_dag.py for tasks to queue
[2025-01-14T17:38:57.812+0000] {logging_mixin.py:190} INFO - [2025-01-14T17:38:57.811+0000] {dagbag.py:588} INFO - Filling up the DagBag from /opt/airflow/dags/tes_dag.py
[2025-01-14T17:38:58.006+0000] {logging_mixin.py:190} INFO - [2025-01-14T17:38:57.995+0000] {dagbag.py:387} ERROR - Failed to import: /opt/airflow/dags/tes_dag.py
Traceback (most recent call last):
  File "/home/airflow/.local/lib/python3.12/site-packages/airflow/models/dagbag.py", line 383, in parse
    loader.exec_module(new_module)
  File "<frozen importlib._bootstrap_external>", line 999, in exec_module
  File "<frozen importlib._bootstrap>", line 488, in _call_with_frames_removed
  File "/opt/airflow/dags/tes_dag.py", line 5, in <module>
    from test import test2
  File "/opt/airflow/dags/test.py", line 2, in <module>
    from kaggle.api.kaggle_api_extended import KaggleApi
  File "/home/airflow/.local/lib/python3.12/site-packages/kaggle/__init__.py", line 7, in <module>
    api.authenticate()
  File "/home/airflow/.local/lib/python3.12/site-packages/kaggle/api/kaggle_api_extended.py", line 407, in authenticate
    raise IOError('Could not find {}. Make sure it\'s located in'
OSError: Could not find kaggle.json. Make sure it's located in /home/airflow/.config/kaggle. Or use the environment method. See setup instructions at https://github.com/Kaggle/kaggle-api/
[2025-01-14T17:38:58.007+0000] {processor.py:927} WARNING - No viable dags retrieved from /opt/airflow/dags/tes_dag.py
[2025-01-14T17:38:58.278+0000] {processor.py:208} INFO - Processing /opt/airflow/dags/tes_dag.py took 0.518 seconds
[2025-01-14T17:39:28.492+0000] {processor.py:186} INFO - Started process (PID=787) to work on /opt/airflow/dags/tes_dag.py
[2025-01-14T17:39:28.493+0000] {processor.py:914} INFO - Processing file /opt/airflow/dags/tes_dag.py for tasks to queue
[2025-01-14T17:39:28.496+0000] {logging_mixin.py:190} INFO - [2025-01-14T17:39:28.495+0000] {dagbag.py:588} INFO - Filling up the DagBag from /opt/airflow/dags/tes_dag.py
[2025-01-14T17:39:28.826+0000] {logging_mixin.py:190} INFO - [2025-01-14T17:39:28.815+0000] {dagbag.py:387} ERROR - Failed to import: /opt/airflow/dags/tes_dag.py
Traceback (most recent call last):
  File "/home/airflow/.local/lib/python3.12/site-packages/airflow/models/dagbag.py", line 383, in parse
    loader.exec_module(new_module)
  File "<frozen importlib._bootstrap_external>", line 999, in exec_module
  File "<frozen importlib._bootstrap>", line 488, in _call_with_frames_removed
  File "/opt/airflow/dags/tes_dag.py", line 5, in <module>
    from test import test2
  File "/opt/airflow/dags/test.py", line 2, in <module>
    from kaggle.api.kaggle_api_extended import KaggleApi
  File "/home/airflow/.local/lib/python3.12/site-packages/kaggle/__init__.py", line 7, in <module>
    api.authenticate()
  File "/home/airflow/.local/lib/python3.12/site-packages/kaggle/api/kaggle_api_extended.py", line 407, in authenticate
    raise IOError('Could not find {}. Make sure it\'s located in'
OSError: Could not find kaggle.json. Make sure it's located in /home/airflow/.config/kaggle. Or use the environment method. See setup instructions at https://github.com/Kaggle/kaggle-api/
[2025-01-14T17:39:28.827+0000] {processor.py:927} WARNING - No viable dags retrieved from /opt/airflow/dags/tes_dag.py
[2025-01-14T17:39:28.852+0000] {processor.py:208} INFO - Processing /opt/airflow/dags/tes_dag.py took 0.368 seconds
[2025-01-14T17:39:59.344+0000] {processor.py:186} INFO - Started process (PID=809) to work on /opt/airflow/dags/tes_dag.py
[2025-01-14T17:39:59.345+0000] {processor.py:914} INFO - Processing file /opt/airflow/dags/tes_dag.py for tasks to queue
[2025-01-14T17:39:59.348+0000] {logging_mixin.py:190} INFO - [2025-01-14T17:39:59.347+0000] {dagbag.py:588} INFO - Filling up the DagBag from /opt/airflow/dags/tes_dag.py
[2025-01-14T17:39:59.767+0000] {logging_mixin.py:190} INFO - [2025-01-14T17:39:59.755+0000] {dagbag.py:387} ERROR - Failed to import: /opt/airflow/dags/tes_dag.py
Traceback (most recent call last):
  File "/home/airflow/.local/lib/python3.12/site-packages/airflow/models/dagbag.py", line 383, in parse
    loader.exec_module(new_module)
  File "<frozen importlib._bootstrap_external>", line 999, in exec_module
  File "<frozen importlib._bootstrap>", line 488, in _call_with_frames_removed
  File "/opt/airflow/dags/tes_dag.py", line 5, in <module>
    from test import test2
  File "/opt/airflow/dags/test.py", line 2, in <module>
    from kaggle.api.kaggle_api_extended import KaggleApi
  File "/home/airflow/.local/lib/python3.12/site-packages/kaggle/__init__.py", line 7, in <module>
    api.authenticate()
  File "/home/airflow/.local/lib/python3.12/site-packages/kaggle/api/kaggle_api_extended.py", line 407, in authenticate
    raise IOError('Could not find {}. Make sure it\'s located in'
OSError: Could not find kaggle.json. Make sure it's located in /home/airflow/.config/kaggle. Or use the environment method. See setup instructions at https://github.com/Kaggle/kaggle-api/
[2025-01-14T17:39:59.771+0000] {processor.py:927} WARNING - No viable dags retrieved from /opt/airflow/dags/tes_dag.py
[2025-01-14T17:39:59.794+0000] {processor.py:208} INFO - Processing /opt/airflow/dags/tes_dag.py took 0.463 seconds
[2025-01-14T17:40:30.079+0000] {processor.py:186} INFO - Started process (PID=831) to work on /opt/airflow/dags/tes_dag.py
[2025-01-14T17:40:30.081+0000] {processor.py:914} INFO - Processing file /opt/airflow/dags/tes_dag.py for tasks to queue
[2025-01-14T17:40:30.090+0000] {logging_mixin.py:190} INFO - [2025-01-14T17:40:30.082+0000] {dagbag.py:588} INFO - Filling up the DagBag from /opt/airflow/dags/tes_dag.py
[2025-01-14T17:40:30.524+0000] {logging_mixin.py:190} INFO - [2025-01-14T17:40:30.512+0000] {dagbag.py:387} ERROR - Failed to import: /opt/airflow/dags/tes_dag.py
Traceback (most recent call last):
  File "/home/airflow/.local/lib/python3.12/site-packages/airflow/models/dagbag.py", line 383, in parse
    loader.exec_module(new_module)
  File "<frozen importlib._bootstrap_external>", line 999, in exec_module
  File "<frozen importlib._bootstrap>", line 488, in _call_with_frames_removed
  File "/opt/airflow/dags/tes_dag.py", line 5, in <module>
    from test import test2
  File "/opt/airflow/dags/test.py", line 2, in <module>
    from kaggle.api.kaggle_api_extended import KaggleApi
  File "/home/airflow/.local/lib/python3.12/site-packages/kaggle/__init__.py", line 7, in <module>
    api.authenticate()
  File "/home/airflow/.local/lib/python3.12/site-packages/kaggle/api/kaggle_api_extended.py", line 407, in authenticate
    raise IOError('Could not find {}. Make sure it\'s located in'
OSError: Could not find kaggle.json. Make sure it's located in /home/airflow/.config/kaggle. Or use the environment method. See setup instructions at https://github.com/Kaggle/kaggle-api/
[2025-01-14T17:40:30.526+0000] {processor.py:927} WARNING - No viable dags retrieved from /opt/airflow/dags/tes_dag.py
[2025-01-14T17:40:30.559+0000] {processor.py:208} INFO - Processing /opt/airflow/dags/tes_dag.py took 0.498 seconds
[2025-01-14T17:41:00.751+0000] {processor.py:186} INFO - Started process (PID=853) to work on /opt/airflow/dags/tes_dag.py
[2025-01-14T17:41:00.754+0000] {processor.py:914} INFO - Processing file /opt/airflow/dags/tes_dag.py for tasks to queue
[2025-01-14T17:41:00.757+0000] {logging_mixin.py:190} INFO - [2025-01-14T17:41:00.756+0000] {dagbag.py:588} INFO - Filling up the DagBag from /opt/airflow/dags/tes_dag.py
[2025-01-14T17:41:01.135+0000] {logging_mixin.py:190} INFO - [2025-01-14T17:41:01.123+0000] {dagbag.py:387} ERROR - Failed to import: /opt/airflow/dags/tes_dag.py
Traceback (most recent call last):
  File "/home/airflow/.local/lib/python3.12/site-packages/airflow/models/dagbag.py", line 383, in parse
    loader.exec_module(new_module)
  File "<frozen importlib._bootstrap_external>", line 999, in exec_module
  File "<frozen importlib._bootstrap>", line 488, in _call_with_frames_removed
  File "/opt/airflow/dags/tes_dag.py", line 5, in <module>
    from test import test2
  File "/opt/airflow/dags/test.py", line 2, in <module>
    from kaggle.api.kaggle_api_extended import KaggleApi
  File "/home/airflow/.local/lib/python3.12/site-packages/kaggle/__init__.py", line 7, in <module>
    api.authenticate()
  File "/home/airflow/.local/lib/python3.12/site-packages/kaggle/api/kaggle_api_extended.py", line 407, in authenticate
    raise IOError('Could not find {}. Make sure it\'s located in'
OSError: Could not find kaggle.json. Make sure it's located in /home/airflow/.config/kaggle. Or use the environment method. See setup instructions at https://github.com/Kaggle/kaggle-api/
[2025-01-14T17:41:01.136+0000] {processor.py:927} WARNING - No viable dags retrieved from /opt/airflow/dags/tes_dag.py
[2025-01-14T17:41:01.161+0000] {processor.py:208} INFO - Processing /opt/airflow/dags/tes_dag.py took 0.423 seconds
[2025-01-14T17:41:31.423+0000] {processor.py:186} INFO - Started process (PID=875) to work on /opt/airflow/dags/tes_dag.py
[2025-01-14T17:41:31.425+0000] {processor.py:914} INFO - Processing file /opt/airflow/dags/tes_dag.py for tasks to queue
[2025-01-14T17:41:31.429+0000] {logging_mixin.py:190} INFO - [2025-01-14T17:41:31.427+0000] {dagbag.py:588} INFO - Filling up the DagBag from /opt/airflow/dags/tes_dag.py
[2025-01-14T17:41:31.631+0000] {logging_mixin.py:190} INFO - [2025-01-14T17:41:31.620+0000] {dagbag.py:387} ERROR - Failed to import: /opt/airflow/dags/tes_dag.py
Traceback (most recent call last):
  File "/home/airflow/.local/lib/python3.12/site-packages/airflow/models/dagbag.py", line 383, in parse
    loader.exec_module(new_module)
  File "<frozen importlib._bootstrap_external>", line 999, in exec_module
  File "<frozen importlib._bootstrap>", line 488, in _call_with_frames_removed
  File "/opt/airflow/dags/tes_dag.py", line 5, in <module>
    from test import test2
  File "/opt/airflow/dags/test.py", line 2, in <module>
    from kaggle.api.kaggle_api_extended import KaggleApi
  File "/home/airflow/.local/lib/python3.12/site-packages/kaggle/__init__.py", line 7, in <module>
    api.authenticate()
  File "/home/airflow/.local/lib/python3.12/site-packages/kaggle/api/kaggle_api_extended.py", line 407, in authenticate
    raise IOError('Could not find {}. Make sure it\'s located in'
OSError: Could not find kaggle.json. Make sure it's located in /home/airflow/.config/kaggle. Or use the environment method. See setup instructions at https://github.com/Kaggle/kaggle-api/
[2025-01-14T17:41:31.632+0000] {processor.py:927} WARNING - No viable dags retrieved from /opt/airflow/dags/tes_dag.py
[2025-01-14T17:41:31.660+0000] {processor.py:208} INFO - Processing /opt/airflow/dags/tes_dag.py took 0.248 seconds
[2025-01-14T17:42:02.109+0000] {processor.py:186} INFO - Started process (PID=897) to work on /opt/airflow/dags/tes_dag.py
[2025-01-14T17:42:02.110+0000] {processor.py:914} INFO - Processing file /opt/airflow/dags/tes_dag.py for tasks to queue
[2025-01-14T17:42:02.113+0000] {logging_mixin.py:190} INFO - [2025-01-14T17:42:02.112+0000] {dagbag.py:588} INFO - Filling up the DagBag from /opt/airflow/dags/tes_dag.py
[2025-01-14T17:42:02.479+0000] {logging_mixin.py:190} INFO - [2025-01-14T17:42:02.469+0000] {dagbag.py:387} ERROR - Failed to import: /opt/airflow/dags/tes_dag.py
Traceback (most recent call last):
  File "/home/airflow/.local/lib/python3.12/site-packages/airflow/models/dagbag.py", line 383, in parse
    loader.exec_module(new_module)
  File "<frozen importlib._bootstrap_external>", line 999, in exec_module
  File "<frozen importlib._bootstrap>", line 488, in _call_with_frames_removed
  File "/opt/airflow/dags/tes_dag.py", line 5, in <module>
    from test import test2
  File "/opt/airflow/dags/test.py", line 2, in <module>
    from kaggle.api.kaggle_api_extended import KaggleApi
  File "/home/airflow/.local/lib/python3.12/site-packages/kaggle/__init__.py", line 7, in <module>
    api.authenticate()
  File "/home/airflow/.local/lib/python3.12/site-packages/kaggle/api/kaggle_api_extended.py", line 407, in authenticate
    raise IOError('Could not find {}. Make sure it\'s located in'
OSError: Could not find kaggle.json. Make sure it's located in /home/airflow/.config/kaggle. Or use the environment method. See setup instructions at https://github.com/Kaggle/kaggle-api/
[2025-01-14T17:42:02.480+0000] {processor.py:927} WARNING - No viable dags retrieved from /opt/airflow/dags/tes_dag.py
[2025-01-14T17:42:02.505+0000] {processor.py:208} INFO - Processing /opt/airflow/dags/tes_dag.py took 0.405 seconds
[2025-01-14T17:42:32.981+0000] {processor.py:186} INFO - Started process (PID=919) to work on /opt/airflow/dags/tes_dag.py
[2025-01-14T17:42:32.983+0000] {processor.py:914} INFO - Processing file /opt/airflow/dags/tes_dag.py for tasks to queue
[2025-01-14T17:42:32.986+0000] {logging_mixin.py:190} INFO - [2025-01-14T17:42:32.985+0000] {dagbag.py:588} INFO - Filling up the DagBag from /opt/airflow/dags/tes_dag.py
[2025-01-14T17:42:33.526+0000] {logging_mixin.py:190} INFO - [2025-01-14T17:42:33.432+0000] {dagbag.py:387} ERROR - Failed to import: /opt/airflow/dags/tes_dag.py
Traceback (most recent call last):
  File "/home/airflow/.local/lib/python3.12/site-packages/airflow/models/dagbag.py", line 383, in parse
    loader.exec_module(new_module)
  File "<frozen importlib._bootstrap_external>", line 999, in exec_module
  File "<frozen importlib._bootstrap>", line 488, in _call_with_frames_removed
  File "/opt/airflow/dags/tes_dag.py", line 5, in <module>
    from test import test2
  File "/opt/airflow/dags/test.py", line 2, in <module>
    from kaggle.api.kaggle_api_extended import KaggleApi
  File "/home/airflow/.local/lib/python3.12/site-packages/kaggle/__init__.py", line 7, in <module>
    api.authenticate()
  File "/home/airflow/.local/lib/python3.12/site-packages/kaggle/api/kaggle_api_extended.py", line 407, in authenticate
    raise IOError('Could not find {}. Make sure it\'s located in'
OSError: Could not find kaggle.json. Make sure it's located in /home/airflow/.config/kaggle. Or use the environment method. See setup instructions at https://github.com/Kaggle/kaggle-api/
[2025-01-14T17:42:33.528+0000] {processor.py:927} WARNING - No viable dags retrieved from /opt/airflow/dags/tes_dag.py
[2025-01-14T17:42:33.602+0000] {processor.py:208} INFO - Processing /opt/airflow/dags/tes_dag.py took 0.640 seconds
[2025-01-14T17:43:04.295+0000] {processor.py:186} INFO - Started process (PID=941) to work on /opt/airflow/dags/tes_dag.py
[2025-01-14T17:43:04.298+0000] {processor.py:914} INFO - Processing file /opt/airflow/dags/tes_dag.py for tasks to queue
[2025-01-14T17:43:04.300+0000] {logging_mixin.py:190} INFO - [2025-01-14T17:43:04.300+0000] {dagbag.py:588} INFO - Filling up the DagBag from /opt/airflow/dags/tes_dag.py
[2025-01-14T17:43:04.773+0000] {logging_mixin.py:190} INFO - [2025-01-14T17:43:04.760+0000] {dagbag.py:387} ERROR - Failed to import: /opt/airflow/dags/tes_dag.py
Traceback (most recent call last):
  File "/home/airflow/.local/lib/python3.12/site-packages/airflow/models/dagbag.py", line 383, in parse
    loader.exec_module(new_module)
  File "<frozen importlib._bootstrap_external>", line 999, in exec_module
  File "<frozen importlib._bootstrap>", line 488, in _call_with_frames_removed
  File "/opt/airflow/dags/tes_dag.py", line 5, in <module>
    from test import test2
  File "/opt/airflow/dags/test.py", line 2, in <module>
    from kaggle.api.kaggle_api_extended import KaggleApi
  File "/home/airflow/.local/lib/python3.12/site-packages/kaggle/__init__.py", line 7, in <module>
    api.authenticate()
  File "/home/airflow/.local/lib/python3.12/site-packages/kaggle/api/kaggle_api_extended.py", line 407, in authenticate
    raise IOError('Could not find {}. Make sure it\'s located in'
OSError: Could not find kaggle.json. Make sure it's located in /home/airflow/.config/kaggle. Or use the environment method. See setup instructions at https://github.com/Kaggle/kaggle-api/
[2025-01-14T17:43:04.775+0000] {processor.py:927} WARNING - No viable dags retrieved from /opt/airflow/dags/tes_dag.py
[2025-01-14T17:43:04.805+0000] {processor.py:208} INFO - Processing /opt/airflow/dags/tes_dag.py took 0.526 seconds
[2025-01-14T17:43:35.131+0000] {processor.py:186} INFO - Started process (PID=963) to work on /opt/airflow/dags/tes_dag.py
[2025-01-14T17:43:35.133+0000] {processor.py:914} INFO - Processing file /opt/airflow/dags/tes_dag.py for tasks to queue
[2025-01-14T17:43:35.135+0000] {logging_mixin.py:190} INFO - [2025-01-14T17:43:35.135+0000] {dagbag.py:588} INFO - Filling up the DagBag from /opt/airflow/dags/tes_dag.py
[2025-01-14T17:43:35.624+0000] {logging_mixin.py:190} INFO - [2025-01-14T17:43:35.607+0000] {dagbag.py:387} ERROR - Failed to import: /opt/airflow/dags/tes_dag.py
Traceback (most recent call last):
  File "/home/airflow/.local/lib/python3.12/site-packages/airflow/models/dagbag.py", line 383, in parse
    loader.exec_module(new_module)
  File "<frozen importlib._bootstrap_external>", line 999, in exec_module
  File "<frozen importlib._bootstrap>", line 488, in _call_with_frames_removed
  File "/opt/airflow/dags/tes_dag.py", line 5, in <module>
    from test import test2
  File "/opt/airflow/dags/test.py", line 2, in <module>
    from kaggle.api.kaggle_api_extended import KaggleApi
  File "/home/airflow/.local/lib/python3.12/site-packages/kaggle/__init__.py", line 7, in <module>
    api.authenticate()
  File "/home/airflow/.local/lib/python3.12/site-packages/kaggle/api/kaggle_api_extended.py", line 407, in authenticate
    raise IOError('Could not find {}. Make sure it\'s located in'
OSError: Could not find kaggle.json. Make sure it's located in /home/airflow/.config/kaggle. Or use the environment method. See setup instructions at https://github.com/Kaggle/kaggle-api/
[2025-01-14T17:43:35.625+0000] {processor.py:927} WARNING - No viable dags retrieved from /opt/airflow/dags/tes_dag.py
[2025-01-14T17:43:35.669+0000] {processor.py:208} INFO - Processing /opt/airflow/dags/tes_dag.py took 0.547 seconds
[2025-01-14T17:44:06.044+0000] {processor.py:186} INFO - Started process (PID=985) to work on /opt/airflow/dags/tes_dag.py
[2025-01-14T17:44:06.047+0000] {processor.py:914} INFO - Processing file /opt/airflow/dags/tes_dag.py for tasks to queue
[2025-01-14T17:44:06.049+0000] {logging_mixin.py:190} INFO - [2025-01-14T17:44:06.049+0000] {dagbag.py:588} INFO - Filling up the DagBag from /opt/airflow/dags/tes_dag.py
[2025-01-14T17:44:06.219+0000] {logging_mixin.py:190} INFO - [2025-01-14T17:44:06.205+0000] {dagbag.py:387} ERROR - Failed to import: /opt/airflow/dags/tes_dag.py
Traceback (most recent call last):
  File "/home/airflow/.local/lib/python3.12/site-packages/airflow/models/dagbag.py", line 383, in parse
    loader.exec_module(new_module)
  File "<frozen importlib._bootstrap_external>", line 999, in exec_module
  File "<frozen importlib._bootstrap>", line 488, in _call_with_frames_removed
  File "/opt/airflow/dags/tes_dag.py", line 5, in <module>
    from test import test2
  File "/opt/airflow/dags/test.py", line 2, in <module>
    from kaggle.api.kaggle_api_extended import KaggleApi
  File "/home/airflow/.local/lib/python3.12/site-packages/kaggle/__init__.py", line 7, in <module>
    api.authenticate()
  File "/home/airflow/.local/lib/python3.12/site-packages/kaggle/api/kaggle_api_extended.py", line 407, in authenticate
    raise IOError('Could not find {}. Make sure it\'s located in'
OSError: Could not find kaggle.json. Make sure it's located in /home/airflow/.config/kaggle. Or use the environment method. See setup instructions at https://github.com/Kaggle/kaggle-api/
[2025-01-14T17:44:06.220+0000] {processor.py:927} WARNING - No viable dags retrieved from /opt/airflow/dags/tes_dag.py
[2025-01-14T17:44:06.253+0000] {processor.py:208} INFO - Processing /opt/airflow/dags/tes_dag.py took 0.220 seconds
[2025-01-14T17:44:36.663+0000] {processor.py:186} INFO - Started process (PID=1007) to work on /opt/airflow/dags/tes_dag.py
[2025-01-14T17:44:36.664+0000] {processor.py:914} INFO - Processing file /opt/airflow/dags/tes_dag.py for tasks to queue
[2025-01-14T17:44:36.666+0000] {logging_mixin.py:190} INFO - [2025-01-14T17:44:36.665+0000] {dagbag.py:588} INFO - Filling up the DagBag from /opt/airflow/dags/tes_dag.py
[2025-01-14T17:44:36.841+0000] {logging_mixin.py:190} INFO - [2025-01-14T17:44:36.829+0000] {dagbag.py:387} ERROR - Failed to import: /opt/airflow/dags/tes_dag.py
Traceback (most recent call last):
  File "/home/airflow/.local/lib/python3.12/site-packages/airflow/models/dagbag.py", line 383, in parse
    loader.exec_module(new_module)
  File "<frozen importlib._bootstrap_external>", line 999, in exec_module
  File "<frozen importlib._bootstrap>", line 488, in _call_with_frames_removed
  File "/opt/airflow/dags/tes_dag.py", line 5, in <module>
    from test import test2
  File "/opt/airflow/dags/test.py", line 2, in <module>
    from kaggle.api.kaggle_api_extended import KaggleApi
  File "/home/airflow/.local/lib/python3.12/site-packages/kaggle/__init__.py", line 7, in <module>
    api.authenticate()
  File "/home/airflow/.local/lib/python3.12/site-packages/kaggle/api/kaggle_api_extended.py", line 407, in authenticate
    raise IOError('Could not find {}. Make sure it\'s located in'
OSError: Could not find kaggle.json. Make sure it's located in /home/airflow/.config/kaggle. Or use the environment method. See setup instructions at https://github.com/Kaggle/kaggle-api/
[2025-01-14T17:44:36.842+0000] {processor.py:927} WARNING - No viable dags retrieved from /opt/airflow/dags/tes_dag.py
[2025-01-14T17:44:37.093+0000] {processor.py:208} INFO - Processing /opt/airflow/dags/tes_dag.py took 0.438 seconds
[2025-01-14T17:45:07.460+0000] {processor.py:186} INFO - Started process (PID=1029) to work on /opt/airflow/dags/tes_dag.py
[2025-01-14T17:45:07.462+0000] {processor.py:914} INFO - Processing file /opt/airflow/dags/tes_dag.py for tasks to queue
[2025-01-14T17:45:07.464+0000] {logging_mixin.py:190} INFO - [2025-01-14T17:45:07.464+0000] {dagbag.py:588} INFO - Filling up the DagBag from /opt/airflow/dags/tes_dag.py
[2025-01-14T17:45:07.827+0000] {logging_mixin.py:190} INFO - [2025-01-14T17:45:07.816+0000] {dagbag.py:387} ERROR - Failed to import: /opt/airflow/dags/tes_dag.py
Traceback (most recent call last):
  File "/home/airflow/.local/lib/python3.12/site-packages/airflow/models/dagbag.py", line 383, in parse
    loader.exec_module(new_module)
  File "<frozen importlib._bootstrap_external>", line 999, in exec_module
  File "<frozen importlib._bootstrap>", line 488, in _call_with_frames_removed
  File "/opt/airflow/dags/tes_dag.py", line 5, in <module>
    from test import test2
  File "/opt/airflow/dags/test.py", line 2, in <module>
    from kaggle.api.kaggle_api_extended import KaggleApi
  File "/home/airflow/.local/lib/python3.12/site-packages/kaggle/__init__.py", line 7, in <module>
    api.authenticate()
  File "/home/airflow/.local/lib/python3.12/site-packages/kaggle/api/kaggle_api_extended.py", line 407, in authenticate
    raise IOError('Could not find {}. Make sure it\'s located in'
OSError: Could not find kaggle.json. Make sure it's located in /home/airflow/.config/kaggle. Or use the environment method. See setup instructions at https://github.com/Kaggle/kaggle-api/
[2025-01-14T17:45:07.829+0000] {processor.py:927} WARNING - No viable dags retrieved from /opt/airflow/dags/tes_dag.py
[2025-01-14T17:45:07.852+0000] {processor.py:208} INFO - Processing /opt/airflow/dags/tes_dag.py took 0.402 seconds
[2025-01-14T17:45:38.218+0000] {processor.py:186} INFO - Started process (PID=1051) to work on /opt/airflow/dags/tes_dag.py
[2025-01-14T17:45:38.220+0000] {processor.py:914} INFO - Processing file /opt/airflow/dags/tes_dag.py for tasks to queue
[2025-01-14T17:45:38.223+0000] {logging_mixin.py:190} INFO - [2025-01-14T17:45:38.222+0000] {dagbag.py:588} INFO - Filling up the DagBag from /opt/airflow/dags/tes_dag.py
[2025-01-14T17:45:38.622+0000] {logging_mixin.py:190} INFO - [2025-01-14T17:45:38.610+0000] {dagbag.py:387} ERROR - Failed to import: /opt/airflow/dags/tes_dag.py
Traceback (most recent call last):
  File "/home/airflow/.local/lib/python3.12/site-packages/airflow/models/dagbag.py", line 383, in parse
    loader.exec_module(new_module)
  File "<frozen importlib._bootstrap_external>", line 999, in exec_module
  File "<frozen importlib._bootstrap>", line 488, in _call_with_frames_removed
  File "/opt/airflow/dags/tes_dag.py", line 5, in <module>
    from test import test2
  File "/opt/airflow/dags/test.py", line 2, in <module>
    from kaggle.api.kaggle_api_extended import KaggleApi
  File "/home/airflow/.local/lib/python3.12/site-packages/kaggle/__init__.py", line 7, in <module>
    api.authenticate()
  File "/home/airflow/.local/lib/python3.12/site-packages/kaggle/api/kaggle_api_extended.py", line 407, in authenticate
    raise IOError('Could not find {}. Make sure it\'s located in'
OSError: Could not find kaggle.json. Make sure it's located in /home/airflow/.config/kaggle. Or use the environment method. See setup instructions at https://github.com/Kaggle/kaggle-api/
[2025-01-14T17:45:38.624+0000] {processor.py:927} WARNING - No viable dags retrieved from /opt/airflow/dags/tes_dag.py
[2025-01-14T17:45:38.652+0000] {processor.py:208} INFO - Processing /opt/airflow/dags/tes_dag.py took 0.446 seconds
[2025-01-14T17:46:08.984+0000] {processor.py:186} INFO - Started process (PID=1073) to work on /opt/airflow/dags/tes_dag.py
[2025-01-14T17:46:08.986+0000] {processor.py:914} INFO - Processing file /opt/airflow/dags/tes_dag.py for tasks to queue
[2025-01-14T17:46:08.988+0000] {logging_mixin.py:190} INFO - [2025-01-14T17:46:08.987+0000] {dagbag.py:588} INFO - Filling up the DagBag from /opt/airflow/dags/tes_dag.py
[2025-01-14T17:46:09.330+0000] {logging_mixin.py:190} INFO - [2025-01-14T17:46:09.318+0000] {dagbag.py:387} ERROR - Failed to import: /opt/airflow/dags/tes_dag.py
Traceback (most recent call last):
  File "/home/airflow/.local/lib/python3.12/site-packages/airflow/models/dagbag.py", line 383, in parse
    loader.exec_module(new_module)
  File "<frozen importlib._bootstrap_external>", line 999, in exec_module
  File "<frozen importlib._bootstrap>", line 488, in _call_with_frames_removed
  File "/opt/airflow/dags/tes_dag.py", line 5, in <module>
    from test import test2
  File "/opt/airflow/dags/test.py", line 2, in <module>
    from kaggle.api.kaggle_api_extended import KaggleApi
  File "/home/airflow/.local/lib/python3.12/site-packages/kaggle/__init__.py", line 7, in <module>
    api.authenticate()
  File "/home/airflow/.local/lib/python3.12/site-packages/kaggle/api/kaggle_api_extended.py", line 407, in authenticate
    raise IOError('Could not find {}. Make sure it\'s located in'
OSError: Could not find kaggle.json. Make sure it's located in /home/airflow/.config/kaggle. Or use the environment method. See setup instructions at https://github.com/Kaggle/kaggle-api/
[2025-01-14T17:46:09.331+0000] {processor.py:927} WARNING - No viable dags retrieved from /opt/airflow/dags/tes_dag.py
[2025-01-14T17:46:09.354+0000] {processor.py:208} INFO - Processing /opt/airflow/dags/tes_dag.py took 0.382 seconds
[2025-01-14T17:46:39.828+0000] {processor.py:186} INFO - Started process (PID=1095) to work on /opt/airflow/dags/tes_dag.py
[2025-01-14T17:46:39.830+0000] {processor.py:914} INFO - Processing file /opt/airflow/dags/tes_dag.py for tasks to queue
[2025-01-14T17:46:39.834+0000] {logging_mixin.py:190} INFO - [2025-01-14T17:46:39.833+0000] {dagbag.py:588} INFO - Filling up the DagBag from /opt/airflow/dags/tes_dag.py
[2025-01-14T17:46:40.196+0000] {logging_mixin.py:190} INFO - [2025-01-14T17:46:40.185+0000] {dagbag.py:387} ERROR - Failed to import: /opt/airflow/dags/tes_dag.py
Traceback (most recent call last):
  File "/home/airflow/.local/lib/python3.12/site-packages/airflow/models/dagbag.py", line 383, in parse
    loader.exec_module(new_module)
  File "<frozen importlib._bootstrap_external>", line 999, in exec_module
  File "<frozen importlib._bootstrap>", line 488, in _call_with_frames_removed
  File "/opt/airflow/dags/tes_dag.py", line 5, in <module>
    from test import test2
  File "/opt/airflow/dags/test.py", line 2, in <module>
    from kaggle.api.kaggle_api_extended import KaggleApi
  File "/home/airflow/.local/lib/python3.12/site-packages/kaggle/__init__.py", line 7, in <module>
    api.authenticate()
  File "/home/airflow/.local/lib/python3.12/site-packages/kaggle/api/kaggle_api_extended.py", line 407, in authenticate
    raise IOError('Could not find {}. Make sure it\'s located in'
OSError: Could not find kaggle.json. Make sure it's located in /home/airflow/.config/kaggle. Or use the environment method. See setup instructions at https://github.com/Kaggle/kaggle-api/
[2025-01-14T17:46:40.198+0000] {processor.py:927} WARNING - No viable dags retrieved from /opt/airflow/dags/tes_dag.py
[2025-01-14T17:46:40.229+0000] {processor.py:208} INFO - Processing /opt/airflow/dags/tes_dag.py took 0.411 seconds
[2025-01-14T17:47:10.818+0000] {processor.py:186} INFO - Started process (PID=1117) to work on /opt/airflow/dags/tes_dag.py
[2025-01-14T17:47:10.819+0000] {processor.py:914} INFO - Processing file /opt/airflow/dags/tes_dag.py for tasks to queue
[2025-01-14T17:47:10.821+0000] {logging_mixin.py:190} INFO - [2025-01-14T17:47:10.820+0000] {dagbag.py:588} INFO - Filling up the DagBag from /opt/airflow/dags/tes_dag.py
[2025-01-14T17:47:10.977+0000] {logging_mixin.py:190} INFO - [2025-01-14T17:47:10.961+0000] {dagbag.py:387} ERROR - Failed to import: /opt/airflow/dags/tes_dag.py
Traceback (most recent call last):
  File "/home/airflow/.local/lib/python3.12/site-packages/airflow/models/dagbag.py", line 383, in parse
    loader.exec_module(new_module)
  File "<frozen importlib._bootstrap_external>", line 999, in exec_module
  File "<frozen importlib._bootstrap>", line 488, in _call_with_frames_removed
  File "/opt/airflow/dags/tes_dag.py", line 5, in <module>
    from test import test2
  File "/opt/airflow/dags/test.py", line 2, in <module>
    from kaggle.api.kaggle_api_extended import KaggleApi
  File "/home/airflow/.local/lib/python3.12/site-packages/kaggle/__init__.py", line 7, in <module>
    api.authenticate()
  File "/home/airflow/.local/lib/python3.12/site-packages/kaggle/api/kaggle_api_extended.py", line 407, in authenticate
    raise IOError('Could not find {}. Make sure it\'s located in'
OSError: Could not find kaggle.json. Make sure it's located in /home/airflow/.config/kaggle. Or use the environment method. See setup instructions at https://github.com/Kaggle/kaggle-api/
[2025-01-14T17:47:10.978+0000] {processor.py:927} WARNING - No viable dags retrieved from /opt/airflow/dags/tes_dag.py
[2025-01-14T17:47:11.002+0000] {processor.py:208} INFO - Processing /opt/airflow/dags/tes_dag.py took 0.412 seconds
[2025-01-14T17:47:41.396+0000] {processor.py:186} INFO - Started process (PID=1139) to work on /opt/airflow/dags/tes_dag.py
[2025-01-14T17:47:41.398+0000] {processor.py:914} INFO - Processing file /opt/airflow/dags/tes_dag.py for tasks to queue
[2025-01-14T17:47:41.401+0000] {logging_mixin.py:190} INFO - [2025-01-14T17:47:41.400+0000] {dagbag.py:588} INFO - Filling up the DagBag from /opt/airflow/dags/tes_dag.py
[2025-01-14T17:47:41.600+0000] {logging_mixin.py:190} INFO - [2025-01-14T17:47:41.591+0000] {dagbag.py:387} ERROR - Failed to import: /opt/airflow/dags/tes_dag.py
Traceback (most recent call last):
  File "/home/airflow/.local/lib/python3.12/site-packages/airflow/models/dagbag.py", line 383, in parse
    loader.exec_module(new_module)
  File "<frozen importlib._bootstrap_external>", line 999, in exec_module
  File "<frozen importlib._bootstrap>", line 488, in _call_with_frames_removed
  File "/opt/airflow/dags/tes_dag.py", line 5, in <module>
    from test import test2
  File "/opt/airflow/dags/test.py", line 2, in <module>
    from kaggle.api.kaggle_api_extended import KaggleApi
  File "/home/airflow/.local/lib/python3.12/site-packages/kaggle/__init__.py", line 7, in <module>
    api.authenticate()
  File "/home/airflow/.local/lib/python3.12/site-packages/kaggle/api/kaggle_api_extended.py", line 407, in authenticate
    raise IOError('Could not find {}. Make sure it\'s located in'
OSError: Could not find kaggle.json. Make sure it's located in /home/airflow/.config/kaggle. Or use the environment method. See setup instructions at https://github.com/Kaggle/kaggle-api/
[2025-01-14T17:47:41.601+0000] {processor.py:927} WARNING - No viable dags retrieved from /opt/airflow/dags/tes_dag.py
[2025-01-14T17:47:41.642+0000] {processor.py:208} INFO - Processing /opt/airflow/dags/tes_dag.py took 0.264 seconds
[2025-01-14T17:48:12.175+0000] {processor.py:186} INFO - Started process (PID=1161) to work on /opt/airflow/dags/tes_dag.py
[2025-01-14T17:48:12.177+0000] {processor.py:914} INFO - Processing file /opt/airflow/dags/tes_dag.py for tasks to queue
[2025-01-14T17:48:12.180+0000] {logging_mixin.py:190} INFO - [2025-01-14T17:48:12.179+0000] {dagbag.py:588} INFO - Filling up the DagBag from /opt/airflow/dags/tes_dag.py
[2025-01-14T17:48:12.385+0000] {logging_mixin.py:190} INFO - [2025-01-14T17:48:12.374+0000] {dagbag.py:387} ERROR - Failed to import: /opt/airflow/dags/tes_dag.py
Traceback (most recent call last):
  File "/home/airflow/.local/lib/python3.12/site-packages/airflow/models/dagbag.py", line 383, in parse
    loader.exec_module(new_module)
  File "<frozen importlib._bootstrap_external>", line 999, in exec_module
  File "<frozen importlib._bootstrap>", line 488, in _call_with_frames_removed
  File "/opt/airflow/dags/tes_dag.py", line 5, in <module>
    from test import test2
  File "/opt/airflow/dags/test.py", line 2, in <module>
    from kaggle.api.kaggle_api_extended import KaggleApi
  File "/home/airflow/.local/lib/python3.12/site-packages/kaggle/__init__.py", line 7, in <module>
    api.authenticate()
  File "/home/airflow/.local/lib/python3.12/site-packages/kaggle/api/kaggle_api_extended.py", line 407, in authenticate
    raise IOError('Could not find {}. Make sure it\'s located in'
OSError: Could not find kaggle.json. Make sure it's located in /home/airflow/.config/kaggle. Or use the environment method. See setup instructions at https://github.com/Kaggle/kaggle-api/
[2025-01-14T17:48:12.387+0000] {processor.py:927} WARNING - No viable dags retrieved from /opt/airflow/dags/tes_dag.py
[2025-01-14T17:48:12.420+0000] {processor.py:208} INFO - Processing /opt/airflow/dags/tes_dag.py took 0.260 seconds
[2025-01-14T17:48:42.718+0000] {processor.py:186} INFO - Started process (PID=1183) to work on /opt/airflow/dags/tes_dag.py
[2025-01-14T17:48:42.720+0000] {processor.py:914} INFO - Processing file /opt/airflow/dags/tes_dag.py for tasks to queue
[2025-01-14T17:48:42.721+0000] {logging_mixin.py:190} INFO - [2025-01-14T17:48:42.721+0000] {dagbag.py:588} INFO - Filling up the DagBag from /opt/airflow/dags/tes_dag.py
[2025-01-14T17:48:42.891+0000] {logging_mixin.py:190} INFO - [2025-01-14T17:48:42.876+0000] {dagbag.py:387} ERROR - Failed to import: /opt/airflow/dags/tes_dag.py
Traceback (most recent call last):
  File "/home/airflow/.local/lib/python3.12/site-packages/airflow/models/dagbag.py", line 383, in parse
    loader.exec_module(new_module)
  File "<frozen importlib._bootstrap_external>", line 999, in exec_module
  File "<frozen importlib._bootstrap>", line 488, in _call_with_frames_removed
  File "/opt/airflow/dags/tes_dag.py", line 5, in <module>
    from test import test2
  File "/opt/airflow/dags/test.py", line 2, in <module>
    from kaggle.api.kaggle_api_extended import KaggleApi
  File "/home/airflow/.local/lib/python3.12/site-packages/kaggle/__init__.py", line 7, in <module>
    api.authenticate()
  File "/home/airflow/.local/lib/python3.12/site-packages/kaggle/api/kaggle_api_extended.py", line 407, in authenticate
    raise IOError('Could not find {}. Make sure it\'s located in'
OSError: Could not find kaggle.json. Make sure it's located in /home/airflow/.config/kaggle. Or use the environment method. See setup instructions at https://github.com/Kaggle/kaggle-api/
[2025-01-14T17:48:42.892+0000] {processor.py:927} WARNING - No viable dags retrieved from /opt/airflow/dags/tes_dag.py
[2025-01-14T17:48:42.925+0000] {processor.py:208} INFO - Processing /opt/airflow/dags/tes_dag.py took 0.216 seconds
[2025-01-14T17:49:13.390+0000] {processor.py:186} INFO - Started process (PID=1205) to work on /opt/airflow/dags/tes_dag.py
[2025-01-14T17:49:13.393+0000] {processor.py:914} INFO - Processing file /opt/airflow/dags/tes_dag.py for tasks to queue
[2025-01-14T17:49:13.396+0000] {logging_mixin.py:190} INFO - [2025-01-14T17:49:13.396+0000] {dagbag.py:588} INFO - Filling up the DagBag from /opt/airflow/dags/tes_dag.py
[2025-01-14T17:49:13.587+0000] {logging_mixin.py:190} INFO - [2025-01-14T17:49:13.576+0000] {dagbag.py:387} ERROR - Failed to import: /opt/airflow/dags/tes_dag.py
Traceback (most recent call last):
  File "/home/airflow/.local/lib/python3.12/site-packages/airflow/models/dagbag.py", line 383, in parse
    loader.exec_module(new_module)
  File "<frozen importlib._bootstrap_external>", line 999, in exec_module
  File "<frozen importlib._bootstrap>", line 488, in _call_with_frames_removed
  File "/opt/airflow/dags/tes_dag.py", line 5, in <module>
    from test import test2
  File "/opt/airflow/dags/test.py", line 2, in <module>
    from kaggle.api.kaggle_api_extended import KaggleApi
  File "/home/airflow/.local/lib/python3.12/site-packages/kaggle/__init__.py", line 7, in <module>
    api.authenticate()
  File "/home/airflow/.local/lib/python3.12/site-packages/kaggle/api/kaggle_api_extended.py", line 407, in authenticate
    raise IOError('Could not find {}. Make sure it\'s located in'
OSError: Could not find kaggle.json. Make sure it's located in /home/airflow/.config/kaggle. Or use the environment method. See setup instructions at https://github.com/Kaggle/kaggle-api/
[2025-01-14T17:49:13.589+0000] {processor.py:927} WARNING - No viable dags retrieved from /opt/airflow/dags/tes_dag.py
[2025-01-14T17:49:13.624+0000] {processor.py:208} INFO - Processing /opt/airflow/dags/tes_dag.py took 0.248 seconds
[2025-01-14T17:49:43.724+0000] {processor.py:186} INFO - Started process (PID=1227) to work on /opt/airflow/dags/tes_dag.py
[2025-01-14T17:49:43.727+0000] {processor.py:914} INFO - Processing file /opt/airflow/dags/tes_dag.py for tasks to queue
[2025-01-14T17:49:43.730+0000] {logging_mixin.py:190} INFO - [2025-01-14T17:49:43.730+0000] {dagbag.py:588} INFO - Filling up the DagBag from /opt/airflow/dags/tes_dag.py
[2025-01-14T17:49:43.884+0000] {logging_mixin.py:190} INFO - [2025-01-14T17:49:43.874+0000] {dagbag.py:387} ERROR - Failed to import: /opt/airflow/dags/tes_dag.py
Traceback (most recent call last):
  File "/home/airflow/.local/lib/python3.12/site-packages/airflow/models/dagbag.py", line 383, in parse
    loader.exec_module(new_module)
  File "<frozen importlib._bootstrap_external>", line 999, in exec_module
  File "<frozen importlib._bootstrap>", line 488, in _call_with_frames_removed
  File "/opt/airflow/dags/tes_dag.py", line 5, in <module>
    from test import test2
  File "/opt/airflow/dags/test.py", line 2, in <module>
    from kaggle.api.kaggle_api_extended import KaggleApi
  File "/home/airflow/.local/lib/python3.12/site-packages/kaggle/__init__.py", line 7, in <module>
    api.authenticate()
  File "/home/airflow/.local/lib/python3.12/site-packages/kaggle/api/kaggle_api_extended.py", line 407, in authenticate
    raise IOError('Could not find {}. Make sure it\'s located in'
OSError: Could not find kaggle.json. Make sure it's located in /home/airflow/.config/kaggle. Or use the environment method. See setup instructions at https://github.com/Kaggle/kaggle-api/
[2025-01-14T17:49:43.885+0000] {processor.py:927} WARNING - No viable dags retrieved from /opt/airflow/dags/tes_dag.py
[2025-01-14T17:49:43.910+0000] {processor.py:208} INFO - Processing /opt/airflow/dags/tes_dag.py took 0.201 seconds
[2025-01-14T17:50:14.289+0000] {processor.py:186} INFO - Started process (PID=1249) to work on /opt/airflow/dags/tes_dag.py
[2025-01-14T17:50:14.290+0000] {processor.py:914} INFO - Processing file /opt/airflow/dags/tes_dag.py for tasks to queue
[2025-01-14T17:50:14.292+0000] {logging_mixin.py:190} INFO - [2025-01-14T17:50:14.292+0000] {dagbag.py:588} INFO - Filling up the DagBag from /opt/airflow/dags/tes_dag.py
[2025-01-14T17:50:14.461+0000] {logging_mixin.py:190} INFO - [2025-01-14T17:50:14.448+0000] {dagbag.py:387} ERROR - Failed to import: /opt/airflow/dags/tes_dag.py
Traceback (most recent call last):
  File "/home/airflow/.local/lib/python3.12/site-packages/airflow/models/dagbag.py", line 383, in parse
    loader.exec_module(new_module)
  File "<frozen importlib._bootstrap_external>", line 999, in exec_module
  File "<frozen importlib._bootstrap>", line 488, in _call_with_frames_removed
  File "/opt/airflow/dags/tes_dag.py", line 5, in <module>
    from test import test2
  File "/opt/airflow/dags/test.py", line 2, in <module>
    from kaggle.api.kaggle_api_extended import KaggleApi
  File "/home/airflow/.local/lib/python3.12/site-packages/kaggle/__init__.py", line 7, in <module>
    api.authenticate()
  File "/home/airflow/.local/lib/python3.12/site-packages/kaggle/api/kaggle_api_extended.py", line 407, in authenticate
    raise IOError('Could not find {}. Make sure it\'s located in'
OSError: Could not find kaggle.json. Make sure it's located in /home/airflow/.config/kaggle. Or use the environment method. See setup instructions at https://github.com/Kaggle/kaggle-api/
[2025-01-14T17:50:14.462+0000] {processor.py:927} WARNING - No viable dags retrieved from /opt/airflow/dags/tes_dag.py
[2025-01-14T17:50:14.490+0000] {processor.py:208} INFO - Processing /opt/airflow/dags/tes_dag.py took 0.211 seconds
[2025-01-14T17:50:44.739+0000] {processor.py:186} INFO - Started process (PID=1271) to work on /opt/airflow/dags/tes_dag.py
[2025-01-14T17:50:44.741+0000] {processor.py:914} INFO - Processing file /opt/airflow/dags/tes_dag.py for tasks to queue
[2025-01-14T17:50:44.743+0000] {logging_mixin.py:190} INFO - [2025-01-14T17:50:44.743+0000] {dagbag.py:588} INFO - Filling up the DagBag from /opt/airflow/dags/tes_dag.py
[2025-01-14T17:50:44.903+0000] {logging_mixin.py:190} INFO - [2025-01-14T17:50:44.893+0000] {dagbag.py:387} ERROR - Failed to import: /opt/airflow/dags/tes_dag.py
Traceback (most recent call last):
  File "/home/airflow/.local/lib/python3.12/site-packages/airflow/models/dagbag.py", line 383, in parse
    loader.exec_module(new_module)
  File "<frozen importlib._bootstrap_external>", line 999, in exec_module
  File "<frozen importlib._bootstrap>", line 488, in _call_with_frames_removed
  File "/opt/airflow/dags/tes_dag.py", line 5, in <module>
    from test import test2
  File "/opt/airflow/dags/test.py", line 2, in <module>
    from kaggle.api.kaggle_api_extended import KaggleApi
  File "/home/airflow/.local/lib/python3.12/site-packages/kaggle/__init__.py", line 7, in <module>
    api.authenticate()
  File "/home/airflow/.local/lib/python3.12/site-packages/kaggle/api/kaggle_api_extended.py", line 407, in authenticate
    raise IOError('Could not find {}. Make sure it\'s located in'
OSError: Could not find kaggle.json. Make sure it's located in /home/airflow/.config/kaggle. Or use the environment method. See setup instructions at https://github.com/Kaggle/kaggle-api/
[2025-01-14T17:50:44.904+0000] {processor.py:927} WARNING - No viable dags retrieved from /opt/airflow/dags/tes_dag.py
[2025-01-14T17:50:44.930+0000] {processor.py:208} INFO - Processing /opt/airflow/dags/tes_dag.py took 0.202 seconds
[2025-01-14T17:51:15.154+0000] {processor.py:186} INFO - Started process (PID=1293) to work on /opt/airflow/dags/tes_dag.py
[2025-01-14T17:51:15.155+0000] {processor.py:914} INFO - Processing file /opt/airflow/dags/tes_dag.py for tasks to queue
[2025-01-14T17:51:15.157+0000] {logging_mixin.py:190} INFO - [2025-01-14T17:51:15.157+0000] {dagbag.py:588} INFO - Filling up the DagBag from /opt/airflow/dags/tes_dag.py
[2025-01-14T17:51:15.338+0000] {logging_mixin.py:190} INFO - [2025-01-14T17:51:15.323+0000] {dagbag.py:387} ERROR - Failed to import: /opt/airflow/dags/tes_dag.py
Traceback (most recent call last):
  File "/home/airflow/.local/lib/python3.12/site-packages/airflow/models/dagbag.py", line 383, in parse
    loader.exec_module(new_module)
  File "<frozen importlib._bootstrap_external>", line 999, in exec_module
  File "<frozen importlib._bootstrap>", line 488, in _call_with_frames_removed
  File "/opt/airflow/dags/tes_dag.py", line 5, in <module>
    from test import test2
  File "/opt/airflow/dags/test.py", line 2, in <module>
    from kaggle.api.kaggle_api_extended import KaggleApi
  File "/home/airflow/.local/lib/python3.12/site-packages/kaggle/__init__.py", line 7, in <module>
    api.authenticate()
  File "/home/airflow/.local/lib/python3.12/site-packages/kaggle/api/kaggle_api_extended.py", line 407, in authenticate
    raise IOError('Could not find {}. Make sure it\'s located in'
OSError: Could not find kaggle.json. Make sure it's located in /home/airflow/.config/kaggle. Or use the environment method. See setup instructions at https://github.com/Kaggle/kaggle-api/
[2025-01-14T17:51:15.339+0000] {processor.py:927} WARNING - No viable dags retrieved from /opt/airflow/dags/tes_dag.py
[2025-01-14T17:51:15.376+0000] {processor.py:208} INFO - Processing /opt/airflow/dags/tes_dag.py took 0.231 seconds
[2025-01-14T17:51:45.686+0000] {processor.py:186} INFO - Started process (PID=1315) to work on /opt/airflow/dags/tes_dag.py
[2025-01-14T17:51:45.688+0000] {processor.py:914} INFO - Processing file /opt/airflow/dags/tes_dag.py for tasks to queue
[2025-01-14T17:51:45.692+0000] {logging_mixin.py:190} INFO - [2025-01-14T17:51:45.690+0000] {dagbag.py:588} INFO - Filling up the DagBag from /opt/airflow/dags/tes_dag.py
[2025-01-14T17:51:45.946+0000] {logging_mixin.py:190} INFO - [2025-01-14T17:51:45.936+0000] {dagbag.py:387} ERROR - Failed to import: /opt/airflow/dags/tes_dag.py
Traceback (most recent call last):
  File "/home/airflow/.local/lib/python3.12/site-packages/airflow/models/dagbag.py", line 383, in parse
    loader.exec_module(new_module)
  File "<frozen importlib._bootstrap_external>", line 999, in exec_module
  File "<frozen importlib._bootstrap>", line 488, in _call_with_frames_removed
  File "/opt/airflow/dags/tes_dag.py", line 5, in <module>
    from test import test2
  File "/opt/airflow/dags/test.py", line 2, in <module>
    from kaggle.api.kaggle_api_extended import KaggleApi
  File "/home/airflow/.local/lib/python3.12/site-packages/kaggle/__init__.py", line 7, in <module>
    api.authenticate()
  File "/home/airflow/.local/lib/python3.12/site-packages/kaggle/api/kaggle_api_extended.py", line 407, in authenticate
    raise IOError('Could not find {}. Make sure it\'s located in'
OSError: Could not find kaggle.json. Make sure it's located in /home/airflow/.config/kaggle. Or use the environment method. See setup instructions at https://github.com/Kaggle/kaggle-api/
[2025-01-14T17:51:45.947+0000] {processor.py:927} WARNING - No viable dags retrieved from /opt/airflow/dags/tes_dag.py
[2025-01-14T17:51:45.984+0000] {processor.py:208} INFO - Processing /opt/airflow/dags/tes_dag.py took 0.316 seconds
[2025-01-14T17:52:16.056+0000] {processor.py:186} INFO - Started process (PID=1337) to work on /opt/airflow/dags/tes_dag.py
[2025-01-14T17:52:16.057+0000] {processor.py:914} INFO - Processing file /opt/airflow/dags/tes_dag.py for tasks to queue
[2025-01-14T17:52:16.059+0000] {logging_mixin.py:190} INFO - [2025-01-14T17:52:16.059+0000] {dagbag.py:588} INFO - Filling up the DagBag from /opt/airflow/dags/tes_dag.py
[2025-01-14T17:52:16.273+0000] {logging_mixin.py:190} INFO - [2025-01-14T17:52:16.258+0000] {dagbag.py:387} ERROR - Failed to import: /opt/airflow/dags/tes_dag.py
Traceback (most recent call last):
  File "/home/airflow/.local/lib/python3.12/site-packages/airflow/models/dagbag.py", line 383, in parse
    loader.exec_module(new_module)
  File "<frozen importlib._bootstrap_external>", line 999, in exec_module
  File "<frozen importlib._bootstrap>", line 488, in _call_with_frames_removed
  File "/opt/airflow/dags/tes_dag.py", line 5, in <module>
    from test import test2
  File "/opt/airflow/dags/test.py", line 2, in <module>
    from kaggle.api.kaggle_api_extended import KaggleApi
  File "/home/airflow/.local/lib/python3.12/site-packages/kaggle/__init__.py", line 7, in <module>
    api.authenticate()
  File "/home/airflow/.local/lib/python3.12/site-packages/kaggle/api/kaggle_api_extended.py", line 407, in authenticate
    raise IOError('Could not find {}. Make sure it\'s located in'
OSError: Could not find kaggle.json. Make sure it's located in /home/airflow/.config/kaggle. Or use the environment method. See setup instructions at https://github.com/Kaggle/kaggle-api/
[2025-01-14T17:52:16.275+0000] {processor.py:927} WARNING - No viable dags retrieved from /opt/airflow/dags/tes_dag.py
[2025-01-14T17:52:16.313+0000] {processor.py:208} INFO - Processing /opt/airflow/dags/tes_dag.py took 0.266 seconds
[2025-01-14T17:52:46.738+0000] {processor.py:186} INFO - Started process (PID=1360) to work on /opt/airflow/dags/tes_dag.py
[2025-01-14T17:52:46.740+0000] {processor.py:914} INFO - Processing file /opt/airflow/dags/tes_dag.py for tasks to queue
[2025-01-14T17:52:46.742+0000] {logging_mixin.py:190} INFO - [2025-01-14T17:52:46.741+0000] {dagbag.py:588} INFO - Filling up the DagBag from /opt/airflow/dags/tes_dag.py
[2025-01-14T17:52:46.918+0000] {logging_mixin.py:190} INFO - [2025-01-14T17:52:46.905+0000] {dagbag.py:387} ERROR - Failed to import: /opt/airflow/dags/tes_dag.py
Traceback (most recent call last):
  File "/home/airflow/.local/lib/python3.12/site-packages/airflow/models/dagbag.py", line 383, in parse
    loader.exec_module(new_module)
  File "<frozen importlib._bootstrap_external>", line 999, in exec_module
  File "<frozen importlib._bootstrap>", line 488, in _call_with_frames_removed
  File "/opt/airflow/dags/tes_dag.py", line 5, in <module>
    from test import test2
  File "/opt/airflow/dags/test.py", line 2, in <module>
    from kaggle.api.kaggle_api_extended import KaggleApi
  File "/home/airflow/.local/lib/python3.12/site-packages/kaggle/__init__.py", line 7, in <module>
    api.authenticate()
  File "/home/airflow/.local/lib/python3.12/site-packages/kaggle/api/kaggle_api_extended.py", line 407, in authenticate
    raise IOError('Could not find {}. Make sure it\'s located in'
OSError: Could not find kaggle.json. Make sure it's located in /home/airflow/.config/kaggle. Or use the environment method. See setup instructions at https://github.com/Kaggle/kaggle-api/
[2025-01-14T17:52:46.919+0000] {processor.py:927} WARNING - No viable dags retrieved from /opt/airflow/dags/tes_dag.py
[2025-01-14T17:52:46.951+0000] {processor.py:208} INFO - Processing /opt/airflow/dags/tes_dag.py took 0.224 seconds
[2025-01-14T17:53:17.282+0000] {processor.py:186} INFO - Started process (PID=1382) to work on /opt/airflow/dags/tes_dag.py
[2025-01-14T17:53:17.285+0000] {processor.py:914} INFO - Processing file /opt/airflow/dags/tes_dag.py for tasks to queue
[2025-01-14T17:53:17.288+0000] {logging_mixin.py:190} INFO - [2025-01-14T17:53:17.287+0000] {dagbag.py:588} INFO - Filling up the DagBag from /opt/airflow/dags/tes_dag.py
[2025-01-14T17:53:17.628+0000] {logging_mixin.py:190} INFO - [2025-01-14T17:53:17.612+0000] {dagbag.py:387} ERROR - Failed to import: /opt/airflow/dags/tes_dag.py
Traceback (most recent call last):
  File "/home/airflow/.local/lib/python3.12/site-packages/airflow/models/dagbag.py", line 383, in parse
    loader.exec_module(new_module)
  File "<frozen importlib._bootstrap_external>", line 999, in exec_module
  File "<frozen importlib._bootstrap>", line 488, in _call_with_frames_removed
  File "/opt/airflow/dags/tes_dag.py", line 5, in <module>
    from test import test2
  File "/opt/airflow/dags/test.py", line 2, in <module>
    from kaggle.api.kaggle_api_extended import KaggleApi
  File "/home/airflow/.local/lib/python3.12/site-packages/kaggle/__init__.py", line 7, in <module>
    api.authenticate()
  File "/home/airflow/.local/lib/python3.12/site-packages/kaggle/api/kaggle_api_extended.py", line 407, in authenticate
    raise IOError('Could not find {}. Make sure it\'s located in'
OSError: Could not find kaggle.json. Make sure it's located in /home/airflow/.config/kaggle. Or use the environment method. See setup instructions at https://github.com/Kaggle/kaggle-api/
[2025-01-14T17:53:17.630+0000] {processor.py:927} WARNING - No viable dags retrieved from /opt/airflow/dags/tes_dag.py
[2025-01-14T17:53:17.670+0000] {processor.py:208} INFO - Processing /opt/airflow/dags/tes_dag.py took 0.408 seconds
[2025-01-14T17:53:48.251+0000] {processor.py:186} INFO - Started process (PID=1404) to work on /opt/airflow/dags/tes_dag.py
[2025-01-14T17:53:48.253+0000] {processor.py:914} INFO - Processing file /opt/airflow/dags/tes_dag.py for tasks to queue
[2025-01-14T17:53:48.256+0000] {logging_mixin.py:190} INFO - [2025-01-14T17:53:48.255+0000] {dagbag.py:588} INFO - Filling up the DagBag from /opt/airflow/dags/tes_dag.py
[2025-01-14T17:53:48.451+0000] {logging_mixin.py:190} INFO - [2025-01-14T17:53:48.438+0000] {dagbag.py:387} ERROR - Failed to import: /opt/airflow/dags/tes_dag.py
Traceback (most recent call last):
  File "/home/airflow/.local/lib/python3.12/site-packages/airflow/models/dagbag.py", line 383, in parse
    loader.exec_module(new_module)
  File "<frozen importlib._bootstrap_external>", line 999, in exec_module
  File "<frozen importlib._bootstrap>", line 488, in _call_with_frames_removed
  File "/opt/airflow/dags/tes_dag.py", line 5, in <module>
    from test import test2
  File "/opt/airflow/dags/test.py", line 2, in <module>
    from kaggle.api.kaggle_api_extended import KaggleApi
  File "/home/airflow/.local/lib/python3.12/site-packages/kaggle/__init__.py", line 7, in <module>
    api.authenticate()
  File "/home/airflow/.local/lib/python3.12/site-packages/kaggle/api/kaggle_api_extended.py", line 407, in authenticate
    raise IOError('Could not find {}. Make sure it\'s located in'
OSError: Could not find kaggle.json. Make sure it's located in /home/airflow/.config/kaggle. Or use the environment method. See setup instructions at https://github.com/Kaggle/kaggle-api/
[2025-01-14T17:53:48.452+0000] {processor.py:927} WARNING - No viable dags retrieved from /opt/airflow/dags/tes_dag.py
[2025-01-14T17:53:48.478+0000] {processor.py:208} INFO - Processing /opt/airflow/dags/tes_dag.py took 0.239 seconds
[2025-01-14T17:54:18.881+0000] {processor.py:186} INFO - Started process (PID=1426) to work on /opt/airflow/dags/tes_dag.py
[2025-01-14T17:54:18.883+0000] {processor.py:914} INFO - Processing file /opt/airflow/dags/tes_dag.py for tasks to queue
[2025-01-14T17:54:18.886+0000] {logging_mixin.py:190} INFO - [2025-01-14T17:54:18.885+0000] {dagbag.py:588} INFO - Filling up the DagBag from /opt/airflow/dags/tes_dag.py
[2025-01-14T17:54:19.096+0000] {logging_mixin.py:190} INFO - [2025-01-14T17:54:19.084+0000] {dagbag.py:387} ERROR - Failed to import: /opt/airflow/dags/tes_dag.py
Traceback (most recent call last):
  File "/home/airflow/.local/lib/python3.12/site-packages/airflow/models/dagbag.py", line 383, in parse
    loader.exec_module(new_module)
  File "<frozen importlib._bootstrap_external>", line 999, in exec_module
  File "<frozen importlib._bootstrap>", line 488, in _call_with_frames_removed
  File "/opt/airflow/dags/tes_dag.py", line 5, in <module>
    from test import test2
  File "/opt/airflow/dags/test.py", line 2, in <module>
    from kaggle.api.kaggle_api_extended import KaggleApi
  File "/home/airflow/.local/lib/python3.12/site-packages/kaggle/__init__.py", line 7, in <module>
    api.authenticate()
  File "/home/airflow/.local/lib/python3.12/site-packages/kaggle/api/kaggle_api_extended.py", line 407, in authenticate
    raise IOError('Could not find {}. Make sure it\'s located in'
OSError: Could not find kaggle.json. Make sure it's located in /home/airflow/.config/kaggle. Or use the environment method. See setup instructions at https://github.com/Kaggle/kaggle-api/
[2025-01-14T17:54:19.098+0000] {processor.py:927} WARNING - No viable dags retrieved from /opt/airflow/dags/tes_dag.py
[2025-01-14T17:54:19.135+0000] {processor.py:208} INFO - Processing /opt/airflow/dags/tes_dag.py took 0.266 seconds
[2025-01-14T17:54:49.254+0000] {processor.py:186} INFO - Started process (PID=1448) to work on /opt/airflow/dags/tes_dag.py
[2025-01-14T17:54:49.256+0000] {processor.py:914} INFO - Processing file /opt/airflow/dags/tes_dag.py for tasks to queue
[2025-01-14T17:54:49.258+0000] {logging_mixin.py:190} INFO - [2025-01-14T17:54:49.258+0000] {dagbag.py:588} INFO - Filling up the DagBag from /opt/airflow/dags/tes_dag.py
[2025-01-14T17:54:49.444+0000] {logging_mixin.py:190} INFO - [2025-01-14T17:54:49.432+0000] {dagbag.py:387} ERROR - Failed to import: /opt/airflow/dags/tes_dag.py
Traceback (most recent call last):
  File "/home/airflow/.local/lib/python3.12/site-packages/airflow/models/dagbag.py", line 383, in parse
    loader.exec_module(new_module)
  File "<frozen importlib._bootstrap_external>", line 999, in exec_module
  File "<frozen importlib._bootstrap>", line 488, in _call_with_frames_removed
  File "/opt/airflow/dags/tes_dag.py", line 5, in <module>
    from test import test2
  File "/opt/airflow/dags/test.py", line 2, in <module>
    from kaggle.api.kaggle_api_extended import KaggleApi
  File "/home/airflow/.local/lib/python3.12/site-packages/kaggle/__init__.py", line 7, in <module>
    api.authenticate()
  File "/home/airflow/.local/lib/python3.12/site-packages/kaggle/api/kaggle_api_extended.py", line 407, in authenticate
    raise IOError('Could not find {}. Make sure it\'s located in'
OSError: Could not find kaggle.json. Make sure it's located in /home/airflow/.config/kaggle. Or use the environment method. See setup instructions at https://github.com/Kaggle/kaggle-api/
[2025-01-14T17:54:49.445+0000] {processor.py:927} WARNING - No viable dags retrieved from /opt/airflow/dags/tes_dag.py
[2025-01-14T17:54:49.471+0000] {processor.py:208} INFO - Processing /opt/airflow/dags/tes_dag.py took 0.228 seconds
[2025-01-14T17:55:19.640+0000] {processor.py:186} INFO - Started process (PID=1470) to work on /opt/airflow/dags/tes_dag.py
[2025-01-14T17:55:19.641+0000] {processor.py:914} INFO - Processing file /opt/airflow/dags/tes_dag.py for tasks to queue
[2025-01-14T17:55:19.644+0000] {logging_mixin.py:190} INFO - [2025-01-14T17:55:19.643+0000] {dagbag.py:588} INFO - Filling up the DagBag from /opt/airflow/dags/tes_dag.py
[2025-01-14T17:55:19.814+0000] {logging_mixin.py:190} INFO - [2025-01-14T17:55:19.803+0000] {dagbag.py:387} ERROR - Failed to import: /opt/airflow/dags/tes_dag.py
Traceback (most recent call last):
  File "/home/airflow/.local/lib/python3.12/site-packages/airflow/models/dagbag.py", line 383, in parse
    loader.exec_module(new_module)
  File "<frozen importlib._bootstrap_external>", line 999, in exec_module
  File "<frozen importlib._bootstrap>", line 488, in _call_with_frames_removed
  File "/opt/airflow/dags/tes_dag.py", line 5, in <module>
    from test import test2
  File "/opt/airflow/dags/test.py", line 2, in <module>
    from kaggle.api.kaggle_api_extended import KaggleApi
  File "/home/airflow/.local/lib/python3.12/site-packages/kaggle/__init__.py", line 7, in <module>
    api.authenticate()
  File "/home/airflow/.local/lib/python3.12/site-packages/kaggle/api/kaggle_api_extended.py", line 407, in authenticate
    raise IOError('Could not find {}. Make sure it\'s located in'
OSError: Could not find kaggle.json. Make sure it's located in /home/airflow/.config/kaggle. Or use the environment method. See setup instructions at https://github.com/Kaggle/kaggle-api/
[2025-01-14T17:55:19.815+0000] {processor.py:927} WARNING - No viable dags retrieved from /opt/airflow/dags/tes_dag.py
[2025-01-14T17:55:19.848+0000] {processor.py:208} INFO - Processing /opt/airflow/dags/tes_dag.py took 0.220 seconds
[2025-01-14T17:55:49.966+0000] {processor.py:186} INFO - Started process (PID=1492) to work on /opt/airflow/dags/tes_dag.py
[2025-01-14T17:55:49.967+0000] {processor.py:914} INFO - Processing file /opt/airflow/dags/tes_dag.py for tasks to queue
[2025-01-14T17:55:49.969+0000] {logging_mixin.py:190} INFO - [2025-01-14T17:55:49.969+0000] {dagbag.py:588} INFO - Filling up the DagBag from /opt/airflow/dags/tes_dag.py
[2025-01-14T17:55:50.158+0000] {logging_mixin.py:190} INFO - [2025-01-14T17:55:50.145+0000] {dagbag.py:387} ERROR - Failed to import: /opt/airflow/dags/tes_dag.py
Traceback (most recent call last):
  File "/home/airflow/.local/lib/python3.12/site-packages/airflow/models/dagbag.py", line 383, in parse
    loader.exec_module(new_module)
  File "<frozen importlib._bootstrap_external>", line 999, in exec_module
  File "<frozen importlib._bootstrap>", line 488, in _call_with_frames_removed
  File "/opt/airflow/dags/tes_dag.py", line 5, in <module>
    from test import test2
  File "/opt/airflow/dags/test.py", line 2, in <module>
    from kaggle.api.kaggle_api_extended import KaggleApi
  File "/home/airflow/.local/lib/python3.12/site-packages/kaggle/__init__.py", line 7, in <module>
    api.authenticate()
  File "/home/airflow/.local/lib/python3.12/site-packages/kaggle/api/kaggle_api_extended.py", line 407, in authenticate
    raise IOError('Could not find {}. Make sure it\'s located in'
OSError: Could not find kaggle.json. Make sure it's located in /home/airflow/.config/kaggle. Or use the environment method. See setup instructions at https://github.com/Kaggle/kaggle-api/
[2025-01-14T17:55:50.159+0000] {processor.py:927} WARNING - No viable dags retrieved from /opt/airflow/dags/tes_dag.py
[2025-01-14T17:55:50.188+0000] {processor.py:208} INFO - Processing /opt/airflow/dags/tes_dag.py took 0.236 seconds
[2025-01-14T17:56:20.570+0000] {processor.py:186} INFO - Started process (PID=1513) to work on /opt/airflow/dags/tes_dag.py
[2025-01-14T17:56:20.571+0000] {processor.py:914} INFO - Processing file /opt/airflow/dags/tes_dag.py for tasks to queue
[2025-01-14T17:56:20.574+0000] {logging_mixin.py:190} INFO - [2025-01-14T17:56:20.573+0000] {dagbag.py:588} INFO - Filling up the DagBag from /opt/airflow/dags/tes_dag.py
[2025-01-14T17:56:20.746+0000] {logging_mixin.py:190} INFO - [2025-01-14T17:56:20.733+0000] {dagbag.py:387} ERROR - Failed to import: /opt/airflow/dags/tes_dag.py
Traceback (most recent call last):
  File "/home/airflow/.local/lib/python3.12/site-packages/airflow/models/dagbag.py", line 383, in parse
    loader.exec_module(new_module)
  File "<frozen importlib._bootstrap_external>", line 999, in exec_module
  File "<frozen importlib._bootstrap>", line 488, in _call_with_frames_removed
  File "/opt/airflow/dags/tes_dag.py", line 5, in <module>
    from test import test2
  File "/opt/airflow/dags/test.py", line 2, in <module>
    from kaggle.api.kaggle_api_extended import KaggleApi
  File "/home/airflow/.local/lib/python3.12/site-packages/kaggle/__init__.py", line 7, in <module>
    api.authenticate()
  File "/home/airflow/.local/lib/python3.12/site-packages/kaggle/api/kaggle_api_extended.py", line 407, in authenticate
    raise IOError('Could not find {}. Make sure it\'s located in'
OSError: Could not find kaggle.json. Make sure it's located in /home/airflow/.config/kaggle. Or use the environment method. See setup instructions at https://github.com/Kaggle/kaggle-api/
[2025-01-14T17:56:20.748+0000] {processor.py:927} WARNING - No viable dags retrieved from /opt/airflow/dags/tes_dag.py
[2025-01-14T17:56:20.776+0000] {processor.py:208} INFO - Processing /opt/airflow/dags/tes_dag.py took 0.219 seconds
[2025-01-14T17:56:50.921+0000] {processor.py:186} INFO - Started process (PID=1534) to work on /opt/airflow/dags/tes_dag.py
[2025-01-14T17:56:50.923+0000] {processor.py:914} INFO - Processing file /opt/airflow/dags/tes_dag.py for tasks to queue
[2025-01-14T17:56:50.926+0000] {logging_mixin.py:190} INFO - [2025-01-14T17:56:50.925+0000] {dagbag.py:588} INFO - Filling up the DagBag from /opt/airflow/dags/tes_dag.py
[2025-01-14T17:56:51.126+0000] {logging_mixin.py:190} INFO - [2025-01-14T17:56:51.117+0000] {dagbag.py:387} ERROR - Failed to import: /opt/airflow/dags/tes_dag.py
Traceback (most recent call last):
  File "/home/airflow/.local/lib/python3.12/site-packages/airflow/models/dagbag.py", line 383, in parse
    loader.exec_module(new_module)
  File "<frozen importlib._bootstrap_external>", line 999, in exec_module
  File "<frozen importlib._bootstrap>", line 488, in _call_with_frames_removed
  File "/opt/airflow/dags/tes_dag.py", line 5, in <module>
    from test import test2
  File "/opt/airflow/dags/test.py", line 2, in <module>
    from kaggle.api.kaggle_api_extended import KaggleApi
  File "/home/airflow/.local/lib/python3.12/site-packages/kaggle/__init__.py", line 7, in <module>
    api.authenticate()
  File "/home/airflow/.local/lib/python3.12/site-packages/kaggle/api/kaggle_api_extended.py", line 407, in authenticate
    raise IOError('Could not find {}. Make sure it\'s located in'
OSError: Could not find kaggle.json. Make sure it's located in /home/airflow/.config/kaggle. Or use the environment method. See setup instructions at https://github.com/Kaggle/kaggle-api/
[2025-01-14T17:56:51.127+0000] {processor.py:927} WARNING - No viable dags retrieved from /opt/airflow/dags/tes_dag.py
[2025-01-14T17:56:51.151+0000] {processor.py:208} INFO - Processing /opt/airflow/dags/tes_dag.py took 0.249 seconds
[2025-01-14T17:57:21.588+0000] {processor.py:186} INFO - Started process (PID=1556) to work on /opt/airflow/dags/tes_dag.py
[2025-01-14T17:57:21.589+0000] {processor.py:914} INFO - Processing file /opt/airflow/dags/tes_dag.py for tasks to queue
[2025-01-14T17:57:21.591+0000] {logging_mixin.py:190} INFO - [2025-01-14T17:57:21.591+0000] {dagbag.py:588} INFO - Filling up the DagBag from /opt/airflow/dags/tes_dag.py
[2025-01-14T17:57:21.899+0000] {logging_mixin.py:190} INFO - [2025-01-14T17:57:21.884+0000] {dagbag.py:387} ERROR - Failed to import: /opt/airflow/dags/tes_dag.py
Traceback (most recent call last):
  File "/home/airflow/.local/lib/python3.12/site-packages/airflow/models/dagbag.py", line 383, in parse
    loader.exec_module(new_module)
  File "<frozen importlib._bootstrap_external>", line 999, in exec_module
  File "<frozen importlib._bootstrap>", line 488, in _call_with_frames_removed
  File "/opt/airflow/dags/tes_dag.py", line 5, in <module>
    from test import test2
  File "/opt/airflow/dags/test.py", line 2, in <module>
    from kaggle.api.kaggle_api_extended import KaggleApi
  File "/home/airflow/.local/lib/python3.12/site-packages/kaggle/__init__.py", line 7, in <module>
    api.authenticate()
  File "/home/airflow/.local/lib/python3.12/site-packages/kaggle/api/kaggle_api_extended.py", line 407, in authenticate
    raise IOError('Could not find {}. Make sure it\'s located in'
OSError: Could not find kaggle.json. Make sure it's located in /home/airflow/.config/kaggle. Or use the environment method. See setup instructions at https://github.com/Kaggle/kaggle-api/
[2025-01-14T17:57:21.901+0000] {processor.py:927} WARNING - No viable dags retrieved from /opt/airflow/dags/tes_dag.py
[2025-01-14T17:57:21.944+0000] {processor.py:208} INFO - Processing /opt/airflow/dags/tes_dag.py took 0.364 seconds
[2025-01-14T17:57:52.320+0000] {processor.py:186} INFO - Started process (PID=1578) to work on /opt/airflow/dags/tes_dag.py
[2025-01-14T17:57:52.322+0000] {processor.py:914} INFO - Processing file /opt/airflow/dags/tes_dag.py for tasks to queue
[2025-01-14T17:57:52.324+0000] {logging_mixin.py:190} INFO - [2025-01-14T17:57:52.324+0000] {dagbag.py:588} INFO - Filling up the DagBag from /opt/airflow/dags/tes_dag.py
[2025-01-14T17:57:52.498+0000] {logging_mixin.py:190} INFO - [2025-01-14T17:57:52.486+0000] {dagbag.py:387} ERROR - Failed to import: /opt/airflow/dags/tes_dag.py
Traceback (most recent call last):
  File "/home/airflow/.local/lib/python3.12/site-packages/airflow/models/dagbag.py", line 383, in parse
    loader.exec_module(new_module)
  File "<frozen importlib._bootstrap_external>", line 999, in exec_module
  File "<frozen importlib._bootstrap>", line 488, in _call_with_frames_removed
  File "/opt/airflow/dags/tes_dag.py", line 5, in <module>
    from test import test2
  File "/opt/airflow/dags/test.py", line 2, in <module>
    from kaggle.api.kaggle_api_extended import KaggleApi
  File "/home/airflow/.local/lib/python3.12/site-packages/kaggle/__init__.py", line 7, in <module>
    api.authenticate()
  File "/home/airflow/.local/lib/python3.12/site-packages/kaggle/api/kaggle_api_extended.py", line 407, in authenticate
    raise IOError('Could not find {}. Make sure it\'s located in'
OSError: Could not find kaggle.json. Make sure it's located in /home/airflow/.config/kaggle. Or use the environment method. See setup instructions at https://github.com/Kaggle/kaggle-api/
[2025-01-14T17:57:52.499+0000] {processor.py:927} WARNING - No viable dags retrieved from /opt/airflow/dags/tes_dag.py
[2025-01-14T17:57:52.531+0000] {processor.py:208} INFO - Processing /opt/airflow/dags/tes_dag.py took 0.220 seconds
[2025-01-14T17:58:22.972+0000] {processor.py:186} INFO - Started process (PID=1605) to work on /opt/airflow/dags/tes_dag.py
[2025-01-14T17:58:22.974+0000] {processor.py:914} INFO - Processing file /opt/airflow/dags/tes_dag.py for tasks to queue
[2025-01-14T17:58:22.976+0000] {logging_mixin.py:190} INFO - [2025-01-14T17:58:22.975+0000] {dagbag.py:588} INFO - Filling up the DagBag from /opt/airflow/dags/tes_dag.py
[2025-01-14T17:58:23.153+0000] {logging_mixin.py:190} INFO - [2025-01-14T17:58:23.139+0000] {dagbag.py:387} ERROR - Failed to import: /opt/airflow/dags/tes_dag.py
Traceback (most recent call last):
  File "/home/airflow/.local/lib/python3.12/site-packages/airflow/models/dagbag.py", line 383, in parse
    loader.exec_module(new_module)
  File "<frozen importlib._bootstrap_external>", line 999, in exec_module
  File "<frozen importlib._bootstrap>", line 488, in _call_with_frames_removed
  File "/opt/airflow/dags/tes_dag.py", line 5, in <module>
    from test import test2
  File "/opt/airflow/dags/test.py", line 2, in <module>
    from kaggle.api.kaggle_api_extended import KaggleApi
  File "/home/airflow/.local/lib/python3.12/site-packages/kaggle/__init__.py", line 7, in <module>
    api.authenticate()
  File "/home/airflow/.local/lib/python3.12/site-packages/kaggle/api/kaggle_api_extended.py", line 407, in authenticate
    raise IOError('Could not find {}. Make sure it\'s located in'
OSError: Could not find kaggle.json. Make sure it's located in /home/airflow/.config/kaggle. Or use the environment method. See setup instructions at https://github.com/Kaggle/kaggle-api/
[2025-01-14T17:58:23.154+0000] {processor.py:927} WARNING - No viable dags retrieved from /opt/airflow/dags/tes_dag.py
[2025-01-14T17:58:23.193+0000] {processor.py:208} INFO - Processing /opt/airflow/dags/tes_dag.py took 0.233 seconds
[2025-01-14T17:58:53.326+0000] {processor.py:186} INFO - Started process (PID=1627) to work on /opt/airflow/dags/tes_dag.py
[2025-01-14T17:58:53.328+0000] {processor.py:914} INFO - Processing file /opt/airflow/dags/tes_dag.py for tasks to queue
[2025-01-14T17:58:53.332+0000] {logging_mixin.py:190} INFO - [2025-01-14T17:58:53.331+0000] {dagbag.py:588} INFO - Filling up the DagBag from /opt/airflow/dags/tes_dag.py
[2025-01-14T17:58:53.553+0000] {logging_mixin.py:190} INFO - [2025-01-14T17:58:53.540+0000] {dagbag.py:387} ERROR - Failed to import: /opt/airflow/dags/tes_dag.py
Traceback (most recent call last):
  File "/home/airflow/.local/lib/python3.12/site-packages/airflow/models/dagbag.py", line 383, in parse
    loader.exec_module(new_module)
  File "<frozen importlib._bootstrap_external>", line 999, in exec_module
  File "<frozen importlib._bootstrap>", line 488, in _call_with_frames_removed
  File "/opt/airflow/dags/tes_dag.py", line 5, in <module>
    from test import test2
  File "/opt/airflow/dags/test.py", line 2, in <module>
    from kaggle.api.kaggle_api_extended import KaggleApi
  File "/home/airflow/.local/lib/python3.12/site-packages/kaggle/__init__.py", line 7, in <module>
    api.authenticate()
  File "/home/airflow/.local/lib/python3.12/site-packages/kaggle/api/kaggle_api_extended.py", line 407, in authenticate
    raise IOError('Could not find {}. Make sure it\'s located in'
OSError: Could not find kaggle.json. Make sure it's located in /home/airflow/.config/kaggle. Or use the environment method. See setup instructions at https://github.com/Kaggle/kaggle-api/
[2025-01-14T17:58:53.554+0000] {processor.py:927} WARNING - No viable dags retrieved from /opt/airflow/dags/tes_dag.py
[2025-01-14T17:58:53.582+0000] {processor.py:208} INFO - Processing /opt/airflow/dags/tes_dag.py took 0.268 seconds
[2025-01-14T17:59:23.952+0000] {processor.py:186} INFO - Started process (PID=1649) to work on /opt/airflow/dags/tes_dag.py
[2025-01-14T17:59:23.955+0000] {processor.py:914} INFO - Processing file /opt/airflow/dags/tes_dag.py for tasks to queue
[2025-01-14T17:59:23.958+0000] {logging_mixin.py:190} INFO - [2025-01-14T17:59:23.957+0000] {dagbag.py:588} INFO - Filling up the DagBag from /opt/airflow/dags/tes_dag.py
[2025-01-14T17:59:24.132+0000] {logging_mixin.py:190} INFO - [2025-01-14T17:59:24.124+0000] {dagbag.py:387} ERROR - Failed to import: /opt/airflow/dags/tes_dag.py
Traceback (most recent call last):
  File "/home/airflow/.local/lib/python3.12/site-packages/airflow/models/dagbag.py", line 383, in parse
    loader.exec_module(new_module)
  File "<frozen importlib._bootstrap_external>", line 999, in exec_module
  File "<frozen importlib._bootstrap>", line 488, in _call_with_frames_removed
  File "/opt/airflow/dags/tes_dag.py", line 5, in <module>
    from test import test2
  File "/opt/airflow/dags/test.py", line 2, in <module>
    from kaggle.api.kaggle_api_extended import KaggleApi
  File "/home/airflow/.local/lib/python3.12/site-packages/kaggle/__init__.py", line 7, in <module>
    api.authenticate()
  File "/home/airflow/.local/lib/python3.12/site-packages/kaggle/api/kaggle_api_extended.py", line 407, in authenticate
    raise IOError('Could not find {}. Make sure it\'s located in'
OSError: Could not find kaggle.json. Make sure it's located in /home/airflow/.config/kaggle. Or use the environment method. See setup instructions at https://github.com/Kaggle/kaggle-api/
[2025-01-14T17:59:24.134+0000] {processor.py:927} WARNING - No viable dags retrieved from /opt/airflow/dags/tes_dag.py
[2025-01-14T17:59:24.158+0000] {processor.py:208} INFO - Processing /opt/airflow/dags/tes_dag.py took 0.218 seconds
[2025-01-14T17:59:54.499+0000] {processor.py:186} INFO - Started process (PID=1671) to work on /opt/airflow/dags/tes_dag.py
[2025-01-14T17:59:54.501+0000] {processor.py:914} INFO - Processing file /opt/airflow/dags/tes_dag.py for tasks to queue
[2025-01-14T17:59:54.503+0000] {logging_mixin.py:190} INFO - [2025-01-14T17:59:54.503+0000] {dagbag.py:588} INFO - Filling up the DagBag from /opt/airflow/dags/tes_dag.py
[2025-01-14T17:59:54.726+0000] {logging_mixin.py:190} INFO - [2025-01-14T17:59:54.711+0000] {dagbag.py:387} ERROR - Failed to import: /opt/airflow/dags/tes_dag.py
Traceback (most recent call last):
  File "/home/airflow/.local/lib/python3.12/site-packages/airflow/models/dagbag.py", line 383, in parse
    loader.exec_module(new_module)
  File "<frozen importlib._bootstrap_external>", line 999, in exec_module
  File "<frozen importlib._bootstrap>", line 488, in _call_with_frames_removed
  File "/opt/airflow/dags/tes_dag.py", line 5, in <module>
    from test import test2
  File "/opt/airflow/dags/test.py", line 2, in <module>
    from kaggle.api.kaggle_api_extended import KaggleApi
  File "/home/airflow/.local/lib/python3.12/site-packages/kaggle/__init__.py", line 7, in <module>
    api.authenticate()
  File "/home/airflow/.local/lib/python3.12/site-packages/kaggle/api/kaggle_api_extended.py", line 407, in authenticate
    raise IOError('Could not find {}. Make sure it\'s located in'
OSError: Could not find kaggle.json. Make sure it's located in /home/airflow/.config/kaggle. Or use the environment method. See setup instructions at https://github.com/Kaggle/kaggle-api/
[2025-01-14T17:59:54.728+0000] {processor.py:927} WARNING - No viable dags retrieved from /opt/airflow/dags/tes_dag.py
[2025-01-14T17:59:54.769+0000] {processor.py:208} INFO - Processing /opt/airflow/dags/tes_dag.py took 0.280 seconds
[2025-01-14T18:00:25.206+0000] {processor.py:186} INFO - Started process (PID=1693) to work on /opt/airflow/dags/tes_dag.py
[2025-01-14T18:00:25.209+0000] {processor.py:914} INFO - Processing file /opt/airflow/dags/tes_dag.py for tasks to queue
[2025-01-14T18:00:25.213+0000] {logging_mixin.py:190} INFO - [2025-01-14T18:00:25.212+0000] {dagbag.py:588} INFO - Filling up the DagBag from /opt/airflow/dags/tes_dag.py
[2025-01-14T18:00:25.397+0000] {logging_mixin.py:190} INFO - [2025-01-14T18:00:25.385+0000] {dagbag.py:387} ERROR - Failed to import: /opt/airflow/dags/tes_dag.py
Traceback (most recent call last):
  File "/home/airflow/.local/lib/python3.12/site-packages/airflow/models/dagbag.py", line 383, in parse
    loader.exec_module(new_module)
  File "<frozen importlib._bootstrap_external>", line 999, in exec_module
  File "<frozen importlib._bootstrap>", line 488, in _call_with_frames_removed
  File "/opt/airflow/dags/tes_dag.py", line 5, in <module>
    from test import test2
  File "/opt/airflow/dags/test.py", line 2, in <module>
    from kaggle.api.kaggle_api_extended import KaggleApi
  File "/home/airflow/.local/lib/python3.12/site-packages/kaggle/__init__.py", line 7, in <module>
    api.authenticate()
  File "/home/airflow/.local/lib/python3.12/site-packages/kaggle/api/kaggle_api_extended.py", line 407, in authenticate
    raise IOError('Could not find {}. Make sure it\'s located in'
OSError: Could not find kaggle.json. Make sure it's located in /home/airflow/.config/kaggle. Or use the environment method. See setup instructions at https://github.com/Kaggle/kaggle-api/
[2025-01-14T18:00:25.398+0000] {processor.py:927} WARNING - No viable dags retrieved from /opt/airflow/dags/tes_dag.py
[2025-01-14T18:00:25.426+0000] {processor.py:208} INFO - Processing /opt/airflow/dags/tes_dag.py took 0.261 seconds
[2025-01-14T18:00:55.612+0000] {processor.py:186} INFO - Started process (PID=1715) to work on /opt/airflow/dags/tes_dag.py
[2025-01-14T18:00:55.613+0000] {processor.py:914} INFO - Processing file /opt/airflow/dags/tes_dag.py for tasks to queue
[2025-01-14T18:00:55.615+0000] {logging_mixin.py:190} INFO - [2025-01-14T18:00:55.615+0000] {dagbag.py:588} INFO - Filling up the DagBag from /opt/airflow/dags/tes_dag.py
[2025-01-14T18:00:55.783+0000] {logging_mixin.py:190} INFO - [2025-01-14T18:00:55.769+0000] {dagbag.py:387} ERROR - Failed to import: /opt/airflow/dags/tes_dag.py
Traceback (most recent call last):
  File "/home/airflow/.local/lib/python3.12/site-packages/airflow/models/dagbag.py", line 383, in parse
    loader.exec_module(new_module)
  File "<frozen importlib._bootstrap_external>", line 999, in exec_module
  File "<frozen importlib._bootstrap>", line 488, in _call_with_frames_removed
  File "/opt/airflow/dags/tes_dag.py", line 5, in <module>
    from test import test2
  File "/opt/airflow/dags/test.py", line 2, in <module>
    from kaggle.api.kaggle_api_extended import KaggleApi
  File "/home/airflow/.local/lib/python3.12/site-packages/kaggle/__init__.py", line 7, in <module>
    api.authenticate()
  File "/home/airflow/.local/lib/python3.12/site-packages/kaggle/api/kaggle_api_extended.py", line 407, in authenticate
    raise IOError('Could not find {}. Make sure it\'s located in'
OSError: Could not find kaggle.json. Make sure it's located in /home/airflow/.config/kaggle. Or use the environment method. See setup instructions at https://github.com/Kaggle/kaggle-api/
[2025-01-14T18:00:55.784+0000] {processor.py:927} WARNING - No viable dags retrieved from /opt/airflow/dags/tes_dag.py
[2025-01-14T18:00:55.816+0000] {processor.py:208} INFO - Processing /opt/airflow/dags/tes_dag.py took 0.212 seconds
[2025-01-14T18:01:26.776+0000] {processor.py:186} INFO - Started process (PID=1737) to work on /opt/airflow/dags/tes_dag.py
[2025-01-14T18:01:26.778+0000] {processor.py:914} INFO - Processing file /opt/airflow/dags/tes_dag.py for tasks to queue
[2025-01-14T18:01:26.780+0000] {logging_mixin.py:190} INFO - [2025-01-14T18:01:26.780+0000] {dagbag.py:588} INFO - Filling up the DagBag from /opt/airflow/dags/tes_dag.py
[2025-01-14T18:01:26.986+0000] {logging_mixin.py:190} INFO - [2025-01-14T18:01:26.972+0000] {dagbag.py:387} ERROR - Failed to import: /opt/airflow/dags/tes_dag.py
Traceback (most recent call last):
  File "/home/airflow/.local/lib/python3.12/site-packages/airflow/models/dagbag.py", line 383, in parse
    loader.exec_module(new_module)
  File "<frozen importlib._bootstrap_external>", line 999, in exec_module
  File "<frozen importlib._bootstrap>", line 488, in _call_with_frames_removed
  File "/opt/airflow/dags/tes_dag.py", line 5, in <module>
    from test import test2
  File "/opt/airflow/dags/test.py", line 2, in <module>
    from kaggle.api.kaggle_api_extended import KaggleApi
  File "/home/airflow/.local/lib/python3.12/site-packages/kaggle/__init__.py", line 7, in <module>
    api.authenticate()
  File "/home/airflow/.local/lib/python3.12/site-packages/kaggle/api/kaggle_api_extended.py", line 407, in authenticate
    raise IOError('Could not find {}. Make sure it\'s located in'
OSError: Could not find kaggle.json. Make sure it's located in /home/airflow/.config/kaggle. Or use the environment method. See setup instructions at https://github.com/Kaggle/kaggle-api/
[2025-01-14T18:01:26.989+0000] {processor.py:927} WARNING - No viable dags retrieved from /opt/airflow/dags/tes_dag.py
[2025-01-14T18:01:27.014+0000] {processor.py:208} INFO - Processing /opt/airflow/dags/tes_dag.py took 0.250 seconds
[2025-01-14T18:01:57.364+0000] {processor.py:186} INFO - Started process (PID=1759) to work on /opt/airflow/dags/tes_dag.py
[2025-01-14T18:01:57.367+0000] {processor.py:914} INFO - Processing file /opt/airflow/dags/tes_dag.py for tasks to queue
[2025-01-14T18:01:57.370+0000] {logging_mixin.py:190} INFO - [2025-01-14T18:01:57.370+0000] {dagbag.py:588} INFO - Filling up the DagBag from /opt/airflow/dags/tes_dag.py
[2025-01-14T18:01:57.561+0000] {logging_mixin.py:190} INFO - [2025-01-14T18:01:57.548+0000] {dagbag.py:387} ERROR - Failed to import: /opt/airflow/dags/tes_dag.py
Traceback (most recent call last):
  File "/home/airflow/.local/lib/python3.12/site-packages/airflow/models/dagbag.py", line 383, in parse
    loader.exec_module(new_module)
  File "<frozen importlib._bootstrap_external>", line 999, in exec_module
  File "<frozen importlib._bootstrap>", line 488, in _call_with_frames_removed
  File "/opt/airflow/dags/tes_dag.py", line 5, in <module>
    from test import test2
  File "/opt/airflow/dags/test.py", line 2, in <module>
    from kaggle.api.kaggle_api_extended import KaggleApi
  File "/home/airflow/.local/lib/python3.12/site-packages/kaggle/__init__.py", line 7, in <module>
    api.authenticate()
  File "/home/airflow/.local/lib/python3.12/site-packages/kaggle/api/kaggle_api_extended.py", line 407, in authenticate
    raise IOError('Could not find {}. Make sure it\'s located in'
OSError: Could not find kaggle.json. Make sure it's located in /home/airflow/.config/kaggle. Or use the environment method. See setup instructions at https://github.com/Kaggle/kaggle-api/
[2025-01-14T18:01:57.562+0000] {processor.py:927} WARNING - No viable dags retrieved from /opt/airflow/dags/tes_dag.py
[2025-01-14T18:01:57.599+0000] {processor.py:208} INFO - Processing /opt/airflow/dags/tes_dag.py took 0.247 seconds
[2025-01-14T18:02:27.801+0000] {processor.py:186} INFO - Started process (PID=1781) to work on /opt/airflow/dags/tes_dag.py
[2025-01-14T18:02:27.802+0000] {processor.py:914} INFO - Processing file /opt/airflow/dags/tes_dag.py for tasks to queue
[2025-01-14T18:02:27.805+0000] {logging_mixin.py:190} INFO - [2025-01-14T18:02:27.804+0000] {dagbag.py:588} INFO - Filling up the DagBag from /opt/airflow/dags/tes_dag.py
[2025-01-14T18:02:27.979+0000] {logging_mixin.py:190} INFO - [2025-01-14T18:02:27.967+0000] {dagbag.py:387} ERROR - Failed to import: /opt/airflow/dags/tes_dag.py
Traceback (most recent call last):
  File "/home/airflow/.local/lib/python3.12/site-packages/airflow/models/dagbag.py", line 383, in parse
    loader.exec_module(new_module)
  File "<frozen importlib._bootstrap_external>", line 999, in exec_module
  File "<frozen importlib._bootstrap>", line 488, in _call_with_frames_removed
  File "/opt/airflow/dags/tes_dag.py", line 5, in <module>
    from test import test2
  File "/opt/airflow/dags/test.py", line 2, in <module>
    from kaggle.api.kaggle_api_extended import KaggleApi
  File "/home/airflow/.local/lib/python3.12/site-packages/kaggle/__init__.py", line 7, in <module>
    api.authenticate()
  File "/home/airflow/.local/lib/python3.12/site-packages/kaggle/api/kaggle_api_extended.py", line 407, in authenticate
    raise IOError('Could not find {}. Make sure it\'s located in'
OSError: Could not find kaggle.json. Make sure it's located in /home/airflow/.config/kaggle. Or use the environment method. See setup instructions at https://github.com/Kaggle/kaggle-api/
[2025-01-14T18:02:27.980+0000] {processor.py:927} WARNING - No viable dags retrieved from /opt/airflow/dags/tes_dag.py
[2025-01-14T18:02:28.011+0000] {processor.py:208} INFO - Processing /opt/airflow/dags/tes_dag.py took 0.226 seconds
[2025-01-14T18:02:58.174+0000] {processor.py:186} INFO - Started process (PID=1802) to work on /opt/airflow/dags/tes_dag.py
[2025-01-14T18:02:58.176+0000] {processor.py:914} INFO - Processing file /opt/airflow/dags/tes_dag.py for tasks to queue
[2025-01-14T18:02:58.178+0000] {logging_mixin.py:190} INFO - [2025-01-14T18:02:58.178+0000] {dagbag.py:588} INFO - Filling up the DagBag from /opt/airflow/dags/tes_dag.py
[2025-01-14T18:02:58.363+0000] {logging_mixin.py:190} INFO - [2025-01-14T18:02:58.348+0000] {dagbag.py:387} ERROR - Failed to import: /opt/airflow/dags/tes_dag.py
Traceback (most recent call last):
  File "/home/airflow/.local/lib/python3.12/site-packages/airflow/models/dagbag.py", line 383, in parse
    loader.exec_module(new_module)
  File "<frozen importlib._bootstrap_external>", line 999, in exec_module
  File "<frozen importlib._bootstrap>", line 488, in _call_with_frames_removed
  File "/opt/airflow/dags/tes_dag.py", line 5, in <module>
    from test import test2
  File "/opt/airflow/dags/test.py", line 2, in <module>
    from kaggle.api.kaggle_api_extended import KaggleApi
  File "/home/airflow/.local/lib/python3.12/site-packages/kaggle/__init__.py", line 7, in <module>
    api.authenticate()
  File "/home/airflow/.local/lib/python3.12/site-packages/kaggle/api/kaggle_api_extended.py", line 407, in authenticate
    raise IOError('Could not find {}. Make sure it\'s located in'
OSError: Could not find kaggle.json. Make sure it's located in /home/airflow/.config/kaggle. Or use the environment method. See setup instructions at https://github.com/Kaggle/kaggle-api/
[2025-01-14T18:02:58.364+0000] {processor.py:927} WARNING - No viable dags retrieved from /opt/airflow/dags/tes_dag.py
[2025-01-14T18:02:58.391+0000] {processor.py:208} INFO - Processing /opt/airflow/dags/tes_dag.py took 0.231 seconds
[2025-01-14T18:03:28.952+0000] {processor.py:186} INFO - Started process (PID=1824) to work on /opt/airflow/dags/tes_dag.py
[2025-01-14T18:03:28.954+0000] {processor.py:914} INFO - Processing file /opt/airflow/dags/tes_dag.py for tasks to queue
[2025-01-14T18:03:28.956+0000] {logging_mixin.py:190} INFO - [2025-01-14T18:03:28.955+0000] {dagbag.py:588} INFO - Filling up the DagBag from /opt/airflow/dags/tes_dag.py
[2025-01-14T18:03:29.119+0000] {logging_mixin.py:190} INFO - [2025-01-14T18:03:29.108+0000] {dagbag.py:387} ERROR - Failed to import: /opt/airflow/dags/tes_dag.py
Traceback (most recent call last):
  File "/home/airflow/.local/lib/python3.12/site-packages/airflow/models/dagbag.py", line 383, in parse
    loader.exec_module(new_module)
  File "<frozen importlib._bootstrap_external>", line 999, in exec_module
  File "<frozen importlib._bootstrap>", line 488, in _call_with_frames_removed
  File "/opt/airflow/dags/tes_dag.py", line 5, in <module>
    from test import test2
  File "/opt/airflow/dags/test.py", line 2, in <module>
    from kaggle.api.kaggle_api_extended import KaggleApi
  File "/home/airflow/.local/lib/python3.12/site-packages/kaggle/__init__.py", line 7, in <module>
    api.authenticate()
  File "/home/airflow/.local/lib/python3.12/site-packages/kaggle/api/kaggle_api_extended.py", line 407, in authenticate
    raise IOError('Could not find {}. Make sure it\'s located in'
OSError: Could not find kaggle.json. Make sure it's located in /home/airflow/.config/kaggle. Or use the environment method. See setup instructions at https://github.com/Kaggle/kaggle-api/
[2025-01-14T18:03:29.121+0000] {processor.py:927} WARNING - No viable dags retrieved from /opt/airflow/dags/tes_dag.py
[2025-01-14T18:03:29.160+0000] {processor.py:208} INFO - Processing /opt/airflow/dags/tes_dag.py took 0.218 seconds
[2025-01-14T18:03:59.821+0000] {processor.py:186} INFO - Started process (PID=1846) to work on /opt/airflow/dags/tes_dag.py
[2025-01-14T18:03:59.824+0000] {processor.py:914} INFO - Processing file /opt/airflow/dags/tes_dag.py for tasks to queue
[2025-01-14T18:03:59.827+0000] {logging_mixin.py:190} INFO - [2025-01-14T18:03:59.826+0000] {dagbag.py:588} INFO - Filling up the DagBag from /opt/airflow/dags/tes_dag.py
[2025-01-14T18:04:00.075+0000] {logging_mixin.py:190} INFO - [2025-01-14T18:04:00.061+0000] {dagbag.py:387} ERROR - Failed to import: /opt/airflow/dags/tes_dag.py
Traceback (most recent call last):
  File "/home/airflow/.local/lib/python3.12/site-packages/airflow/models/dagbag.py", line 383, in parse
    loader.exec_module(new_module)
  File "<frozen importlib._bootstrap_external>", line 999, in exec_module
  File "<frozen importlib._bootstrap>", line 488, in _call_with_frames_removed
  File "/opt/airflow/dags/tes_dag.py", line 5, in <module>
    from test import test2
  File "/opt/airflow/dags/test.py", line 2, in <module>
    from kaggle.api.kaggle_api_extended import KaggleApi
  File "/home/airflow/.local/lib/python3.12/site-packages/kaggle/__init__.py", line 7, in <module>
    api.authenticate()
  File "/home/airflow/.local/lib/python3.12/site-packages/kaggle/api/kaggle_api_extended.py", line 407, in authenticate
    raise IOError('Could not find {}. Make sure it\'s located in'
OSError: Could not find kaggle.json. Make sure it's located in /home/airflow/.config/kaggle. Or use the environment method. See setup instructions at https://github.com/Kaggle/kaggle-api/
[2025-01-14T18:04:00.077+0000] {processor.py:927} WARNING - No viable dags retrieved from /opt/airflow/dags/tes_dag.py
[2025-01-14T18:04:00.135+0000] {processor.py:208} INFO - Processing /opt/airflow/dags/tes_dag.py took 0.331 seconds
[2025-01-14T18:04:30.526+0000] {processor.py:186} INFO - Started process (PID=1867) to work on /opt/airflow/dags/tes_dag.py
[2025-01-14T18:04:30.528+0000] {processor.py:914} INFO - Processing file /opt/airflow/dags/tes_dag.py for tasks to queue
[2025-01-14T18:04:30.531+0000] {logging_mixin.py:190} INFO - [2025-01-14T18:04:30.530+0000] {dagbag.py:588} INFO - Filling up the DagBag from /opt/airflow/dags/tes_dag.py
[2025-01-14T18:04:30.752+0000] {logging_mixin.py:190} INFO - [2025-01-14T18:04:30.738+0000] {dagbag.py:387} ERROR - Failed to import: /opt/airflow/dags/tes_dag.py
Traceback (most recent call last):
  File "/home/airflow/.local/lib/python3.12/site-packages/airflow/models/dagbag.py", line 383, in parse
    loader.exec_module(new_module)
  File "<frozen importlib._bootstrap_external>", line 999, in exec_module
  File "<frozen importlib._bootstrap>", line 488, in _call_with_frames_removed
  File "/opt/airflow/dags/tes_dag.py", line 5, in <module>
    from test import test2
  File "/opt/airflow/dags/test.py", line 2, in <module>
    from kaggle.api.kaggle_api_extended import KaggleApi
  File "/home/airflow/.local/lib/python3.12/site-packages/kaggle/__init__.py", line 7, in <module>
    api.authenticate()
  File "/home/airflow/.local/lib/python3.12/site-packages/kaggle/api/kaggle_api_extended.py", line 407, in authenticate
    raise IOError('Could not find {}. Make sure it\'s located in'
OSError: Could not find kaggle.json. Make sure it's located in /home/airflow/.config/kaggle. Or use the environment method. See setup instructions at https://github.com/Kaggle/kaggle-api/
[2025-01-14T18:04:30.753+0000] {processor.py:927} WARNING - No viable dags retrieved from /opt/airflow/dags/tes_dag.py
[2025-01-14T18:04:30.785+0000] {processor.py:208} INFO - Processing /opt/airflow/dags/tes_dag.py took 0.271 seconds
[2025-01-14T18:05:01.182+0000] {processor.py:186} INFO - Started process (PID=1889) to work on /opt/airflow/dags/tes_dag.py
[2025-01-14T18:05:01.184+0000] {processor.py:914} INFO - Processing file /opt/airflow/dags/tes_dag.py for tasks to queue
[2025-01-14T18:05:01.185+0000] {logging_mixin.py:190} INFO - [2025-01-14T18:05:01.185+0000] {dagbag.py:588} INFO - Filling up the DagBag from /opt/airflow/dags/tes_dag.py
[2025-01-14T18:05:01.329+0000] {logging_mixin.py:190} INFO - [2025-01-14T18:05:01.317+0000] {dagbag.py:387} ERROR - Failed to import: /opt/airflow/dags/tes_dag.py
Traceback (most recent call last):
  File "/home/airflow/.local/lib/python3.12/site-packages/airflow/models/dagbag.py", line 383, in parse
    loader.exec_module(new_module)
  File "<frozen importlib._bootstrap_external>", line 999, in exec_module
  File "<frozen importlib._bootstrap>", line 488, in _call_with_frames_removed
  File "/opt/airflow/dags/tes_dag.py", line 5, in <module>
    from test import test2
  File "/opt/airflow/dags/test.py", line 2, in <module>
    from kaggle.api.kaggle_api_extended import KaggleApi
  File "/home/airflow/.local/lib/python3.12/site-packages/kaggle/__init__.py", line 7, in <module>
    api.authenticate()
  File "/home/airflow/.local/lib/python3.12/site-packages/kaggle/api/kaggle_api_extended.py", line 407, in authenticate
    raise IOError('Could not find {}. Make sure it\'s located in'
OSError: Could not find kaggle.json. Make sure it's located in /home/airflow/.config/kaggle. Or use the environment method. See setup instructions at https://github.com/Kaggle/kaggle-api/
[2025-01-14T18:05:01.330+0000] {processor.py:927} WARNING - No viable dags retrieved from /opt/airflow/dags/tes_dag.py
[2025-01-14T18:05:01.353+0000] {processor.py:208} INFO - Processing /opt/airflow/dags/tes_dag.py took 0.179 seconds
[2025-01-14T18:05:32.132+0000] {processor.py:186} INFO - Started process (PID=1911) to work on /opt/airflow/dags/tes_dag.py
[2025-01-14T18:05:32.134+0000] {processor.py:914} INFO - Processing file /opt/airflow/dags/tes_dag.py for tasks to queue
[2025-01-14T18:05:32.136+0000] {logging_mixin.py:190} INFO - [2025-01-14T18:05:32.135+0000] {dagbag.py:588} INFO - Filling up the DagBag from /opt/airflow/dags/tes_dag.py
[2025-01-14T18:05:32.274+0000] {logging_mixin.py:190} INFO - [2025-01-14T18:05:32.263+0000] {dagbag.py:387} ERROR - Failed to import: /opt/airflow/dags/tes_dag.py
Traceback (most recent call last):
  File "/home/airflow/.local/lib/python3.12/site-packages/airflow/models/dagbag.py", line 383, in parse
    loader.exec_module(new_module)
  File "<frozen importlib._bootstrap_external>", line 999, in exec_module
  File "<frozen importlib._bootstrap>", line 488, in _call_with_frames_removed
  File "/opt/airflow/dags/tes_dag.py", line 5, in <module>
    from test import test2
  File "/opt/airflow/dags/test.py", line 2, in <module>
    from kaggle.api.kaggle_api_extended import KaggleApi
  File "/home/airflow/.local/lib/python3.12/site-packages/kaggle/__init__.py", line 7, in <module>
    api.authenticate()
  File "/home/airflow/.local/lib/python3.12/site-packages/kaggle/api/kaggle_api_extended.py", line 407, in authenticate
    raise IOError('Could not find {}. Make sure it\'s located in'
OSError: Could not find kaggle.json. Make sure it's located in /home/airflow/.config/kaggle. Or use the environment method. See setup instructions at https://github.com/Kaggle/kaggle-api/
[2025-01-14T18:05:32.274+0000] {processor.py:927} WARNING - No viable dags retrieved from /opt/airflow/dags/tes_dag.py
[2025-01-14T18:05:32.305+0000] {processor.py:208} INFO - Processing /opt/airflow/dags/tes_dag.py took 0.182 seconds
[2025-01-14T18:06:02.394+0000] {processor.py:186} INFO - Started process (PID=1933) to work on /opt/airflow/dags/tes_dag.py
[2025-01-14T18:06:02.395+0000] {processor.py:914} INFO - Processing file /opt/airflow/dags/tes_dag.py for tasks to queue
[2025-01-14T18:06:02.397+0000] {logging_mixin.py:190} INFO - [2025-01-14T18:06:02.397+0000] {dagbag.py:588} INFO - Filling up the DagBag from /opt/airflow/dags/tes_dag.py
[2025-01-14T18:06:02.546+0000] {logging_mixin.py:190} INFO - [2025-01-14T18:06:02.536+0000] {dagbag.py:387} ERROR - Failed to import: /opt/airflow/dags/tes_dag.py
Traceback (most recent call last):
  File "/home/airflow/.local/lib/python3.12/site-packages/airflow/models/dagbag.py", line 383, in parse
    loader.exec_module(new_module)
  File "<frozen importlib._bootstrap_external>", line 999, in exec_module
  File "<frozen importlib._bootstrap>", line 488, in _call_with_frames_removed
  File "/opt/airflow/dags/tes_dag.py", line 5, in <module>
    from test import test2
  File "/opt/airflow/dags/test.py", line 2, in <module>
    from kaggle.api.kaggle_api_extended import KaggleApi
  File "/home/airflow/.local/lib/python3.12/site-packages/kaggle/__init__.py", line 7, in <module>
    api.authenticate()
  File "/home/airflow/.local/lib/python3.12/site-packages/kaggle/api/kaggle_api_extended.py", line 407, in authenticate
    raise IOError('Could not find {}. Make sure it\'s located in'
OSError: Could not find kaggle.json. Make sure it's located in /home/airflow/.config/kaggle. Or use the environment method. See setup instructions at https://github.com/Kaggle/kaggle-api/
[2025-01-14T18:06:02.547+0000] {processor.py:927} WARNING - No viable dags retrieved from /opt/airflow/dags/tes_dag.py
[2025-01-14T18:06:02.580+0000] {processor.py:208} INFO - Processing /opt/airflow/dags/tes_dag.py took 0.194 seconds
[2025-01-14T18:06:33.374+0000] {processor.py:186} INFO - Started process (PID=1955) to work on /opt/airflow/dags/tes_dag.py
[2025-01-14T18:06:33.375+0000] {processor.py:914} INFO - Processing file /opt/airflow/dags/tes_dag.py for tasks to queue
[2025-01-14T18:06:33.377+0000] {logging_mixin.py:190} INFO - [2025-01-14T18:06:33.376+0000] {dagbag.py:588} INFO - Filling up the DagBag from /opt/airflow/dags/tes_dag.py
[2025-01-14T18:06:33.520+0000] {logging_mixin.py:190} INFO - [2025-01-14T18:06:33.507+0000] {dagbag.py:387} ERROR - Failed to import: /opt/airflow/dags/tes_dag.py
Traceback (most recent call last):
  File "/home/airflow/.local/lib/python3.12/site-packages/airflow/models/dagbag.py", line 383, in parse
    loader.exec_module(new_module)
  File "<frozen importlib._bootstrap_external>", line 999, in exec_module
  File "<frozen importlib._bootstrap>", line 488, in _call_with_frames_removed
  File "/opt/airflow/dags/tes_dag.py", line 5, in <module>
    from test import test2
  File "/opt/airflow/dags/test.py", line 2, in <module>
    from kaggle.api.kaggle_api_extended import KaggleApi
  File "/home/airflow/.local/lib/python3.12/site-packages/kaggle/__init__.py", line 7, in <module>
    api.authenticate()
  File "/home/airflow/.local/lib/python3.12/site-packages/kaggle/api/kaggle_api_extended.py", line 407, in authenticate
    raise IOError('Could not find {}. Make sure it\'s located in'
OSError: Could not find kaggle.json. Make sure it's located in /home/airflow/.config/kaggle. Or use the environment method. See setup instructions at https://github.com/Kaggle/kaggle-api/
[2025-01-14T18:06:33.521+0000] {processor.py:927} WARNING - No viable dags retrieved from /opt/airflow/dags/tes_dag.py
[2025-01-14T18:06:33.551+0000] {processor.py:208} INFO - Processing /opt/airflow/dags/tes_dag.py took 0.186 seconds
[2025-01-14T18:07:03.730+0000] {processor.py:186} INFO - Started process (PID=1977) to work on /opt/airflow/dags/tes_dag.py
[2025-01-14T18:07:03.732+0000] {processor.py:914} INFO - Processing file /opt/airflow/dags/tes_dag.py for tasks to queue
[2025-01-14T18:07:03.735+0000] {logging_mixin.py:190} INFO - [2025-01-14T18:07:03.734+0000] {dagbag.py:588} INFO - Filling up the DagBag from /opt/airflow/dags/tes_dag.py
[2025-01-14T18:07:03.916+0000] {logging_mixin.py:190} INFO - [2025-01-14T18:07:03.906+0000] {dagbag.py:387} ERROR - Failed to import: /opt/airflow/dags/tes_dag.py
Traceback (most recent call last):
  File "/home/airflow/.local/lib/python3.12/site-packages/airflow/models/dagbag.py", line 383, in parse
    loader.exec_module(new_module)
  File "<frozen importlib._bootstrap_external>", line 999, in exec_module
  File "<frozen importlib._bootstrap>", line 488, in _call_with_frames_removed
  File "/opt/airflow/dags/tes_dag.py", line 5, in <module>
    from test import test2
  File "/opt/airflow/dags/test.py", line 2, in <module>
    from kaggle.api.kaggle_api_extended import KaggleApi
  File "/home/airflow/.local/lib/python3.12/site-packages/kaggle/__init__.py", line 7, in <module>
    api.authenticate()
  File "/home/airflow/.local/lib/python3.12/site-packages/kaggle/api/kaggle_api_extended.py", line 407, in authenticate
    raise IOError('Could not find {}. Make sure it\'s located in'
OSError: Could not find kaggle.json. Make sure it's located in /home/airflow/.config/kaggle. Or use the environment method. See setup instructions at https://github.com/Kaggle/kaggle-api/
[2025-01-14T18:07:03.917+0000] {processor.py:927} WARNING - No viable dags retrieved from /opt/airflow/dags/tes_dag.py
[2025-01-14T18:07:03.946+0000] {processor.py:208} INFO - Processing /opt/airflow/dags/tes_dag.py took 0.229 seconds
[2025-01-14T18:07:34.397+0000] {processor.py:186} INFO - Started process (PID=1999) to work on /opt/airflow/dags/tes_dag.py
[2025-01-14T18:07:34.400+0000] {processor.py:914} INFO - Processing file /opt/airflow/dags/tes_dag.py for tasks to queue
[2025-01-14T18:07:34.403+0000] {logging_mixin.py:190} INFO - [2025-01-14T18:07:34.402+0000] {dagbag.py:588} INFO - Filling up the DagBag from /opt/airflow/dags/tes_dag.py
[2025-01-14T18:07:34.597+0000] {logging_mixin.py:190} INFO - [2025-01-14T18:07:34.587+0000] {dagbag.py:387} ERROR - Failed to import: /opt/airflow/dags/tes_dag.py
Traceback (most recent call last):
  File "/home/airflow/.local/lib/python3.12/site-packages/airflow/models/dagbag.py", line 383, in parse
    loader.exec_module(new_module)
  File "<frozen importlib._bootstrap_external>", line 999, in exec_module
  File "<frozen importlib._bootstrap>", line 488, in _call_with_frames_removed
  File "/opt/airflow/dags/tes_dag.py", line 5, in <module>
    from test import test2
  File "/opt/airflow/dags/test.py", line 2, in <module>
    from kaggle.api.kaggle_api_extended import KaggleApi
  File "/home/airflow/.local/lib/python3.12/site-packages/kaggle/__init__.py", line 7, in <module>
    api.authenticate()
  File "/home/airflow/.local/lib/python3.12/site-packages/kaggle/api/kaggle_api_extended.py", line 407, in authenticate
    raise IOError('Could not find {}. Make sure it\'s located in'
OSError: Could not find kaggle.json. Make sure it's located in /home/airflow/.config/kaggle. Or use the environment method. See setup instructions at https://github.com/Kaggle/kaggle-api/
[2025-01-14T18:07:34.599+0000] {processor.py:927} WARNING - No viable dags retrieved from /opt/airflow/dags/tes_dag.py
[2025-01-14T18:07:34.628+0000] {processor.py:208} INFO - Processing /opt/airflow/dags/tes_dag.py took 0.255 seconds
[2025-01-14T18:08:04.983+0000] {processor.py:186} INFO - Started process (PID=2021) to work on /opt/airflow/dags/tes_dag.py
[2025-01-14T18:08:04.984+0000] {processor.py:914} INFO - Processing file /opt/airflow/dags/tes_dag.py for tasks to queue
[2025-01-14T18:08:04.987+0000] {logging_mixin.py:190} INFO - [2025-01-14T18:08:04.987+0000] {dagbag.py:588} INFO - Filling up the DagBag from /opt/airflow/dags/tes_dag.py
[2025-01-14T18:08:05.172+0000] {logging_mixin.py:190} INFO - [2025-01-14T18:08:05.161+0000] {dagbag.py:387} ERROR - Failed to import: /opt/airflow/dags/tes_dag.py
Traceback (most recent call last):
  File "/home/airflow/.local/lib/python3.12/site-packages/airflow/models/dagbag.py", line 383, in parse
    loader.exec_module(new_module)
  File "<frozen importlib._bootstrap_external>", line 999, in exec_module
  File "<frozen importlib._bootstrap>", line 488, in _call_with_frames_removed
  File "/opt/airflow/dags/tes_dag.py", line 5, in <module>
    from test import test2
  File "/opt/airflow/dags/test.py", line 2, in <module>
    from kaggle.api.kaggle_api_extended import KaggleApi
  File "/home/airflow/.local/lib/python3.12/site-packages/kaggle/__init__.py", line 7, in <module>
    api.authenticate()
  File "/home/airflow/.local/lib/python3.12/site-packages/kaggle/api/kaggle_api_extended.py", line 407, in authenticate
    raise IOError('Could not find {}. Make sure it\'s located in'
OSError: Could not find kaggle.json. Make sure it's located in /home/airflow/.config/kaggle. Or use the environment method. See setup instructions at https://github.com/Kaggle/kaggle-api/
[2025-01-14T18:08:05.173+0000] {processor.py:927} WARNING - No viable dags retrieved from /opt/airflow/dags/tes_dag.py
[2025-01-14T18:08:05.213+0000] {processor.py:208} INFO - Processing /opt/airflow/dags/tes_dag.py took 0.238 seconds
[2025-01-14T18:08:35.600+0000] {processor.py:186} INFO - Started process (PID=2043) to work on /opt/airflow/dags/tes_dag.py
[2025-01-14T18:08:35.601+0000] {processor.py:914} INFO - Processing file /opt/airflow/dags/tes_dag.py for tasks to queue
[2025-01-14T18:08:35.603+0000] {logging_mixin.py:190} INFO - [2025-01-14T18:08:35.603+0000] {dagbag.py:588} INFO - Filling up the DagBag from /opt/airflow/dags/tes_dag.py
[2025-01-14T18:08:35.741+0000] {logging_mixin.py:190} INFO - [2025-01-14T18:08:35.732+0000] {dagbag.py:387} ERROR - Failed to import: /opt/airflow/dags/tes_dag.py
Traceback (most recent call last):
  File "/home/airflow/.local/lib/python3.12/site-packages/airflow/models/dagbag.py", line 383, in parse
    loader.exec_module(new_module)
  File "<frozen importlib._bootstrap_external>", line 999, in exec_module
  File "<frozen importlib._bootstrap>", line 488, in _call_with_frames_removed
  File "/opt/airflow/dags/tes_dag.py", line 5, in <module>
    from test import test2
  File "/opt/airflow/dags/test.py", line 2, in <module>
    from kaggle.api.kaggle_api_extended import KaggleApi
  File "/home/airflow/.local/lib/python3.12/site-packages/kaggle/__init__.py", line 7, in <module>
    api.authenticate()
  File "/home/airflow/.local/lib/python3.12/site-packages/kaggle/api/kaggle_api_extended.py", line 407, in authenticate
    raise IOError('Could not find {}. Make sure it\'s located in'
OSError: Could not find kaggle.json. Make sure it's located in /home/airflow/.config/kaggle. Or use the environment method. See setup instructions at https://github.com/Kaggle/kaggle-api/
[2025-01-14T18:08:35.742+0000] {processor.py:927} WARNING - No viable dags retrieved from /opt/airflow/dags/tes_dag.py
[2025-01-14T18:08:35.770+0000] {processor.py:208} INFO - Processing /opt/airflow/dags/tes_dag.py took 0.183 seconds
[2025-01-14T18:09:05.872+0000] {processor.py:186} INFO - Started process (PID=2065) to work on /opt/airflow/dags/tes_dag.py
[2025-01-14T18:09:05.873+0000] {processor.py:914} INFO - Processing file /opt/airflow/dags/tes_dag.py for tasks to queue
[2025-01-14T18:09:05.875+0000] {logging_mixin.py:190} INFO - [2025-01-14T18:09:05.874+0000] {dagbag.py:588} INFO - Filling up the DagBag from /opt/airflow/dags/tes_dag.py
[2025-01-14T18:09:06.013+0000] {logging_mixin.py:190} INFO - [2025-01-14T18:09:06.002+0000] {dagbag.py:387} ERROR - Failed to import: /opt/airflow/dags/tes_dag.py
Traceback (most recent call last):
  File "/home/airflow/.local/lib/python3.12/site-packages/airflow/models/dagbag.py", line 383, in parse
    loader.exec_module(new_module)
  File "<frozen importlib._bootstrap_external>", line 999, in exec_module
  File "<frozen importlib._bootstrap>", line 488, in _call_with_frames_removed
  File "/opt/airflow/dags/tes_dag.py", line 5, in <module>
    from test import test2
  File "/opt/airflow/dags/test.py", line 2, in <module>
    from kaggle.api.kaggle_api_extended import KaggleApi
  File "/home/airflow/.local/lib/python3.12/site-packages/kaggle/__init__.py", line 7, in <module>
    api.authenticate()
  File "/home/airflow/.local/lib/python3.12/site-packages/kaggle/api/kaggle_api_extended.py", line 407, in authenticate
    raise IOError('Could not find {}. Make sure it\'s located in'
OSError: Could not find kaggle.json. Make sure it's located in /home/airflow/.config/kaggle. Or use the environment method. See setup instructions at https://github.com/Kaggle/kaggle-api/
[2025-01-14T18:09:06.014+0000] {processor.py:927} WARNING - No viable dags retrieved from /opt/airflow/dags/tes_dag.py
[2025-01-14T18:09:06.045+0000] {processor.py:208} INFO - Processing /opt/airflow/dags/tes_dag.py took 0.183 seconds
[2025-01-14T18:09:36.845+0000] {processor.py:186} INFO - Started process (PID=2087) to work on /opt/airflow/dags/tes_dag.py
[2025-01-14T18:09:36.846+0000] {processor.py:914} INFO - Processing file /opt/airflow/dags/tes_dag.py for tasks to queue
[2025-01-14T18:09:36.848+0000] {logging_mixin.py:190} INFO - [2025-01-14T18:09:36.848+0000] {dagbag.py:588} INFO - Filling up the DagBag from /opt/airflow/dags/tes_dag.py
[2025-01-14T18:09:37.013+0000] {logging_mixin.py:190} INFO - [2025-01-14T18:09:37.000+0000] {dagbag.py:387} ERROR - Failed to import: /opt/airflow/dags/tes_dag.py
Traceback (most recent call last):
  File "/home/airflow/.local/lib/python3.12/site-packages/airflow/models/dagbag.py", line 383, in parse
    loader.exec_module(new_module)
  File "<frozen importlib._bootstrap_external>", line 999, in exec_module
  File "<frozen importlib._bootstrap>", line 488, in _call_with_frames_removed
  File "/opt/airflow/dags/tes_dag.py", line 5, in <module>
    from test import test2
  File "/opt/airflow/dags/test.py", line 2, in <module>
    from kaggle.api.kaggle_api_extended import KaggleApi
  File "/home/airflow/.local/lib/python3.12/site-packages/kaggle/__init__.py", line 7, in <module>
    api.authenticate()
  File "/home/airflow/.local/lib/python3.12/site-packages/kaggle/api/kaggle_api_extended.py", line 407, in authenticate
    raise IOError('Could not find {}. Make sure it\'s located in'
OSError: Could not find kaggle.json. Make sure it's located in /home/airflow/.config/kaggle. Or use the environment method. See setup instructions at https://github.com/Kaggle/kaggle-api/
[2025-01-14T18:09:37.015+0000] {processor.py:927} WARNING - No viable dags retrieved from /opt/airflow/dags/tes_dag.py
[2025-01-14T18:09:37.051+0000] {processor.py:208} INFO - Processing /opt/airflow/dags/tes_dag.py took 0.215 seconds
[2025-01-14T18:10:07.444+0000] {processor.py:186} INFO - Started process (PID=2109) to work on /opt/airflow/dags/tes_dag.py
[2025-01-14T18:10:07.447+0000] {processor.py:914} INFO - Processing file /opt/airflow/dags/tes_dag.py for tasks to queue
[2025-01-14T18:10:07.450+0000] {logging_mixin.py:190} INFO - [2025-01-14T18:10:07.449+0000] {dagbag.py:588} INFO - Filling up the DagBag from /opt/airflow/dags/tes_dag.py
[2025-01-14T18:10:07.599+0000] {logging_mixin.py:190} INFO - [2025-01-14T18:10:07.587+0000] {dagbag.py:387} ERROR - Failed to import: /opt/airflow/dags/tes_dag.py
Traceback (most recent call last):
  File "/home/airflow/.local/lib/python3.12/site-packages/airflow/models/dagbag.py", line 383, in parse
    loader.exec_module(new_module)
  File "<frozen importlib._bootstrap_external>", line 999, in exec_module
  File "<frozen importlib._bootstrap>", line 488, in _call_with_frames_removed
  File "/opt/airflow/dags/tes_dag.py", line 5, in <module>
    from test import test2
  File "/opt/airflow/dags/test.py", line 2, in <module>
    from kaggle.api.kaggle_api_extended import KaggleApi
  File "/home/airflow/.local/lib/python3.12/site-packages/kaggle/__init__.py", line 7, in <module>
    api.authenticate()
  File "/home/airflow/.local/lib/python3.12/site-packages/kaggle/api/kaggle_api_extended.py", line 407, in authenticate
    raise IOError('Could not find {}. Make sure it\'s located in'
OSError: Could not find kaggle.json. Make sure it's located in /home/airflow/.config/kaggle. Or use the environment method. See setup instructions at https://github.com/Kaggle/kaggle-api/
[2025-01-14T18:10:07.600+0000] {processor.py:927} WARNING - No viable dags retrieved from /opt/airflow/dags/tes_dag.py
[2025-01-14T18:10:07.629+0000] {processor.py:208} INFO - Processing /opt/airflow/dags/tes_dag.py took 0.202 seconds
[2025-01-14T18:10:37.745+0000] {processor.py:186} INFO - Started process (PID=2132) to work on /opt/airflow/dags/tes_dag.py
[2025-01-14T18:10:37.747+0000] {processor.py:914} INFO - Processing file /opt/airflow/dags/tes_dag.py for tasks to queue
[2025-01-14T18:10:37.748+0000] {logging_mixin.py:190} INFO - [2025-01-14T18:10:37.748+0000] {dagbag.py:588} INFO - Filling up the DagBag from /opt/airflow/dags/tes_dag.py
[2025-01-14T18:10:37.897+0000] {logging_mixin.py:190} INFO - [2025-01-14T18:10:37.883+0000] {dagbag.py:387} ERROR - Failed to import: /opt/airflow/dags/tes_dag.py
Traceback (most recent call last):
  File "/home/airflow/.local/lib/python3.12/site-packages/airflow/models/dagbag.py", line 383, in parse
    loader.exec_module(new_module)
  File "<frozen importlib._bootstrap_external>", line 999, in exec_module
  File "<frozen importlib._bootstrap>", line 488, in _call_with_frames_removed
  File "/opt/airflow/dags/tes_dag.py", line 5, in <module>
    from test import test2
  File "/opt/airflow/dags/test.py", line 2, in <module>
    from kaggle.api.kaggle_api_extended import KaggleApi
  File "/home/airflow/.local/lib/python3.12/site-packages/kaggle/__init__.py", line 7, in <module>
    api.authenticate()
  File "/home/airflow/.local/lib/python3.12/site-packages/kaggle/api/kaggle_api_extended.py", line 407, in authenticate
    raise IOError('Could not find {}. Make sure it\'s located in'
OSError: Could not find kaggle.json. Make sure it's located in /home/airflow/.config/kaggle. Or use the environment method. See setup instructions at https://github.com/Kaggle/kaggle-api/
[2025-01-14T18:10:37.898+0000] {processor.py:927} WARNING - No viable dags retrieved from /opt/airflow/dags/tes_dag.py
[2025-01-14T18:10:37.921+0000] {processor.py:208} INFO - Processing /opt/airflow/dags/tes_dag.py took 0.184 seconds
[2025-01-14T18:11:08.490+0000] {processor.py:186} INFO - Started process (PID=2155) to work on /opt/airflow/dags/tes_dag.py
[2025-01-14T18:11:08.491+0000] {processor.py:914} INFO - Processing file /opt/airflow/dags/tes_dag.py for tasks to queue
[2025-01-14T18:11:08.494+0000] {logging_mixin.py:190} INFO - [2025-01-14T18:11:08.493+0000] {dagbag.py:588} INFO - Filling up the DagBag from /opt/airflow/dags/tes_dag.py
[2025-01-14T18:11:08.654+0000] {logging_mixin.py:190} INFO - [2025-01-14T18:11:08.641+0000] {dagbag.py:387} ERROR - Failed to import: /opt/airflow/dags/tes_dag.py
Traceback (most recent call last):
  File "/home/airflow/.local/lib/python3.12/site-packages/airflow/models/dagbag.py", line 383, in parse
    loader.exec_module(new_module)
  File "<frozen importlib._bootstrap_external>", line 999, in exec_module
  File "<frozen importlib._bootstrap>", line 488, in _call_with_frames_removed
  File "/opt/airflow/dags/tes_dag.py", line 5, in <module>
    from test import test2
  File "/opt/airflow/dags/test.py", line 2, in <module>
    from kaggle.api.kaggle_api_extended import KaggleApi
  File "/home/airflow/.local/lib/python3.12/site-packages/kaggle/__init__.py", line 7, in <module>
    api.authenticate()
  File "/home/airflow/.local/lib/python3.12/site-packages/kaggle/api/kaggle_api_extended.py", line 407, in authenticate
    raise IOError('Could not find {}. Make sure it\'s located in'
OSError: Could not find kaggle.json. Make sure it's located in /home/airflow/.config/kaggle. Or use the environment method. See setup instructions at https://github.com/Kaggle/kaggle-api/
[2025-01-14T18:11:08.655+0000] {processor.py:927} WARNING - No viable dags retrieved from /opt/airflow/dags/tes_dag.py
[2025-01-14T18:11:08.680+0000] {processor.py:208} INFO - Processing /opt/airflow/dags/tes_dag.py took 0.205 seconds
[2025-01-14T18:11:38.870+0000] {processor.py:186} INFO - Started process (PID=2177) to work on /opt/airflow/dags/tes_dag.py
[2025-01-14T18:11:38.872+0000] {processor.py:914} INFO - Processing file /opt/airflow/dags/tes_dag.py for tasks to queue
[2025-01-14T18:11:38.875+0000] {logging_mixin.py:190} INFO - [2025-01-14T18:11:38.874+0000] {dagbag.py:588} INFO - Filling up the DagBag from /opt/airflow/dags/tes_dag.py
[2025-01-14T18:11:39.041+0000] {logging_mixin.py:190} INFO - [2025-01-14T18:11:39.027+0000] {dagbag.py:387} ERROR - Failed to import: /opt/airflow/dags/tes_dag.py
Traceback (most recent call last):
  File "/home/airflow/.local/lib/python3.12/site-packages/airflow/models/dagbag.py", line 383, in parse
    loader.exec_module(new_module)
  File "<frozen importlib._bootstrap_external>", line 999, in exec_module
  File "<frozen importlib._bootstrap>", line 488, in _call_with_frames_removed
  File "/opt/airflow/dags/tes_dag.py", line 5, in <module>
    from test import test2
  File "/opt/airflow/dags/test.py", line 2, in <module>
    from kaggle.api.kaggle_api_extended import KaggleApi
  File "/home/airflow/.local/lib/python3.12/site-packages/kaggle/__init__.py", line 7, in <module>
    api.authenticate()
  File "/home/airflow/.local/lib/python3.12/site-packages/kaggle/api/kaggle_api_extended.py", line 407, in authenticate
    raise IOError('Could not find {}. Make sure it\'s located in'
OSError: Could not find kaggle.json. Make sure it's located in /home/airflow/.config/kaggle. Or use the environment method. See setup instructions at https://github.com/Kaggle/kaggle-api/
[2025-01-14T18:11:39.043+0000] {processor.py:927} WARNING - No viable dags retrieved from /opt/airflow/dags/tes_dag.py
[2025-01-14T18:11:39.080+0000] {processor.py:208} INFO - Processing /opt/airflow/dags/tes_dag.py took 0.219 seconds
[2025-01-14T18:12:09.362+0000] {processor.py:186} INFO - Started process (PID=2199) to work on /opt/airflow/dags/tes_dag.py
[2025-01-14T18:12:09.364+0000] {processor.py:914} INFO - Processing file /opt/airflow/dags/tes_dag.py for tasks to queue
[2025-01-14T18:12:09.371+0000] {logging_mixin.py:190} INFO - [2025-01-14T18:12:09.369+0000] {dagbag.py:588} INFO - Filling up the DagBag from /opt/airflow/dags/tes_dag.py
[2025-01-14T18:12:09.888+0000] {logging_mixin.py:190} INFO - [2025-01-14T18:12:09.867+0000] {dagbag.py:387} ERROR - Failed to import: /opt/airflow/dags/tes_dag.py
Traceback (most recent call last):
  File "/home/airflow/.local/lib/python3.12/site-packages/airflow/models/dagbag.py", line 383, in parse
    loader.exec_module(new_module)
  File "<frozen importlib._bootstrap_external>", line 999, in exec_module
  File "<frozen importlib._bootstrap>", line 488, in _call_with_frames_removed
  File "/opt/airflow/dags/tes_dag.py", line 5, in <module>
    from test import test2
  File "/opt/airflow/dags/test.py", line 2, in <module>
    from kaggle.api.kaggle_api_extended import KaggleApi
  File "/home/airflow/.local/lib/python3.12/site-packages/kaggle/__init__.py", line 7, in <module>
    api.authenticate()
  File "/home/airflow/.local/lib/python3.12/site-packages/kaggle/api/kaggle_api_extended.py", line 407, in authenticate
    raise IOError('Could not find {}. Make sure it\'s located in'
OSError: Could not find kaggle.json. Make sure it's located in /home/airflow/.config/kaggle. Or use the environment method. See setup instructions at https://github.com/Kaggle/kaggle-api/
[2025-01-14T18:12:09.890+0000] {processor.py:927} WARNING - No viable dags retrieved from /opt/airflow/dags/tes_dag.py
[2025-01-14T18:12:09.941+0000] {processor.py:208} INFO - Processing /opt/airflow/dags/tes_dag.py took 0.598 seconds
[2025-01-14T18:12:40.418+0000] {processor.py:186} INFO - Started process (PID=2221) to work on /opt/airflow/dags/tes_dag.py
[2025-01-14T18:12:40.420+0000] {processor.py:914} INFO - Processing file /opt/airflow/dags/tes_dag.py for tasks to queue
[2025-01-14T18:12:40.436+0000] {logging_mixin.py:190} INFO - [2025-01-14T18:12:40.435+0000] {dagbag.py:588} INFO - Filling up the DagBag from /opt/airflow/dags/tes_dag.py
[2025-01-14T18:12:40.980+0000] {logging_mixin.py:190} INFO - [2025-01-14T18:12:40.964+0000] {dagbag.py:387} ERROR - Failed to import: /opt/airflow/dags/tes_dag.py
Traceback (most recent call last):
  File "/home/airflow/.local/lib/python3.12/site-packages/airflow/models/dagbag.py", line 383, in parse
    loader.exec_module(new_module)
  File "<frozen importlib._bootstrap_external>", line 999, in exec_module
  File "<frozen importlib._bootstrap>", line 488, in _call_with_frames_removed
  File "/opt/airflow/dags/tes_dag.py", line 5, in <module>
    from test import test2
  File "/opt/airflow/dags/test.py", line 2, in <module>
    from kaggle.api.kaggle_api_extended import KaggleApi
  File "/home/airflow/.local/lib/python3.12/site-packages/kaggle/__init__.py", line 7, in <module>
    api.authenticate()
  File "/home/airflow/.local/lib/python3.12/site-packages/kaggle/api/kaggle_api_extended.py", line 407, in authenticate
    raise IOError('Could not find {}. Make sure it\'s located in'
OSError: Could not find kaggle.json. Make sure it's located in /home/airflow/.config/kaggle. Or use the environment method. See setup instructions at https://github.com/Kaggle/kaggle-api/
[2025-01-14T18:12:40.982+0000] {processor.py:927} WARNING - No viable dags retrieved from /opt/airflow/dags/tes_dag.py
[2025-01-14T18:12:41.027+0000] {processor.py:208} INFO - Processing /opt/airflow/dags/tes_dag.py took 0.650 seconds
[2025-01-14T18:13:11.239+0000] {processor.py:186} INFO - Started process (PID=2243) to work on /opt/airflow/dags/tes_dag.py
[2025-01-14T18:13:11.240+0000] {processor.py:914} INFO - Processing file /opt/airflow/dags/tes_dag.py for tasks to queue
[2025-01-14T18:13:11.243+0000] {logging_mixin.py:190} INFO - [2025-01-14T18:13:11.242+0000] {dagbag.py:588} INFO - Filling up the DagBag from /opt/airflow/dags/tes_dag.py
[2025-01-14T18:13:11.415+0000] {logging_mixin.py:190} INFO - [2025-01-14T18:13:11.404+0000] {dagbag.py:387} ERROR - Failed to import: /opt/airflow/dags/tes_dag.py
Traceback (most recent call last):
  File "/home/airflow/.local/lib/python3.12/site-packages/airflow/models/dagbag.py", line 383, in parse
    loader.exec_module(new_module)
  File "<frozen importlib._bootstrap_external>", line 999, in exec_module
  File "<frozen importlib._bootstrap>", line 488, in _call_with_frames_removed
  File "/opt/airflow/dags/tes_dag.py", line 5, in <module>
    from test import test2
  File "/opt/airflow/dags/test.py", line 2, in <module>
    from kaggle.api.kaggle_api_extended import KaggleApi
  File "/home/airflow/.local/lib/python3.12/site-packages/kaggle/__init__.py", line 7, in <module>
    api.authenticate()
  File "/home/airflow/.local/lib/python3.12/site-packages/kaggle/api/kaggle_api_extended.py", line 407, in authenticate
    raise IOError('Could not find {}. Make sure it\'s located in'
OSError: Could not find kaggle.json. Make sure it's located in /home/airflow/.config/kaggle. Or use the environment method. See setup instructions at https://github.com/Kaggle/kaggle-api/
[2025-01-14T18:13:11.416+0000] {processor.py:927} WARNING - No viable dags retrieved from /opt/airflow/dags/tes_dag.py
[2025-01-14T18:13:11.442+0000] {processor.py:208} INFO - Processing /opt/airflow/dags/tes_dag.py took 0.215 seconds
[2025-01-14T18:13:41.561+0000] {processor.py:186} INFO - Started process (PID=2265) to work on /opt/airflow/dags/tes_dag.py
[2025-01-14T18:13:41.563+0000] {processor.py:914} INFO - Processing file /opt/airflow/dags/tes_dag.py for tasks to queue
[2025-01-14T18:13:41.565+0000] {logging_mixin.py:190} INFO - [2025-01-14T18:13:41.564+0000] {dagbag.py:588} INFO - Filling up the DagBag from /opt/airflow/dags/tes_dag.py
[2025-01-14T18:13:41.716+0000] {logging_mixin.py:190} INFO - [2025-01-14T18:13:41.703+0000] {dagbag.py:387} ERROR - Failed to import: /opt/airflow/dags/tes_dag.py
Traceback (most recent call last):
  File "/home/airflow/.local/lib/python3.12/site-packages/airflow/models/dagbag.py", line 383, in parse
    loader.exec_module(new_module)
  File "<frozen importlib._bootstrap_external>", line 999, in exec_module
  File "<frozen importlib._bootstrap>", line 488, in _call_with_frames_removed
  File "/opt/airflow/dags/tes_dag.py", line 5, in <module>
    from test import test2
  File "/opt/airflow/dags/test.py", line 2, in <module>
    from kaggle.api.kaggle_api_extended import KaggleApi
  File "/home/airflow/.local/lib/python3.12/site-packages/kaggle/__init__.py", line 7, in <module>
    api.authenticate()
  File "/home/airflow/.local/lib/python3.12/site-packages/kaggle/api/kaggle_api_extended.py", line 407, in authenticate
    raise IOError('Could not find {}. Make sure it\'s located in'
OSError: Could not find kaggle.json. Make sure it's located in /home/airflow/.config/kaggle. Or use the environment method. See setup instructions at https://github.com/Kaggle/kaggle-api/
[2025-01-14T18:13:41.717+0000] {processor.py:927} WARNING - No viable dags retrieved from /opt/airflow/dags/tes_dag.py
[2025-01-14T18:13:41.743+0000] {processor.py:208} INFO - Processing /opt/airflow/dags/tes_dag.py took 0.189 seconds
[2025-01-14T18:14:12.124+0000] {processor.py:186} INFO - Started process (PID=2287) to work on /opt/airflow/dags/tes_dag.py
[2025-01-14T18:14:12.125+0000] {processor.py:914} INFO - Processing file /opt/airflow/dags/tes_dag.py for tasks to queue
[2025-01-14T18:14:12.127+0000] {logging_mixin.py:190} INFO - [2025-01-14T18:14:12.127+0000] {dagbag.py:588} INFO - Filling up the DagBag from /opt/airflow/dags/tes_dag.py
[2025-01-14T18:14:12.322+0000] {logging_mixin.py:190} INFO - [2025-01-14T18:14:12.313+0000] {dagbag.py:387} ERROR - Failed to import: /opt/airflow/dags/tes_dag.py
Traceback (most recent call last):
  File "/home/airflow/.local/lib/python3.12/site-packages/airflow/models/dagbag.py", line 383, in parse
    loader.exec_module(new_module)
  File "<frozen importlib._bootstrap_external>", line 999, in exec_module
  File "<frozen importlib._bootstrap>", line 488, in _call_with_frames_removed
  File "/opt/airflow/dags/tes_dag.py", line 5, in <module>
    from test import test2
  File "/opt/airflow/dags/test.py", line 2, in <module>
    from kaggle.api.kaggle_api_extended import KaggleApi
  File "/home/airflow/.local/lib/python3.12/site-packages/kaggle/__init__.py", line 7, in <module>
    api.authenticate()
  File "/home/airflow/.local/lib/python3.12/site-packages/kaggle/api/kaggle_api_extended.py", line 407, in authenticate
    raise IOError('Could not find {}. Make sure it\'s located in'
OSError: Could not find kaggle.json. Make sure it's located in /home/airflow/.config/kaggle. Or use the environment method. See setup instructions at https://github.com/Kaggle/kaggle-api/
[2025-01-14T18:14:12.324+0000] {processor.py:927} WARNING - No viable dags retrieved from /opt/airflow/dags/tes_dag.py
[2025-01-14T18:14:12.351+0000] {processor.py:208} INFO - Processing /opt/airflow/dags/tes_dag.py took 0.238 seconds
